Workbook

Sheet Unit 1
A1: Roll No | B1: Name | C1: English | D1: Bengali | E1: G Maths | F1: EVS | G1: GK & Dr | H1: Class
H2: 3

Sheet Unit 2
A1: Roll No | B1: English | C1: Bengali | D1: G Maths | E1: EVS | F1: GK & Dr
A2: ='Unit 1'!A2 -> 0

Sheet Half yearly
A1: Roll No | B1: English | C1: Bengali | D1: G Maths | E1: EVS | F1: GK & Dr
A2: ='Unit 1'!A2 -> 0

Sheet Unit 3
A1: Roll No | B1: English | C1: Bengali | D1: G Maths | E1: EVS | F1: GK & Dr
A2: ='Unit 1'!A2 -> 0

Sheet Unit 4
A1: Roll No | B1: English | C1: Bengali | D1: G Maths | E1: EVS | F1: GK & Dr
A2: ='Unit 1'!A2 -> 0

Sheet Annual
A1: Roll No | B1: English | C1: Bengali | D1: G Maths | E1: EVS | F1: GK & Dr
A2: ='Unit 1'!A2 -> 0

Sheet Calculation
A1: New Roll | B1: Roll | C1: Name | D1: Class | E1: English unit 1 | F1: Bengali unit 1 | G1: G maths unit 1 | H1: G Science unit 1 | I1: S Science unit 1 | J1: Total Unit 1 | K1: English unit 2 | L1: Bengali unit 2 | M1: G maths unit 2 | N1: G Science unit 2 | O1: S Science unit 2 | P1: Total Unit 2 | Q1: English unit 3 | R1: Bengali unit 3 | S1: G maths unit 3 | T1: G Science unit 3 | U1: S Science unit 3 | V1: Total Unit 3 | W1: English unit 4 | X1: Bengali unit 4 | Y1: G maths unit 4 | Z1: G Science unit 4 | AA1: S Science unit 4 | AB1: Total Unit 4 | AC1: English Total | AD1: Bengali Total | AE1: G maths Total | AF1: G Science Total | AG1: S Science Total | AH1: Total Total | AI1: English Helf | AJ1: Bengali Helf | AK1: G maths Helf | AL1: G Science Helf | AM1: S Science Helf | AN1: Total Helf | AO1: English Annual | AP1: Bengali Annual | AQ1: G maths Annual | AR1: G Science Annual | AS1: S Science Annual | AT1: Total Annual | AU1: English 20 % of Unit test | AV1: Bengali 20% of unit test | AW1: Gen Math 20% of unit test | AX1: Gen Science 20% of unit test | AY1: S Science 20% of unit test | AZ1: Total of 20 % of unit test | BA1: English 30 % of halfyearly | BB1: Bengali 30% of halfyearly | BC1: Gen Math 30% of halfyearly | BD1: Gen Science 30% of halfyearly | BE1: S Science 30% of halyearly | BF1: Total of 30 % of half | BG1: English 50 % of Annual | BH1: Bengali 50% of Annual | BI1: Gen Math 50% of Annual | BJ1: Gen Science 50% of Annual | BK1: S Science 50% of Annual | BL1: Total of 50% of Annual Exam | BM1: English Grand total | BN1: Bengali Grand total | BO1: Gen Math grand total | BP1: Gen Science Grand total | BQ1: S Science Grand total | BR1: Total of Grand Total | BS1: Percentage | BT1: Grade
B2: ='Unit 1'!A2 -> 0 | C2: ='Unit 1'!B2 -> 0 | D2: ='Unit 1'!$H$2 -> 3 | E2: ='Unit 1'!C2 -> 0 | F2: ='Unit 1'!D2 -> 0 | G2: ='Unit 1'!E2 -> 0 | H2: ='Unit 1'!F2 -> 0 | I2: ='Unit 1'!G2 -> 0 | J2: =SUM(E2:I2) -> 0 | K2: ='Unit 2'!B2 -> 0 | L2: ='Unit 2'!C2 -> 0 | M2: ='Unit 2'!D2 -> 0 | N2: ='Unit 2'!E2 -> 0 | O2: ='Unit 2'!F2 -> 0 | P2: =SUM(K2:O2) -> 0 | Q2: ='Unit 3'!B2 -> 0 | R2: ='Unit 3'!C2 -> 0 | S2: ='Unit 3'!D2 -> 0 | T2: ='Unit 3'!E2 -> 0 | U2: ='Unit 3'!F2 -> 0 | V2: =SUM(Q2:U2) -> 0 | W2: ='Unit 4'!B2 -> 0 | X2: ='Unit 4'!C2 -> 0 | Y2: ='Unit 4'!D2 -> 0 | Z2: ='Unit 4'!E2 -> 0 | AA2: ='Unit 4'!F2 -> 0 | AB2: =SUM(W2:AA2) -> 0 | AC2: =SUM(E2,K2,Q2,W2,) -> 0 | AD2: =SUM(F2,L2,R2,X2,) -> 0 | AE2: =SUM(G2,M2,S2,Y2,) -> 0 | AF2: =SUM(H2,N2,T2,Z2,) -> 0 | AG2: =SUM(I2,O2,U2,AA2,) -> 0 | AH2: =SUM(AC2:AG2) -> 0 | AI2: ='Half yearly'!B2 -> 0 | AJ2: ='Half yearly'!C2 -> 0 | AK2: ='Half yearly'!D2 -> 0 | AL2: ='Half yearly'!E2 -> 0 | AM2: ='Half yearly'!F2 -> 0 | AN2: =SUM(AI2:AM2) -> 0 | AO2: =Annual!B2 -> 0 | AP2: =Annual!C2 -> 0 | AQ2: =Annual!D2 -> 0 | AR2: =Annual!E2 -> 0 | AS2: =Annual!F2 -> 0 | AT2: =SUM(AO2:AS2) -> 0 | AU2: =IF(INT(SUM(E2, K2, Q2, W2) * 0.2) <> A1, IF(SUM(E2, K2, Q2, W2) * 0.2 - INT(SUM(E2, K2, Q2, W2) * 0.2) >= 0.5, ROUNDUP(SUM(E2, K2, Q2, W2) * 0.2, 0), ROUNDDOWN(SUM(E2, K2, Q2, W2) * 0.2, 0)), SUM(E2, K2, Q2, W2) * 0.2) -> 0 | AV2: =IF(INT(SUM(F2, L2, R2, X2) * 0.2) <> B1, IF(SUM(F2, L2, R2, X2) * 0.2 - INT(SUM(F2, L2, R2, X2) * 0.2) >= 0.5, ROUNDUP(SUM(F2, L2, R2, X2) * 0.2, 0), ROUNDDOWN(SUM(F2, L2, R2, X2) * 0.2, 0)), SUM(F2, L2, R2, X2) * 0.2) -> 0 | AW2: =IF(INT(SUM(G2, M2, S2, Y2) * 0.2) <> C1, IF(SUM(G2, M2, S2, Y2) * 0.2 - INT(SUM(G2, M2, S2, Y2) * 0.2) >= 0.5, ROUNDUP(SUM(G2, M2, S2, Y2) * 0.2, 0), ROUNDDOWN(SUM(G2, M2, S2, Y2) * 0.2, 0)), SUM(G2, M2, S2, Y2) * 0.2) -> 0 | AX2: =IF(INT(SUM(H2, N2, T2, Z2) * 0.2) <> D1, IF(SUM(H2, N2, T2, Z2) * 0.2 - INT(SUM(H2, N2, T2, Z2) * 0.2) >= 0.5, ROUNDUP(SUM(H2, N2, T2, Z2) * 0.2, 0), ROUNDDOWN(SUM(H2, N2, T2, Z2) * 0.2, 0)), SUM(H2, N2, T2, Z2) * 0.2) -> 0 | AY2: =IF(INT(SUM(I2, O2, U2, AA2) * 0.2) <> E1, IF(SUM(I2, O2, U2, AA2) * 0.2 - INT(SUM(I2, O2, U2, AA2) * 0.2) >= 0.5, ROUNDUP(SUM(I2, O2, U2, AA2) * 0.2, 0), ROUNDDOWN(SUM(I2, O2, U2, AA2) * 0.2, 0)), SUM(I2, O2, U2, AA2) * 0.2) -> 0 | AZ2: =IF(INT(SUM(J2, P2, V2, AB2) * 0.2) <> G1, IF(SUM(J2, P2, V2, AB2) * 0.2 - INT(SUM(J2, P2, V2, AB2) * 0.2) >= 0.5, ROUNDUP(SUM(J2, P2, V2, AB2) * 0.2, 0), ROUNDDOWN(SUM(J2, P2, V2, AB2) * 0.2, 0)), SUM(J2, P2, V2, AB2) * 0.2) -> 0 | BA2: =IF(INT(SUM(AI2) * 0.3) <> A1, IF(SUM(AI2) * 0.3 - INT(SUM(AI2) * 0.3) >= 0.5, ROUNDUP(SUM(AI2) * 0.3, 0), ROUNDDOWN(SUM(AI2) * 0.3, 0)), SUM(AI2) * 0.3) -> 0 | BB2: =IF(INT(SUM(AJ2) * 0.3) <> B1, IF(SUM(AJ2) * 0.3 - INT(SUM(AJ2) * 0.3) >= 0.5, ROUNDUP(SUM(AJ2) * 0.3, 0), ROUNDDOWN(SUM(AJ2) * 0.3, 0)), SUM(AJ2) * 0.3) -> 0 | BC2: =IF(INT(SUM(AK2) * 0.3) <> C1, IF(SUM(AK2) * 0.3 - INT(SUM(AK2) * 0.3) >= 0.5, ROUNDUP(SUM(AK2) * 0.3, 0), ROUNDDOWN(SUM(AK2) * 0.3, 0)), SUM(AK2) * 0.3) -> 0 | BD2: =IF(INT(SUM(AL2) * 0.3) <> D1, IF(SUM(AL2) * 0.3 - INT(SUM(AL2) * 0.3) >= 0.5, ROUNDUP(SUM(AL2) * 0.3, 0), ROUNDDOWN(SUM(AL2) * 0.3, 0)), SUM(AL2) * 0.3) -> 0 | BE2: =IF(INT(SUM(AM2) * 0.3) <> E1, IF(SUM(AM2) * 0.3 - INT(SUM(AM2) * 0.3) >= 0.5, ROUNDUP(SUM(AM2) * 0.3, 0), ROUNDDOWN(SUM(AM2) * 0.3, 0)), SUM(AM2) * 0.3) -> 0 | BF2: =IF(INT(SUM(AN2) * 0.3) <> G1, IF(SUM(AN2) * 0.3 - INT(SUM(AN2) * 0.3) >= 0.5, ROUNDUP(SUM(AN2) * 0.3, 0), ROUNDDOWN(SUM(AN2) * 0.3, 0)), SUM(AN2) * 0.3) -> 0 | BG2: =IF(INT(SUM(AO2) * 0.5) <> A1, IF(SUM(AO2) * 0.5 - INT(SUM(AO2) * 0.5) >= 0.5, ROUNDUP(SUM(AO2) * 0.5, 0), ROUNDDOWN(SUM(AO2) * 0.5, 0)), SUM(AO2) * 0.5) -> 0 | BH2: =IF(INT(SUM(AP2) * 0.5) <> B1, IF(SUM(AP2) * 0.5 - INT(SUM(AP2) * 0.5) >= 0.5, ROUNDUP(SUM(AP2) * 0.5, 0), ROUNDDOWN(SUM(AP2) * 0.5, 0)), SUM(AP2) * 0.5) -> 0 | BI2: =IF(INT(SUM(AQ2) * 0.5) <> C1, IF(SUM(AQ2) * 0.5 - INT(SUM(AQ2) * 0.5) >= 0.5, ROUNDUP(SUM(AQ2) * 0.5, 0), ROUNDDOWN(SUM(AQ2) * 0.5, 0)), SUM(AQ2) * 0.5) -> 0 | BJ2: =IF(INT(SUM(AR2) * 0.5) <> D1, IF(SUM(AR2) * 0.5 - INT(SUM(AR2) * 0.5) >= 0.5, ROUNDUP(SUM(AR2) * 0.5, 0), ROUNDDOWN(SUM(AR2) * 0.5, 0)), SUM(AR2) * 0.5) -> 0 | BK2: =IF(INT(SUM(AS2) * 0.5) <> E1, IF(SUM(AS2) * 0.5 - INT(SUM(AS2) * 0.5) >= 0.5, ROUNDUP(SUM(AS2) * 0.5, 0), ROUNDDOWN(SUM(AS2) * 0.5, 0)), SUM(AS2) * 0.5) -> 0 | BL2: =IF(INT(SUM(AT2) * 0.5) <> G1, IF(SUM(AT2) * 0.5 - INT(SUM(AT2) * 0.5) >= 0.5, ROUNDUP(SUM(AT2) * 0.5, 0), ROUNDDOWN(SUM(AT2) * 0.5, 0)), SUM(AT2) * 0.5) -> 0 | BM2: =SUM(AU2,BA2,BG2) -> 0 | BN2: =SUM(AV2,BB2,BH2) -> 0 | BO2: =SUM(AW2,BC2,BI2) -> 0 | BP2: =SUM(AX2,BD2,BJ2) -> 0 | BQ2: =SUM(AY2,BE2,BK2) -> 0 | BR2: =SUM(BM2:BQ2) -> 0 | BS2: =SUM(BM2:BQ2)/500*100 -> 0 | BT2: =IF(BS2>=80,"A+",IF(BS2>=70,"A",IF(BS2>=60,"B+",IF(BS2>=50,"B",IF(BS2>=40,"C",IF(BS2>=30,"E","FAIL")))))) -> FAIL
B3: ='Unit 1'!A3 -> 0 | C3: ='Unit 1'!B3 -> 0 | D3: ='Unit 1'!$H$2 -> 3 | E3: ='Unit 1'!C3 -> 0 | F3: ='Unit 1'!D3 -> 0 | G3: ='Unit 1'!E3 -> 0 | H3: ='Unit 1'!F3 -> 0 | I3: ='Unit 1'!G3 -> 0 | J3: =SUM(E3:I3) -> 0 | K3: ='Unit 2'!B3 -> 0 | L3: ='Unit 2'!C3 -> 0 | M3: ='Unit 2'!D3 -> 0 | N3: ='Unit 2'!E3 -> 0 | O3: ='Unit 2'!F3 -> 0 | P3: =SUM(K3:O3) -> 0 | Q3: ='Unit 3'!B3 -> 0 | R3: ='Unit 3'!C3 -> 0 | S3: ='Unit 3'!D3 -> 0 | T3: ='Unit 3'!E3 -> 0 | U3: ='Unit 3'!F3 -> 0 | V3: =SUM(Q3:U3) -> 0 | W3: ='Unit 4'!B3 -> 0 | X3: ='Unit 4'!C3 -> 0 | Y3: ='Unit 4'!D3 -> 0 | Z3: ='Unit 4'!E3 -> 0 | AA3: ='Unit 4'!F3 -> 0 | AB3: =SUM(W3:AA3) -> 0 | AC3: =SUM(E3,K3,Q3,W3,) -> 0 | AD3: =SUM(F3,L3,R3,X3,) -> 0 | AE3: =SUM(G3,M3,S3,Y3,) -> 0 | AF3: =SUM(H3,N3,T3,Z3,) -> 0 | AG3: =SUM(I3,O3,U3,AA3,) -> 0 | AH3: =SUM(AC3:AG3) -> 0 | AI3: ='Half yearly'!B3 -> 0 | AJ3: ='Half yearly'!C3 -> 0 | AK3: ='Half yearly'!D3 -> 0 | AL3: ='Half yearly'!E3 -> 0 | AM3: ='Half yearly'!F3 -> 0 | AN3: =SUM(AI3:AM3) -> 0 | AO3: =Annual!B3 -> 0 | AP3: =Annual!C3 -> 0 | AQ3: =Annual!D3 -> 0 | AR3: =Annual!E3 -> 0 | AS3: =Annual!F3 -> 0 | AT3: =SUM(AO3:AS3) -> 0 | AU3: =IF(INT(SUM(E3, K3, Q3, W3) * 0.2) <> A2, IF(SUM(E3, K3, Q3, W3) * 0.2 - INT(SUM(E3, K3, Q3, W3) * 0.2) >= 0.5, ROUNDUP(SUM(E3, K3, Q3, W3) * 0.2, 0), ROUNDDOWN(SUM(E3, K3, Q3, W3) * 0.2, 0)), SUM(E3, K3, Q3, W3) * 0.2) -> 0 | AV3: =IF(INT(SUM(F3, L3, R3, X3) * 0.2) <> B2, IF(SUM(F3, L3, R3, X3) * 0.2 - INT(SUM(F3, L3, R3, X3) * 0.2) >= 0.5, ROUNDUP(SUM(F3, L3, R3, X3) * 0.2, 0), ROUNDDOWN(SUM(F3, L3, R3, X3) * 0.2, 0)), SUM(F3, L3, R3, X3) * 0.2) -> 0 | AW3: =IF(INT(SUM(G3, M3, S3, Y3) * 0.2) <> C2, IF(SUM(G3, M3, S3, Y3) * 0.2 - INT(SUM(G3, M3, S3, Y3) * 0.2) >= 0.5, ROUNDUP(SUM(G3, M3, S3, Y3) * 0.2, 0), ROUNDDOWN(SUM(G3, M3, S3, Y3) * 0.2, 0)), SUM(G3, M3, S3, Y3) * 0.2) -> 0 | AX3: =IF(INT(SUM(H3, N3, T3, Z3) * 0.2) <> D2, IF(SUM(H3, N3, T3, Z3) * 0.2 - INT(SUM(H3, N3, T3, Z3) * 0.2) >= 0.5, ROUNDUP(SUM(H3, N3, T3, Z3) * 0.2, 0), ROUNDDOWN(SUM(H3, N3, T3, Z3) * 0.2, 0)), SUM(H3, N3, T3, Z3) * 0.2) -> 0 | AY3: =IF(INT(SUM(I3, O3, U3, AA3) * 0.2) <> E2, IF(SUM(I3, O3, U3, AA3) * 0.2 - INT(SUM(I3, O3, U3, AA3) * 0.2) >= 0.5, ROUNDUP(SUM(I3, O3, U3, AA3) * 0.2, 0), ROUNDDOWN(SUM(I3, O3, U3, AA3) * 0.2, 0)), SUM(I3, O3, U3, AA3) * 0.2) -> 0 | AZ3: =IF(INT(SUM(J3, P3, V3, AB3) * 0.2) <> G2, IF(SUM(J3, P3, V3, AB3) * 0.2 - INT(SUM(J3, P3, V3, AB3) * 0.2) >= 0.5, ROUNDUP(SUM(J3, P3, V3, AB3) * 0.2, 0), ROUNDDOWN(SUM(J3, P3, V3, AB3) * 0.2, 0)), SUM(J3, P3, V3, AB3) * 0.2) -> 0 | BA3: =IF(INT(SUM(AI3) * 0.3) <> A2, IF(SUM(AI3) * 0.3 - INT(SUM(AI3) * 0.3) >= 0.5, ROUNDUP(SUM(AI3) * 0.3, 0), ROUNDDOWN(SUM(AI3) * 0.3, 0)), SUM(AI3) * 0.3) -> 0 | BB3: =IF(INT(SUM(AJ3) * 0.3) <> B2, IF(SUM(AJ3) * 0.3 - INT(SUM(AJ3) * 0.3) >= 0.5, ROUNDUP(SUM(AJ3) * 0.3, 0), ROUNDDOWN(SUM(AJ3) * 0.3, 0)), SUM(AJ3) * 0.3) -> 0 | BC3: =IF(INT(SUM(AK3) * 0.3) <> C2, IF(SUM(AK3) * 0.3 - INT(SUM(AK3) * 0.3) >= 0.5, ROUNDUP(SUM(AK3) * 0.3, 0), ROUNDDOWN(SUM(AK3) * 0.3, 0)), SUM(AK3) * 0.3) -> 0 | BD3: =IF(INT(SUM(AL3) * 0.3) <> D2, IF(SUM(AL3) * 0.3 - INT(SUM(AL3) * 0.3) >= 0.5, ROUNDUP(SUM(AL3) * 0.3, 0), ROUNDDOWN(SUM(AL3) * 0.3, 0)), SUM(AL3) * 0.3) -> 0 | BE3: =IF(INT(SUM(AM3) * 0.3) <> E2, IF(SUM(AM3) * 0.3 - INT(SUM(AM3) * 0.3) >= 0.5, ROUNDUP(SUM(AM3) * 0.3, 0), ROUNDDOWN(SUM(AM3) * 0.3, 0)), SUM(AM3) * 0.3) -> 0 | BF3: =IF(INT(SUM(AN3) * 0.3) <> G2, IF(SUM(AN3) * 0.3 - INT(SUM(AN3) * 0.3) >= 0.5, ROUNDUP(SUM(AN3) * 0.3, 0), ROUNDDOWN(SUM(AN3) * 0.3, 0)), SUM(AN3) * 0.3) -> 0 | BG3: =IF(INT(SUM(AO3) * 0.5) <> A2, IF(SUM(AO3) * 0.5 - INT(SUM(AO3) * 0.5) >= 0.5, ROUNDUP(SUM(AO3) * 0.5, 0), ROUNDDOWN(SUM(AO3) * 0.5, 0)), SUM(AO3) * 0.5) -> 0 | BH3: =IF(INT(SUM(AP3) * 0.5) <> B2, IF(SUM(AP3) * 0.5 - INT(SUM(AP3) * 0.5) >= 0.5, ROUNDUP(SUM(AP3) * 0.5, 0), ROUNDDOWN(SUM(AP3) * 0.5, 0)), SUM(AP3) * 0.5) -> 0 | BI3: =IF(INT(SUM(AQ3) * 0.5) <> C2, IF(SUM(AQ3) * 0.5 - INT(SUM(AQ3) * 0.5) >= 0.5, ROUNDUP(SUM(AQ3) * 0.5, 0), ROUNDDOWN(SUM(AQ3) * 0.5, 0)), SUM(AQ3) * 0.5) -> 0 | BJ3: =IF(INT(SUM(AR3) * 0.5) <> D2, IF(SUM(AR3) * 0.5 - INT(SUM(AR3) * 0.5) >= 0.5, ROUNDUP(SUM(AR3) * 0.5, 0), ROUNDDOWN(SUM(AR3) * 0.5, 0)), SUM(AR3) * 0.5) -> 0 | BK3: =IF(INT(SUM(AS3) * 0.5) <> E2, IF(SUM(AS3) * 0.5 - INT(SUM(AS3) * 0.5) >= 0.5, ROUNDUP(SUM(AS3) * 0.5, 0), ROUNDDOWN(SUM(AS3) * 0.5, 0)), SUM(AS3) * 0.5) -> 0 | BL3: =IF(INT(SUM(AT3) * 0.5) <> G2, IF(SUM(AT3) * 0.5 - INT(SUM(AT3) * 0.5) >= 0.5, ROUNDUP(SUM(AT3) * 0.5, 0), ROUNDDOWN(SUM(AT3) * 0.5, 0)), SUM(AT3) * 0.5) -> 0 | BM3: =SUM(AU3,BA3,BG3) -> 0 | BN3: =SUM(AV3,BB3,BH3) -> 0 | BO3: =SUM(AW3,BC3,BI3) -> 0 | BP3: =SUM(AX3,BD3,BJ3) -> 0 | BQ3: =SUM(AY3,BE3,BK3) -> 0 | BR3: =SUM(BM3:BQ3) -> 0 | BS3: =SUM(BM3:BQ3)/500*100 -> 0 | BT3: =IF(BS3>=80,"A+",IF(BS3>=70,"A",IF(BS3>=60,"B+",IF(BS3>=50,"B",IF(BS3>=40,"C",IF(BS3>=30,"E","FAIL")))))) -> FAIL
B4: ='Unit 1'!A4 -> 0 | C4: ='Unit 1'!B4 -> 0 | D4: ='Unit 1'!$H$2 -> 3 | E4: ='Unit 1'!C4 -> 0 | F4: ='Unit 1'!D4 -> 0 | G4: ='Unit 1'!E4 -> 0 | H4: ='Unit 1'!F4 -> 0 | I4: ='Unit 1'!G4 -> 0 | J4: =SUM(E4:I4) -> 0 | K4: ='Unit 2'!B4 -> 0 | L4: ='Unit 2'!C4 -> 0 | M4: ='Unit 2'!D4 -> 0 | N4: ='Unit 2'!E4 -> 0 | O4: ='Unit 2'!F4 -> 0 | P4: =SUM(K4:O4) -> 0 | Q4: ='Unit 3'!B4 -> 0 | R4: ='Unit 3'!C4 -> 0 | S4: ='Unit 3'!D4 -> 0 | T4: ='Unit 3'!E4 -> 0 | U4: ='Unit 3'!F4 -> 0 | V4: =SUM(Q4:U4) -> 0 | W4: ='Unit 4'!B4 -> 0 | X4: ='Unit 4'!C4 -> 0 | Y4: ='Unit 4'!D4 -> 0 | Z4: ='Unit 4'!E4 -> 0 | AA4: ='Unit 4'!F4 -> 0 | AB4: =SUM(W4:AA4) -> 0 | AC4: =SUM(E4,K4,Q4,W4,) -> 0 | AD4: =SUM(F4,L4,R4,X4,) -> 0 | AE4: =SUM(G4,M4,S4,Y4,) -> 0 | AF4: =SUM(H4,N4,T4,Z4,) -> 0 | AG4: =SUM(I4,O4,U4,AA4,) -> 0 | AH4: =SUM(AC4:AG4) -> 0 | AI4: ='Half yearly'!B4 -> 0 | AJ4: ='Half yearly'!C4 -> 0 | AK4: ='Half yearly'!D4 -> 0 | AL4: ='Half yearly'!E4 -> 0 | AM4: ='Half yearly'!F4 -> 0 | AN4: =SUM(AI4:AM4) -> 0 | AO4: =Annual!B4 -> 0 | AP4: =Annual!C4 -> 0 | AQ4: =Annual!D4 -> 0 | AR4: =Annual!E4 -> 0 | AS4: =Annual!F4 -> 0 | AT4: =SUM(AO4:AS4) -> 0 | AU4: =IF(INT(SUM(E4, K4, Q4, W4) * 0.2) <> A3, IF(SUM(E4, K4, Q4, W4) * 0.2 - INT(SUM(E4, K4, Q4, W4) * 0.2) >= 0.5, ROUNDUP(SUM(E4, K4, Q4, W4) * 0.2, 0), ROUNDDOWN(SUM(E4, K4, Q4, W4) * 0.2, 0)), SUM(E4, K4, Q4, W4) * 0.2) -> 0 | AV4: =IF(INT(SUM(F4, L4, R4, X4) * 0.2) <> B3, IF(SUM(F4, L4, R4, X4) * 0.2 - INT(SUM(F4, L4, R4, X4) * 0.2) >= 0.5, ROUNDUP(SUM(F4, L4, R4, X4) * 0.2, 0), ROUNDDOWN(SUM(F4, L4, R4, X4) * 0.2, 0)), SUM(F4, L4, R4, X4) * 0.2) -> 0 | AW4: =IF(INT(SUM(G4, M4, S4, Y4) * 0.2) <> C3, IF(SUM(G4, M4, S4, Y4) * 0.2 - INT(SUM(G4, M4, S4, Y4) * 0.2) >= 0.5, ROUNDUP(SUM(G4, M4, S4, Y4) * 0.2, 0), ROUNDDOWN(SUM(G4, M4, S4, Y4) * 0.2, 0)), SUM(G4, M4, S4, Y4) * 0.2) -> 0 | AX4: =IF(INT(SUM(H4, N4, T4, Z4) * 0.2) <> D3, IF(SUM(H4, N4, T4, Z4) * 0.2 - INT(SUM(H4, N4, T4, Z4) * 0.2) >= 0.5, ROUNDUP(SUM(H4, N4, T4, Z4) * 0.2, 0), ROUNDDOWN(SUM(H4, N4, T4, Z4) * 0.2, 0)), SUM(H4, N4, T4, Z4) * 0.2) -> 0 | AY4: =IF(INT(SUM(I4, O4, U4, AA4) * 0.2) <> E3, IF(SUM(I4, O4, U4, AA4) * 0.2 - INT(SUM(I4, O4, U4, AA4) * 0.2) >= 0.5, ROUNDUP(SUM(I4, O4, U4, AA4) * 0.2, 0), ROUNDDOWN(SUM(I4, O4, U4, AA4) * 0.2, 0)), SUM(I4, O4, U4, AA4) * 0.2) -> 0 | AZ4: =IF(INT(SUM(J4, P4, V4, AB4) * 0.2) <> G3, IF(SUM(J4, P4, V4, AB4) * 0.2 - INT(SUM(J4, P4, V4, AB4) * 0.2) >= 0.5, ROUNDUP(SUM(J4, P4, V4, AB4) * 0.2, 0), ROUNDDOWN(SUM(J4, P4, V4, AB4) * 0.2, 0)), SUM(J4, P4, V4, AB4) * 0.2) -> 0 | BA4: =IF(INT(SUM(AI4) * 0.3) <> A3, IF(SUM(AI4) * 0.3 - INT(SUM(AI4) * 0.3) >= 0.5, ROUNDUP(SUM(AI4) * 0.3, 0), ROUNDDOWN(SUM(AI4) * 0.3, 0)), SUM(AI4) * 0.3) -> 0 | BB4: =IF(INT(SUM(AJ4) * 0.3) <> B3, IF(SUM(AJ4) * 0.3 - INT(SUM(AJ4) * 0.3) >= 0.5, ROUNDUP(SUM(AJ4) * 0.3, 0), ROUNDDOWN(SUM(AJ4) * 0.3, 0)), SUM(AJ4) * 0.3) -> 0 | BC4: =IF(INT(SUM(AK4) * 0.3) <> C3, IF(SUM(AK4) * 0.3 - INT(SUM(AK4) * 0.3) >= 0.5, ROUNDUP(SUM(AK4) * 0.3, 0), ROUNDDOWN(SUM(AK4) * 0.3, 0)), SUM(AK4) * 0.3) -> 0 | BD4: =IF(INT(SUM(AL4) * 0.3) <> D3, IF(SUM(AL4) * 0.3 - INT(SUM(AL4) * 0.3) >= 0.5, ROUNDUP(SUM(AL4) * 0.3, 0), ROUNDDOWN(SUM(AL4) * 0.3, 0)), SUM(AL4) * 0.3) -> 0 | BE4: =IF(INT(SUM(AM4) * 0.3) <> E3, IF(SUM(AM4) * 0.3 - INT(SUM(AM4) * 0.3) >= 0.5, ROUNDUP(SUM(AM4) * 0.3, 0), ROUNDDOWN(SUM(AM4) * 0.3, 0)), SUM(AM4) * 0.3) -> 0 | BF4: =IF(INT(SUM(AN4) * 0.3) <> G3, IF(SUM(AN4) * 0.3 - INT(SUM(AN4) * 0.3) >= 0.5, ROUNDUP(SUM(AN4) * 0.3, 0), ROUNDDOWN(SUM(AN4) * 0.3, 0)), SUM(AN4) * 0.3) -> 0 | BG4: =IF(INT(SUM(AO4) * 0.5) <> A3, IF(SUM(AO4) * 0.5 - INT(SUM(AO4) * 0.5) >= 0.5, ROUNDUP(SUM(AO4) * 0.5, 0), ROUNDDOWN(SUM(AO4) * 0.5, 0)), SUM(AO4) * 0.5) -> 0 | BH4: =IF(INT(SUM(AP4) * 0.5) <> B3, IF(SUM(AP4) * 0.5 - INT(SUM(AP4) * 0.5) >= 0.5, ROUNDUP(SUM(AP4) * 0.5, 0), ROUNDDOWN(SUM(AP4) * 0.5, 0)), SUM(AP4) * 0.5) -> 0 | BI4: =IF(INT(SUM(AQ4) * 0.5) <> C3, IF(SUM(AQ4) * 0.5 - INT(SUM(AQ4) * 0.5) >= 0.5, ROUNDUP(SUM(AQ4) * 0.5, 0), ROUNDDOWN(SUM(AQ4) * 0.5, 0)), SUM(AQ4) * 0.5) -> 0 | BJ4: =IF(INT(SUM(AR4) * 0.5) <> D3, IF(SUM(AR4) * 0.5 - INT(SUM(AR4) * 0.5) >= 0.5, ROUNDUP(SUM(AR4) * 0.5, 0), ROUNDDOWN(SUM(AR4) * 0.5, 0)), SUM(AR4) * 0.5) -> 0 | BK4: =IF(INT(SUM(AS4) * 0.5) <> E3, IF(SUM(AS4) * 0.5 - INT(SUM(AS4) * 0.5) >= 0.5, ROUNDUP(SUM(AS4) * 0.5, 0), ROUNDDOWN(SUM(AS4) * 0.5, 0)), SUM(AS4) * 0.5) -> 0 | BL4: =IF(INT(SUM(AT4) * 0.5) <> G3, IF(SUM(AT4) * 0.5 - INT(SUM(AT4) * 0.5) >= 0.5, ROUNDUP(SUM(AT4) * 0.5, 0), ROUNDDOWN(SUM(AT4) * 0.5, 0)), SUM(AT4) * 0.5) -> 0 | BM4: =SUM(AU4,BA4,BG4) -> 0 | BN4: =SUM(AV4,BB4,BH4) -> 0 | BO4: =SUM(AW4,BC4,BI4) -> 0 | BP4: =SUM(AX4,BD4,BJ4) -> 0 | BQ4: =SUM(AY4,BE4,BK4) -> 0 | BR4: =SUM(BM4:BQ4) -> 0 | BS4: =SUM(BM4:BQ4)/500*100 -> 0 | BT4: =IF(BS4>=80,"A+",IF(BS4>=70,"A",IF(BS4>=60,"B+",IF(BS4>=50,"B",IF(BS4>=40,"C",IF(BS4>=30,"E","FAIL")))))) -> FAIL
B5: ='Unit 1'!A5 -> 0 | C5: ='Unit 1'!B5 -> 0 | D5: ='Unit 1'!$H$2 -> 3 | E5: ='Unit 1'!C5 -> 0 | F5: ='Unit 1'!D5 -> 0 | G5: ='Unit 1'!E5 -> 0 | H5: ='Unit 1'!F5 -> 0 | I5: ='Unit 1'!G5 -> 0 | J5: =SUM(E5:I5) -> 0 | K5: ='Unit 2'!B5 -> 0 | L5: ='Unit 2'!C5 -> 0 | M5: ='Unit 2'!D5 -> 0 | N5: ='Unit 2'!E5 -> 0 | O5: ='Unit 2'!F5 -> 0 | P5: =SUM(K5:O5) -> 0 | Q5: ='Unit 3'!B5 -> 0 | R5: ='Unit 3'!C5 -> 0 | S5: ='Unit 3'!D5 -> 0 | T5: ='Unit 3'!E5 -> 0 | U5: ='Unit 3'!F5 -> 0 | V5: =SUM(Q5:U5) -> 0 | W5: ='Unit 4'!B5 -> 0 | X5: ='Unit 4'!C5 -> 0 | Y5: ='Unit 4'!D5 -> 0 | Z5: ='Unit 4'!E5 -> 0 | AA5: ='Unit 4'!F5 -> 0 | AB5: =SUM(W5:AA5) -> 0 | AC5: =SUM(E5,K5,Q5,W5,) -> 0 | AD5: =SUM(F5,L5,R5,X5,) -> 0 | AE5: =SUM(G5,M5,S5,Y5,) -> 0 | AF5: =SUM(H5,N5,T5,Z5,) -> 0 | AG5: =SUM(I5,O5,U5,AA5,) -> 0 | AH5: =SUM(AC5:AG5) -> 0 | AI5: ='Half yearly'!B5 -> 0 | AJ5: ='Half yearly'!C5 -> 0 | AK5: ='Half yearly'!D5 -> 0 | AL5: ='Half yearly'!E5 -> 0 | AM5: ='Half yearly'!F5 -> 0 | AN5: =SUM(AI5:AM5) -> 0 | AO5: =Annual!B5 -> 0 | AP5: =Annual!C5 -> 0 | AQ5: =Annual!D5 -> 0 | AR5: =Annual!E5 -> 0 | AS5: =Annual!F5 -> 0 | AT5: =SUM(AO5:AS5) -> 0 | AU5: =IF(INT(SUM(E5, K5, Q5, W5) * 0.2) <> A4, IF(SUM(E5, K5, Q5, W5) * 0.2 - INT(SUM(E5, K5, Q5, W5) * 0.2) >= 0.5, ROUNDUP(SUM(E5, K5, Q5, W5) * 0.2, 0), ROUNDDOWN(SUM(E5, K5, Q5, W5) * 0.2, 0)), SUM(E5, K5, Q5, W5) * 0.2) -> 0 | AV5: =IF(INT(SUM(F5, L5, R5, X5) * 0.2) <> B4, IF(SUM(F5, L5, R5, X5) * 0.2 - INT(SUM(F5, L5, R5, X5) * 0.2) >= 0.5, ROUNDUP(SUM(F5, L5, R5, X5) * 0.2, 0), ROUNDDOWN(SUM(F5, L5, R5, X5) * 0.2, 0)), SUM(F5, L5, R5, X5) * 0.2) -> 0 | AW5: =IF(INT(SUM(G5, M5, S5, Y5) * 0.2) <> C4, IF(SUM(G5, M5, S5, Y5) * 0.2 - INT(SUM(G5, M5, S5, Y5) * 0.2) >= 0.5, ROUNDUP(SUM(G5, M5, S5, Y5) * 0.2, 0), ROUNDDOWN(SUM(G5, M5, S5, Y5) * 0.2, 0)), SUM(G5, M5, S5, Y5) * 0.2) -> 0 | AX5: =IF(INT(SUM(H5, N5, T5, Z5) * 0.2) <> D4, IF(SUM(H5, N5, T5, Z5) * 0.2 - INT(SUM(H5, N5, T5, Z5) * 0.2) >= 0.5, ROUNDUP(SUM(H5, N5, T5, Z5) * 0.2, 0), ROUNDDOWN(SUM(H5, N5, T5, Z5) * 0.2, 0)), SUM(H5, N5, T5, Z5) * 0.2) -> 0 | AY5: =IF(INT(SUM(I5, O5, U5, AA5) * 0.2) <> E4, IF(SUM(I5, O5, U5, AA5) * 0.2 - INT(SUM(I5, O5, U5, AA5) * 0.2) >= 0.5, ROUNDUP(SUM(I5, O5, U5, AA5) * 0.2, 0), ROUNDDOWN(SUM(I5, O5, U5, AA5) * 0.2, 0)), SUM(I5, O5, U5, AA5) * 0.2) -> 0 | AZ5: =IF(INT(SUM(J5, P5, V5, AB5) * 0.2) <> G4, IF(SUM(J5, P5, V5, AB5) * 0.2 - INT(SUM(J5, P5, V5, AB5) * 0.2) >= 0.5, ROUNDUP(SUM(J5, P5, V5, AB5) * 0.2, 0), ROUNDDOWN(SUM(J5, P5, V5, AB5) * 0.2, 0)), SUM(J5, P5, V5, AB5) * 0.2) -> 0 | BA5: =IF(INT(SUM(AI5) * 0.3) <> A4, IF(SUM(AI5) * 0.3 - INT(SUM(AI5) * 0.3) >= 0.5, ROUNDUP(SUM(AI5) * 0.3, 0), ROUNDDOWN(SUM(AI5) * 0.3, 0)), SUM(AI5) * 0.3) -> 0 | BB5: =IF(INT(SUM(AJ5) * 0.3) <> B4, IF(SUM(AJ5) * 0.3 - INT(SUM(AJ5) * 0.3) >= 0.5, ROUNDUP(SUM(AJ5) * 0.3, 0), ROUNDDOWN(SUM(AJ5) * 0.3, 0)), SUM(AJ5) * 0.3) -> 0 | BC5: =IF(INT(SUM(AK5) * 0.3) <> C4, IF(SUM(AK5) * 0.3 - INT(SUM(AK5) * 0.3) >= 0.5, ROUNDUP(SUM(AK5) * 0.3, 0), ROUNDDOWN(SUM(AK5) * 0.3, 0)), SUM(AK5) * 0.3) -> 0 | BD5: =IF(INT(SUM(AL5) * 0.3) <> D4, IF(SUM(AL5) * 0.3 - INT(SUM(AL5) * 0.3) >= 0.5, ROUNDUP(SUM(AL5) * 0.3, 0), ROUNDDOWN(SUM(AL5) * 0.3, 0)), SUM(AL5) * 0.3) -> 0 | BE5: =IF(INT(SUM(AM5) * 0.3) <> E4, IF(SUM(AM5) * 0.3 - INT(SUM(AM5) * 0.3) >= 0.5, ROUNDUP(SUM(AM5) * 0.3, 0), ROUNDDOWN(SUM(AM5) * 0.3, 0)), SUM(AM5) * 0.3) -> 0 | BF5: =IF(INT(SUM(AN5) * 0.3) <> G4, IF(SUM(AN5) * 0.3 - INT(SUM(AN5) * 0.3) >= 0.5, ROUNDUP(SUM(AN5) * 0.3, 0), ROUNDDOWN(SUM(AN5) * 0.3, 0)), SUM(AN5) * 0.3) -> 0 | BG5: =IF(INT(SUM(AO5) * 0.5) <> A4, IF(SUM(AO5) * 0.5 - INT(SUM(AO5) * 0.5) >= 0.5, ROUNDUP(SUM(AO5) * 0.5, 0), ROUNDDOWN(SUM(AO5) * 0.5, 0)), SUM(AO5) * 0.5) -> 0 | BH5: =IF(INT(SUM(AP5) * 0.5) <> B4, IF(SUM(AP5) * 0.5 - INT(SUM(AP5) * 0.5) >= 0.5, ROUNDUP(SUM(AP5) * 0.5, 0), ROUNDDOWN(SUM(AP5) * 0.5, 0)), SUM(AP5) * 0.5) -> 0 | BI5: =IF(INT(SUM(AQ5) * 0.5) <> C4, IF(SUM(AQ5) * 0.5 - INT(SUM(AQ5) * 0.5) >= 0.5, ROUNDUP(SUM(AQ5) * 0.5, 0), ROUNDDOWN(SUM(AQ5) * 0.5, 0)), SUM(AQ5) * 0.5) -> 0 | BJ5: =IF(INT(SUM(AR5) * 0.5) <> D4, IF(SUM(AR5) * 0.5 - INT(SUM(AR5) * 0.5) >= 0.5, ROUNDUP(SUM(AR5) * 0.5, 0), ROUNDDOWN(SUM(AR5) * 0.5, 0)), SUM(AR5) * 0.5) -> 0 | BK5: =IF(INT(SUM(AS5) * 0.5) <> E4, IF(SUM(AS5) * 0.5 - INT(SUM(AS5) * 0.5) >= 0.5, ROUNDUP(SUM(AS5) * 0.5, 0), ROUNDDOWN(SUM(AS5) * 0.5, 0)), SUM(AS5) * 0.5) -> 0 | BL5: =IF(INT(SUM(AT5) * 0.5) <> G4, IF(SUM(AT5) * 0.5 - INT(SUM(AT5) * 0.5) >= 0.5, ROUNDUP(SUM(AT5) * 0.5, 0), ROUNDDOWN(SUM(AT5) * 0.5, 0)), SUM(AT5) * 0.5) -> 0 | BM5: =SUM(AU5,BA5,BG5) -> 0 | BN5: =SUM(AV5,BB5,BH5) -> 0 | BO5: =SUM(AW5,BC5,BI5) -> 0 | BP5: =SUM(AX5,BD5,BJ5) -> 0 | BQ5: =SUM(AY5,BE5,BK5) -> 0 | BR5: =SUM(BM5:BQ5) -> 0 | BS5: =SUM(BM5:BQ5)/500*100 -> 0 | BT5: =IF(BS5>=80,"A+",IF(BS5>=70,"A",IF(BS5>=60,"B+",IF(BS5>=50,"B",IF(BS5>=40,"C",IF(BS5>=30,"E","FAIL")))))) -> FAIL
B6: ='Unit 1'!A6 -> 0 | C6: ='Unit 1'!B6 -> 0 | D6: ='Unit 1'!$H$2 -> 3 | E6: ='Unit 1'!C6 -> 0 | F6: ='Unit 1'!D6 -> 0 | G6: ='Unit 1'!E6 -> 0 | H6: ='Unit 1'!F6 -> 0 | I6: ='Unit 1'!G6 -> 0 | J6: =SUM(E6:I6) -> 0 | K6: ='Unit 2'!B6 -> 0 | L6: ='Unit 2'!C6 -> 0 | M6: ='Unit 2'!D6 -> 0 | N6: ='Unit 2'!E6 -> 0 | O6: ='Unit 2'!F6 -> 0 | P6: =SUM(K6:O6) -> 0 | Q6: ='Unit 3'!B6 -> 0 | R6: ='Unit 3'!C6 -> 0 | S6: ='Unit 3'!D6 -> 0 | T6: ='Unit 3'!E6 -> 0 | U6: ='Unit 3'!F6 -> 0 | V6: =SUM(Q6:U6) -> 0 | W6: ='Unit 4'!B6 -> 0 | X6: ='Unit 4'!C6 -> 0 | Y6: ='Unit 4'!D6 -> 0 | Z6: ='Unit 4'!E6 -> 0 | AA6: ='Unit 4'!F6 -> 0 | AB6: =SUM(W6:AA6) -> 0 | AC6: =SUM(E6,K6,Q6,W6,) -> 0 | AD6: =SUM(F6,L6,R6,X6,) -> 0 | AE6: =SUM(G6,M6,S6,Y6,) -> 0 | AF6: =SUM(H6,N6,T6,Z6,) -> 0 | AG6: =SUM(I6,O6,U6,AA6,) -> 0 | AH6: =SUM(AC6:AG6) -> 0 | AI6: ='Half yearly'!B6 -> 0 | AJ6: ='Half yearly'!C6 -> 0 | AK6: ='Half yearly'!D6 -> 0 | AL6: ='Half yearly'!E6 -> 0 | AM6: ='Half yearly'!F6 -> 0 | AN6: =SUM(AI6:AM6) -> 0 | AO6: =Annual!B6 -> 0 | AP6: =Annual!C6 -> 0 | AQ6: =Annual!D6 -> 0 | AR6: =Annual!E6 -> 0 | AS6: =Annual!F6 -> 0 | AT6: =SUM(AO6:AS6) -> 0 | AU6: =IF(INT(SUM(E6, K6, Q6, W6) * 0.2) <> A5, IF(SUM(E6, K6, Q6, W6) * 0.2 - INT(SUM(E6, K6, Q6, W6) * 0.2) >= 0.5, ROUNDUP(SUM(E6, K6, Q6, W6) * 0.2, 0), ROUNDDOWN(SUM(E6, K6, Q6, W6) * 0.2, 0)), SUM(E6, K6, Q6, W6) * 0.2) -> 0 | AV6: =IF(INT(SUM(F6, L6, R6, X6) * 0.2) <> B5, IF(SUM(F6, L6, R6, X6) * 0.2 - INT(SUM(F6, L6, R6, X6) * 0.2) >= 0.5, ROUNDUP(SUM(F6, L6, R6, X6) * 0.2, 0), ROUNDDOWN(SUM(F6, L6, R6, X6) * 0.2, 0)), SUM(F6, L6, R6, X6) * 0.2) -> 0 | AW6: =IF(INT(SUM(G6, M6, S6, Y6) * 0.2) <> C5, IF(SUM(G6, M6, S6, Y6) * 0.2 - INT(SUM(G6, M6, S6, Y6) * 0.2) >= 0.5, ROUNDUP(SUM(G6, M6, S6, Y6) * 0.2, 0), ROUNDDOWN(SUM(G6, M6, S6, Y6) * 0.2, 0)), SUM(G6, M6, S6, Y6) * 0.2) -> 0 | AX6: =IF(INT(SUM(H6, N6, T6, Z6) * 0.2) <> D5, IF(SUM(H6, N6, T6, Z6) * 0.2 - INT(SUM(H6, N6, T6, Z6) * 0.2) >= 0.5, ROUNDUP(SUM(H6, N6, T6, Z6) * 0.2, 0), ROUNDDOWN(SUM(H6, N6, T6, Z6) * 0.2, 0)), SUM(H6, N6, T6, Z6) * 0.2) -> 0 | AY6: =IF(INT(SUM(I6, O6, U6, AA6) * 0.2) <> E5, IF(SUM(I6, O6, U6, AA6) * 0.2 - INT(SUM(I6, O6, U6, AA6) * 0.2) >= 0.5, ROUNDUP(SUM(I6, O6, U6, AA6) * 0.2, 0), ROUNDDOWN(SUM(I6, O6, U6, AA6) * 0.2, 0)), SUM(I6, O6, U6, AA6) * 0.2) -> 0 | AZ6: =IF(INT(SUM(J6, P6, V6, AB6) * 0.2) <> G5, IF(SUM(J6, P6, V6, AB6) * 0.2 - INT(SUM(J6, P6, V6, AB6) * 0.2) >= 0.5, ROUNDUP(SUM(J6, P6, V6, AB6) * 0.2, 0), ROUNDDOWN(SUM(J6, P6, V6, AB6) * 0.2, 0)), SUM(J6, P6, V6, AB6) * 0.2) -> 0 | BA6: =IF(INT(SUM(AI6) * 0.3) <> A5, IF(SUM(AI6) * 0.3 - INT(SUM(AI6) * 0.3) >= 0.5, ROUNDUP(SUM(AI6) * 0.3, 0), ROUNDDOWN(SUM(AI6) * 0.3, 0)), SUM(AI6) * 0.3) -> 0 | BB6: =IF(INT(SUM(AJ6) * 0.3) <> B5, IF(SUM(AJ6) * 0.3 - INT(SUM(AJ6) * 0.3) >= 0.5, ROUNDUP(SUM(AJ6) * 0.3, 0), ROUNDDOWN(SUM(AJ6) * 0.3, 0)), SUM(AJ6) * 0.3) -> 0 | BC6: =IF(INT(SUM(AK6) * 0.3) <> C5, IF(SUM(AK6) * 0.3 - INT(SUM(AK6) * 0.3) >= 0.5, ROUNDUP(SUM(AK6) * 0.3, 0), ROUNDDOWN(SUM(AK6) * 0.3, 0)), SUM(AK6) * 0.3) -> 0 | BD6: =IF(INT(SUM(AL6) * 0.3) <> D5, IF(SUM(AL6) * 0.3 - INT(SUM(AL6) * 0.3) >= 0.5, ROUNDUP(SUM(AL6) * 0.3, 0), ROUNDDOWN(SUM(AL6) * 0.3, 0)), SUM(AL6) * 0.3) -> 0 | BE6: =IF(INT(SUM(AM6) * 0.3) <> E5, IF(SUM(AM6) * 0.3 - INT(SUM(AM6) * 0.3) >= 0.5, ROUNDUP(SUM(AM6) * 0.3, 0), ROUNDDOWN(SUM(AM6) * 0.3, 0)), SUM(AM6) * 0.3) -> 0 | BF6: =IF(INT(SUM(AN6) * 0.3) <> G5, IF(SUM(AN6) * 0.3 - INT(SUM(AN6) * 0.3) >= 0.5, ROUNDUP(SUM(AN6) * 0.3, 0), ROUNDDOWN(SUM(AN6) * 0.3, 0)), SUM(AN6) * 0.3) -> 0 | BG6: =IF(INT(SUM(AO6) * 0.5) <> A5, IF(SUM(AO6) * 0.5 - INT(SUM(AO6) * 0.5) >= 0.5, ROUNDUP(SUM(AO6) * 0.5, 0), ROUNDDOWN(SUM(AO6) * 0.5, 0)), SUM(AO6) * 0.5) -> 0 | BH6: =IF(INT(SUM(AP6) * 0.5) <> B5, IF(SUM(AP6) * 0.5 - INT(SUM(AP6) * 0.5) >= 0.5, ROUNDUP(SUM(AP6) * 0.5, 0), ROUNDDOWN(SUM(AP6) * 0.5, 0)), SUM(AP6) * 0.5) -> 0 | BI6: =IF(INT(SUM(AQ6) * 0.5) <> C5, IF(SUM(AQ6) * 0.5 - INT(SUM(AQ6) * 0.5) >= 0.5, ROUNDUP(SUM(AQ6) * 0.5, 0), ROUNDDOWN(SUM(AQ6) * 0.5, 0)), SUM(AQ6) * 0.5) -> 0 | BJ6: =IF(INT(SUM(AR6) * 0.5) <> D5, IF(SUM(AR6) * 0.5 - INT(SUM(AR6) * 0.5) >= 0.5, ROUNDUP(SUM(AR6) * 0.5, 0), ROUNDDOWN(SUM(AR6) * 0.5, 0)), SUM(AR6) * 0.5) -> 0 | BK6: =IF(INT(SUM(AS6) * 0.5) <> E5, IF(SUM(AS6) * 0.5 - INT(SUM(AS6) * 0.5) >= 0.5, ROUNDUP(SUM(AS6) * 0.5, 0), ROUNDDOWN(SUM(AS6) * 0.5, 0)), SUM(AS6) * 0.5) -> 0 | BL6: =IF(INT(SUM(AT6) * 0.5) <> G5, IF(SUM(AT6) * 0.5 - INT(SUM(AT6) * 0.5) >= 0.5, ROUNDUP(SUM(AT6) * 0.5, 0), ROUNDDOWN(SUM(AT6) * 0.5, 0)), SUM(AT6) * 0.5) -> 0 | BM6: =SUM(AU6,BA6,BG6) -> 0 | BN6: =SUM(AV6,BB6,BH6) -> 0 | BO6: =SUM(AW6,BC6,BI6) -> 0 | BP6: =SUM(AX6,BD6,BJ6) -> 0 | BQ6: =SUM(AY6,BE6,BK6) -> 0 | BR6: =SUM(BM6:BQ6) -> 0 | BS6: =SUM(BM6:BQ6)/500*100 -> 0 | BT6: =IF(BS6>=80,"A+",IF(BS6>=70,"A",IF(BS6>=60,"B+",IF(BS6>=50,"B",IF(BS6>=40,"C",IF(BS6>=30,"E","FAIL")))))) -> FAIL
B7: ='Unit 1'!A7 -> 0 | C7: ='Unit 1'!B7 -> 0 | D7: ='Unit 1'!$H$2 -> 3 | E7: ='Unit 1'!C7 -> 0 | F7: ='Unit 1'!D7 -> 0 | G7: ='Unit 1'!E7 -> 0 | H7: ='Unit 1'!F7 -> 0 | I7: ='Unit 1'!G7 -> 0 | J7: =SUM(E7:I7) -> 0 | K7: ='Unit 2'!B7 -> 0 | L7: ='Unit 2'!C7 -> 0 | M7: ='Unit 2'!D7 -> 0 | N7: ='Unit 2'!E7 -> 0 | O7: ='Unit 2'!F7 -> 0 | P7: =SUM(K7:O7) -> 0 | Q7: ='Unit 3'!B7 -> 0 | R7: ='Unit 3'!C7 -> 0 | S7: ='Unit 3'!D7 -> 0 | T7: ='Unit 3'!E7 -> 0 | U7: ='Unit 3'!F7 -> 0 | V7: =SUM(Q7:U7) -> 0 | W7: ='Unit 4'!B7 -> 0 | X7: ='Unit 4'!C7 -> 0 | Y7: ='Unit 4'!D7 -> 0 | Z7: ='Unit 4'!E7 -> 0 | AA7: ='Unit 4'!F7 -> 0 | AB7: =SUM(W7:AA7) -> 0 | AC7: =SUM(E7,K7,Q7,W7,) -> 0 | AD7: =SUM(F7,L7,R7,X7,) -> 0 | AE7: =SUM(G7,M7,S7,Y7,) -> 0 | AF7: =SUM(H7,N7,T7,Z7,) -> 0 | AG7: =SUM(I7,O7,U7,AA7,) -> 0 | AH7: =SUM(AC7:AG7) -> 0 | AI7: ='Half yearly'!B7 -> 0 | AJ7: ='Half yearly'!C7 -> 0 | AK7: ='Half yearly'!D7 -> 0 | AL7: ='Half yearly'!E7 -> 0 | AM7: ='Half yearly'!F7 -> 0 | AN7: =SUM(AI7:AM7) -> 0 | AO7: =Annual!B7 -> 0 | AP7: =Annual!C7 -> 0 | AQ7: =Annual!D7 -> 0 | AR7: =Annual!E7 -> 0 | AS7: =Annual!F7 -> 0 | AT7: =SUM(AO7:AS7) -> 0 | AU7: =IF(INT(SUM(E7, K7, Q7, W7) * 0.2) <> A6, IF(SUM(E7, K7, Q7, W7) * 0.2 - INT(SUM(E7, K7, Q7, W7) * 0.2) >= 0.5, ROUNDUP(SUM(E7, K7, Q7, W7) * 0.2, 0), ROUNDDOWN(SUM(E7, K7, Q7, W7) * 0.2, 0)), SUM(E7, K7, Q7, W7) * 0.2) -> 0 | AV7: =IF(INT(SUM(F7, L7, R7, X7) * 0.2) <> B6, IF(SUM(F7, L7, R7, X7) * 0.2 - INT(SUM(F7, L7, R7, X7) * 0.2) >= 0.5, ROUNDUP(SUM(F7, L7, R7, X7) * 0.2, 0), ROUNDDOWN(SUM(F7, L7, R7, X7) * 0.2, 0)), SUM(F7, L7, R7, X7) * 0.2) -> 0 | AW7: =IF(INT(SUM(G7, M7, S7, Y7) * 0.2) <> C6, IF(SUM(G7, M7, S7, Y7) * 0.2 - INT(SUM(G7, M7, S7, Y7) * 0.2) >= 0.5, ROUNDUP(SUM(G7, M7, S7, Y7) * 0.2, 0), ROUNDDOWN(SUM(G7, M7, S7, Y7) * 0.2, 0)), SUM(G7, M7, S7, Y7) * 0.2) -> 0 | AX7: =IF(INT(SUM(H7, N7, T7, Z7) * 0.2) <> D6, IF(SUM(H7, N7, T7, Z7) * 0.2 - INT(SUM(H7, N7, T7, Z7) * 0.2) >= 0.5, ROUNDUP(SUM(H7, N7, T7, Z7) * 0.2, 0), ROUNDDOWN(SUM(H7, N7, T7, Z7) * 0.2, 0)), SUM(H7, N7, T7, Z7) * 0.2) -> 0 | AY7: =IF(INT(SUM(I7, O7, U7, AA7) * 0.2) <> E6, IF(SUM(I7, O7, U7, AA7) * 0.2 - INT(SUM(I7, O7, U7, AA7) * 0.2) >= 0.5, ROUNDUP(SUM(I7, O7, U7, AA7) * 0.2, 0), ROUNDDOWN(SUM(I7, O7, U7, AA7) * 0.2, 0)), SUM(I7, O7, U7, AA7) * 0.2) -> 0 | AZ7: =IF(INT(SUM(J7, P7, V7, AB7) * 0.2) <> G6, IF(SUM(J7, P7, V7, AB7) * 0.2 - INT(SUM(J7, P7, V7, AB7) * 0.2) >= 0.5, ROUNDUP(SUM(J7, P7, V7, AB7) * 0.2, 0), ROUNDDOWN(SUM(J7, P7, V7, AB7) * 0.2, 0)), SUM(J7, P7, V7, AB7) * 0.2) -> 0 | BA7: =IF(INT(SUM(AI7) * 0.3) <> A6, IF(SUM(AI7) * 0.3 - INT(SUM(AI7) * 0.3) >= 0.5, ROUNDUP(SUM(AI7) * 0.3, 0), ROUNDDOWN(SUM(AI7) * 0.3, 0)), SUM(AI7) * 0.3) -> 0 | BB7: =IF(INT(SUM(AJ7) * 0.3) <> B6, IF(SUM(AJ7) * 0.3 - INT(SUM(AJ7) * 0.3) >= 0.5, ROUNDUP(SUM(AJ7) * 0.3, 0), ROUNDDOWN(SUM(AJ7) * 0.3, 0)), SUM(AJ7) * 0.3) -> 0 | BC7: =IF(INT(SUM(AK7) * 0.3) <> C6, IF(SUM(AK7) * 0.3 - INT(SUM(AK7) * 0.3) >= 0.5, ROUNDUP(SUM(AK7) * 0.3, 0), ROUNDDOWN(SUM(AK7) * 0.3, 0)), SUM(AK7) * 0.3) -> 0 | BD7: =IF(INT(SUM(AL7) * 0.3) <> D6, IF(SUM(AL7) * 0.3 - INT(SUM(AL7) * 0.3) >= 0.5, ROUNDUP(SUM(AL7) * 0.3, 0), ROUNDDOWN(SUM(AL7) * 0.3, 0)), SUM(AL7) * 0.3) -> 0 | BE7: =IF(INT(SUM(AM7) * 0.3) <> E6, IF(SUM(AM7) * 0.3 - INT(SUM(AM7) * 0.3) >= 0.5, ROUNDUP(SUM(AM7) * 0.3, 0), ROUNDDOWN(SUM(AM7) * 0.3, 0)), SUM(AM7) * 0.3) -> 0 | BF7: =IF(INT(SUM(AN7) * 0.3) <> G6, IF(SUM(AN7) * 0.3 - INT(SUM(AN7) * 0.3) >= 0.5, ROUNDUP(SUM(AN7) * 0.3, 0), ROUNDDOWN(SUM(AN7) * 0.3, 0)), SUM(AN7) * 0.3) -> 0 | BG7: =IF(INT(SUM(AO7) * 0.5) <> A6, IF(SUM(AO7) * 0.5 - INT(SUM(AO7) * 0.5) >= 0.5, ROUNDUP(SUM(AO7) * 0.5, 0), ROUNDDOWN(SUM(AO7) * 0.5, 0)), SUM(AO7) * 0.5) -> 0 | BH7: =IF(INT(SUM(AP7) * 0.5) <> B6, IF(SUM(AP7) * 0.5 - INT(SUM(AP7) * 0.5) >= 0.5, ROUNDUP(SUM(AP7) * 0.5, 0), ROUNDDOWN(SUM(AP7) * 0.5, 0)), SUM(AP7) * 0.5) -> 0 | BI7: =IF(INT(SUM(AQ7) * 0.5) <> C6, IF(SUM(AQ7) * 0.5 - INT(SUM(AQ7) * 0.5) >= 0.5, ROUNDUP(SUM(AQ7) * 0.5, 0), ROUNDDOWN(SUM(AQ7) * 0.5, 0)), SUM(AQ7) * 0.5) -> 0 | BJ7: =IF(INT(SUM(AR7) * 0.5) <> D6, IF(SUM(AR7) * 0.5 - INT(SUM(AR7) * 0.5) >= 0.5, ROUNDUP(SUM(AR7) * 0.5, 0), ROUNDDOWN(SUM(AR7) * 0.5, 0)), SUM(AR7) * 0.5) -> 0 | BK7: =IF(INT(SUM(AS7) * 0.5) <> E6, IF(SUM(AS7) * 0.5 - INT(SUM(AS7) * 0.5) >= 0.5, ROUNDUP(SUM(AS7) * 0.5, 0), ROUNDDOWN(SUM(AS7) * 0.5, 0)), SUM(AS7) * 0.5) -> 0 | BL7: =IF(INT(SUM(AT7) * 0.5) <> G6, IF(SUM(AT7) * 0.5 - INT(SUM(AT7) * 0.5) >= 0.5, ROUNDUP(SUM(AT7) * 0.5, 0), ROUNDDOWN(SUM(AT7) * 0.5, 0)), SUM(AT7) * 0.5) -> 0 | BM7: =SUM(AU7,BA7,BG7) -> 0 | BN7: =SUM(AV7,BB7,BH7) -> 0 | BO7: =SUM(AW7,BC7,BI7) -> 0 | BP7: =SUM(AX7,BD7,BJ7) -> 0 | BQ7: =SUM(AY7,BE7,BK7) -> 0 | BR7: =SUM(BM7:BQ7) -> 0 | BS7: =SUM(BM7:BQ7)/500*100 -> 0 | BT7: =IF(BS7>=80,"A+",IF(BS7>=70,"A",IF(BS7>=60,"B+",IF(BS7>=50,"B",IF(BS7>=40,"C",IF(BS7>=30,"E","FAIL")))))) -> FAIL
B8: ='Unit 1'!A8 -> 0 | C8: ='Unit 1'!B8 -> 0 | D8: ='Unit 1'!$H$2 -> 3 | E8: ='Unit 1'!C8 -> 0 | F8: ='Unit 1'!D8 -> 0 | G8: ='Unit 1'!E8 -> 0 | H8: ='Unit 1'!F8 -> 0 | I8: ='Unit 1'!G8 -> 0 | J8: =SUM(E8:I8) -> 0 | K8: ='Unit 2'!B8 -> 0 | L8: ='Unit 2'!C8 -> 0 | M8: ='Unit 2'!D8 -> 0 | N8: ='Unit 2'!E8 -> 0 | O8: ='Unit 2'!F8 -> 0 | P8: =SUM(K8:O8) -> 0 | Q8: ='Unit 3'!B8 -> 0 | R8: ='Unit 3'!C8 -> 0 | S8: ='Unit 3'!D8 -> 0 | T8: ='Unit 3'!E8 -> 0 | U8: ='Unit 3'!F8 -> 0 | V8: =SUM(Q8:U8) -> 0 | W8: ='Unit 4'!B8 -> 0 | X8: ='Unit 4'!C8 -> 0 | Y8: ='Unit 4'!D8 -> 0 | Z8: ='Unit 4'!E8 -> 0 | AA8: ='Unit 4'!F8 -> 0 | AB8: =SUM(W8:AA8) -> 0 | AC8: =SUM(E8,K8,Q8,W8,) -> 0 | AD8: =SUM(F8,L8,R8,X8,) -> 0 | AE8: =SUM(G8,M8,S8,Y8,) -> 0 | AF8: =SUM(H8,N8,T8,Z8,) -> 0 | AG8: =SUM(I8,O8,U8,AA8,) -> 0 | AH8: =SUM(AC8:AG8) -> 0 | AI8: ='Half yearly'!B8 -> 0 | AJ8: ='Half yearly'!C8 -> 0 | AK8: ='Half yearly'!D8 -> 0 | AL8: ='Half yearly'!E8 -> 0 | AM8: ='Half yearly'!F8 -> 0 | AN8: =SUM(AI8:AM8) -> 0 | AO8: =Annual!B8 -> 0 | AP8: =Annual!C8 -> 0 | AQ8: =Annual!D8 -> 0 | AR8: =Annual!E8 -> 0 | AS8: =Annual!F8 -> 0 | AT8: =SUM(AO8:AS8) -> 0 | AU8: =IF(INT(SUM(E8, K8, Q8, W8) * 0.2) <> A7, IF(SUM(E8, K8, Q8, W8) * 0.2 - INT(SUM(E8, K8, Q8, W8) * 0.2) >= 0.5, ROUNDUP(SUM(E8, K8, Q8, W8) * 0.2, 0), ROUNDDOWN(SUM(E8, K8, Q8, W8) * 0.2, 0)), SUM(E8, K8, Q8, W8) * 0.2) -> 0 | AV8: =IF(INT(SUM(F8, L8, R8, X8) * 0.2) <> B7, IF(SUM(F8, L8, R8, X8) * 0.2 - INT(SUM(F8, L8, R8, X8) * 0.2) >= 0.5, ROUNDUP(SUM(F8, L8, R8, X8) * 0.2, 0), ROUNDDOWN(SUM(F8, L8, R8, X8) * 0.2, 0)), SUM(F8, L8, R8, X8) * 0.2) -> 0 | AW8: =IF(INT(SUM(G8, M8, S8, Y8) * 0.2) <> C7, IF(SUM(G8, M8, S8, Y8) * 0.2 - INT(SUM(G8, M8, S8, Y8) * 0.2) >= 0.5, ROUNDUP(SUM(G8, M8, S8, Y8) * 0.2, 0), ROUNDDOWN(SUM(G8, M8, S8, Y8) * 0.2, 0)), SUM(G8, M8, S8, Y8) * 0.2) -> 0 | AX8: =IF(INT(SUM(H8, N8, T8, Z8) * 0.2) <> D7, IF(SUM(H8, N8, T8, Z8) * 0.2 - INT(SUM(H8, N8, T8, Z8) * 0.2) >= 0.5, ROUNDUP(SUM(H8, N8, T8, Z8) * 0.2, 0), ROUNDDOWN(SUM(H8, N8, T8, Z8) * 0.2, 0)), SUM(H8, N8, T8, Z8) * 0.2) -> 0 | AY8: =IF(INT(SUM(I8, O8, U8, AA8) * 0.2) <> E7, IF(SUM(I8, O8, U8, AA8) * 0.2 - INT(SUM(I8, O8, U8, AA8) * 0.2) >= 0.5, ROUNDUP(SUM(I8, O8, U8, AA8) * 0.2, 0), ROUNDDOWN(SUM(I8, O8, U8, AA8) * 0.2, 0)), SUM(I8, O8, U8, AA8) * 0.2) -> 0 | AZ8: =IF(INT(SUM(J8, P8, V8, AB8) * 0.2) <> G7, IF(SUM(J8, P8, V8, AB8) * 0.2 - INT(SUM(J8, P8, V8, AB8) * 0.2) >= 0.5, ROUNDUP(SUM(J8, P8, V8, AB8) * 0.2, 0), ROUNDDOWN(SUM(J8, P8, V8, AB8) * 0.2, 0)), SUM(J8, P8, V8, AB8) * 0.2) -> 0 | BA8: =IF(INT(SUM(AI8) * 0.3) <> A7, IF(SUM(AI8) * 0.3 - INT(SUM(AI8) * 0.3) >= 0.5, ROUNDUP(SUM(AI8) * 0.3, 0), ROUNDDOWN(SUM(AI8) * 0.3, 0)), SUM(AI8) * 0.3) -> 0 | BB8: =IF(INT(SUM(AJ8) * 0.3) <> B7, IF(SUM(AJ8) * 0.3 - INT(SUM(AJ8) * 0.3) >= 0.5, ROUNDUP(SUM(AJ8) * 0.3, 0), ROUNDDOWN(SUM(AJ8) * 0.3, 0)), SUM(AJ8) * 0.3) -> 0 | BC8: =IF(INT(SUM(AK8) * 0.3) <> C7, IF(SUM(AK8) * 0.3 - INT(SUM(AK8) * 0.3) >= 0.5, ROUNDUP(SUM(AK8) * 0.3, 0), ROUNDDOWN(SUM(AK8) * 0.3, 0)), SUM(AK8) * 0.3) -> 0 | BD8: =IF(INT(SUM(AL8) * 0.3) <> D7, IF(SUM(AL8) * 0.3 - INT(SUM(AL8) * 0.3) >= 0.5, ROUNDUP(SUM(AL8) * 0.3, 0), ROUNDDOWN(SUM(AL8) * 0.3, 0)), SUM(AL8) * 0.3) -> 0 | BE8: =IF(INT(SUM(AM8) * 0.3) <> E7, IF(SUM(AM8) * 0.3 - INT(SUM(AM8) * 0.3) >= 0.5, ROUNDUP(SUM(AM8) * 0.3, 0), ROUNDDOWN(SUM(AM8) * 0.3, 0)), SUM(AM8) * 0.3) -> 0 | BF8: =IF(INT(SUM(AN8) * 0.3) <> G7, IF(SUM(AN8) * 0.3 - INT(SUM(AN8) * 0.3) >= 0.5, ROUNDUP(SUM(AN8) * 0.3, 0), ROUNDDOWN(SUM(AN8) * 0.3, 0)), SUM(AN8) * 0.3) -> 0 | BG8: =IF(INT(SUM(AO8) * 0.5) <> A7, IF(SUM(AO8) * 0.5 - INT(SUM(AO8) * 0.5) >= 0.5, ROUNDUP(SUM(AO8) * 0.5, 0), ROUNDDOWN(SUM(AO8) * 0.5, 0)), SUM(AO8) * 0.5) -> 0 | BH8: =IF(INT(SUM(AP8) * 0.5) <> B7, IF(SUM(AP8) * 0.5 - INT(SUM(AP8) * 0.5) >= 0.5, ROUNDUP(SUM(AP8) * 0.5, 0), ROUNDDOWN(SUM(AP8) * 0.5, 0)), SUM(AP8) * 0.5) -> 0 | BI8: =IF(INT(SUM(AQ8) * 0.5) <> C7, IF(SUM(AQ8) * 0.5 - INT(SUM(AQ8) * 0.5) >= 0.5, ROUNDUP(SUM(AQ8) * 0.5, 0), ROUNDDOWN(SUM(AQ8) * 0.5, 0)), SUM(AQ8) * 0.5) -> 0 | BJ8: =IF(INT(SUM(AR8) * 0.5) <> D7, IF(SUM(AR8) * 0.5 - INT(SUM(AR8) * 0.5) >= 0.5, ROUNDUP(SUM(AR8) * 0.5, 0), ROUNDDOWN(SUM(AR8) * 0.5, 0)), SUM(AR8) * 0.5) -> 0 | BK8: =IF(INT(SUM(AS8) * 0.5) <> E7, IF(SUM(AS8) * 0.5 - INT(SUM(AS8) * 0.5) >= 0.5, ROUNDUP(SUM(AS8) * 0.5, 0), ROUNDDOWN(SUM(AS8) * 0.5, 0)), SUM(AS8) * 0.5) -> 0 | BL8: =IF(INT(SUM(AT8) * 0.5) <> G7, IF(SUM(AT8) * 0.5 - INT(SUM(AT8) * 0.5) >= 0.5, ROUNDUP(SUM(AT8) * 0.5, 0), ROUNDDOWN(SUM(AT8) * 0.5, 0)), SUM(AT8) * 0.5) -> 0 | BM8: =SUM(AU8,BA8,BG8) -> 0 | BN8: =SUM(AV8,BB8,BH8) -> 0 | BO8: =SUM(AW8,BC8,BI8) -> 0 | BP8: =SUM(AX8,BD8,BJ8) -> 0 | BQ8: =SUM(AY8,BE8,BK8) -> 0 | BR8: =SUM(BM8:BQ8) -> 0 | BS8: =SUM(BM8:BQ8)/500*100 -> 0 | BT8: =IF(BS8>=80,"A+",IF(BS8>=70,"A",IF(BS8>=60,"B+",IF(BS8>=50,"B",IF(BS8>=40,"C",IF(BS8>=30,"E","FAIL")))))) -> FAIL
B9: ='Unit 1'!A9 -> 0 | C9: ='Unit 1'!B9 -> 0 | D9: ='Unit 1'!$H$2 -> 3 | E9: ='Unit 1'!C9 -> 0 | F9: ='Unit 1'!D9 -> 0 | G9: ='Unit 1'!E9 -> 0 | H9: ='Unit 1'!F9 -> 0 | I9: ='Unit 1'!G9 -> 0 | J9: =SUM(E9:I9) -> 0 | K9: ='Unit 2'!B9 -> 0 | L9: ='Unit 2'!C9 -> 0 | M9: ='Unit 2'!D9 -> 0 | N9: ='Unit 2'!E9 -> 0 | O9: ='Unit 2'!F9 -> 0 | P9: =SUM(K9:O9) -> 0 | Q9: ='Unit 3'!B9 -> 0 | R9: ='Unit 3'!C9 -> 0 | S9: ='Unit 3'!D9 -> 0 | T9: ='Unit 3'!E9 -> 0 | U9: ='Unit 3'!F9 -> 0 | V9: =SUM(Q9:U9) -> 0 | W9: ='Unit 4'!B9 -> 0 | X9: ='Unit 4'!C9 -> 0 | Y9: ='Unit 4'!D9 -> 0 | Z9: ='Unit 4'!E9 -> 0 | AA9: ='Unit 4'!F9 -> 0 | AB9: =SUM(W9:AA9) -> 0 | AC9: =SUM(E9,K9,Q9,W9,) -> 0 | AD9: =SUM(F9,L9,R9,X9,) -> 0 | AE9: =SUM(G9,M9,S9,Y9,) -> 0 | AF9: =SUM(H9,N9,T9,Z9,) -> 0 | AG9: =SUM(I9,O9,U9,AA9,) -> 0 | AH9: =SUM(AC9:AG9) -> 0 | AI9: ='Half yearly'!B9 -> 0 | AJ9: ='Half yearly'!C9 -> 0 | AK9: ='Half yearly'!D9 -> 0 | AL9: ='Half yearly'!E9 -> 0 | AM9: ='Half yearly'!F9 -> 0 | AN9: =SUM(AI9:AM9) -> 0 | AO9: =Annual!B9 -> 0 | AP9: =Annual!C9 -> 0 | AQ9: =Annual!D9 -> 0 | AR9: =Annual!E9 -> 0 | AS9: =Annual!F9 -> 0 | AT9: =SUM(AO9:AS9) -> 0 | AU9: =IF(INT(SUM(E9, K9, Q9, W9) * 0.2) <> A8, IF(SUM(E9, K9, Q9, W9) * 0.2 - INT(SUM(E9, K9, Q9, W9) * 0.2) >= 0.5, ROUNDUP(SUM(E9, K9, Q9, W9) * 0.2, 0), ROUNDDOWN(SUM(E9, K9, Q9, W9) * 0.2, 0)), SUM(E9, K9, Q9, W9) * 0.2) -> 0 | AV9: =IF(INT(SUM(F9, L9, R9, X9) * 0.2) <> B8, IF(SUM(F9, L9, R9, X9) * 0.2 - INT(SUM(F9, L9, R9, X9) * 0.2) >= 0.5, ROUNDUP(SUM(F9, L9, R9, X9) * 0.2, 0), ROUNDDOWN(SUM(F9, L9, R9, X9) * 0.2, 0)), SUM(F9, L9, R9, X9) * 0.2) -> 0 | AW9: =IF(INT(SUM(G9, M9, S9, Y9) * 0.2) <> C8, IF(SUM(G9, M9, S9, Y9) * 0.2 - INT(SUM(G9, M9, S9, Y9) * 0.2) >= 0.5, ROUNDUP(SUM(G9, M9, S9, Y9) * 0.2, 0), ROUNDDOWN(SUM(G9, M9, S9, Y9) * 0.2, 0)), SUM(G9, M9, S9, Y9) * 0.2) -> 0 | AX9: =IF(INT(SUM(H9, N9, T9, Z9) * 0.2) <> D8, IF(SUM(H9, N9, T9, Z9) * 0.2 - INT(SUM(H9, N9, T9, Z9) * 0.2) >= 0.5, ROUNDUP(SUM(H9, N9, T9, Z9) * 0.2, 0), ROUNDDOWN(SUM(H9, N9, T9, Z9) * 0.2, 0)), SUM(H9, N9, T9, Z9) * 0.2) -> 0 | AY9: =IF(INT(SUM(I9, O9, U9, AA9) * 0.2) <> E8, IF(SUM(I9, O9, U9, AA9) * 0.2 - INT(SUM(I9, O9, U9, AA9) * 0.2) >= 0.5, ROUNDUP(SUM(I9, O9, U9, AA9) * 0.2, 0), ROUNDDOWN(SUM(I9, O9, U9, AA9) * 0.2, 0)), SUM(I9, O9, U9, AA9) * 0.2) -> 0 | AZ9: =IF(INT(SUM(J9, P9, V9, AB9) * 0.2) <> G8, IF(SUM(J9, P9, V9, AB9) * 0.2 - INT(SUM(J9, P9, V9, AB9) * 0.2) >= 0.5, ROUNDUP(SUM(J9, P9, V9, AB9) * 0.2, 0), ROUNDDOWN(SUM(J9, P9, V9, AB9) * 0.2, 0)), SUM(J9, P9, V9, AB9) * 0.2) -> 0 | BA9: =IF(INT(SUM(AI9) * 0.3) <> A8, IF(SUM(AI9) * 0.3 - INT(SUM(AI9) * 0.3) >= 0.5, ROUNDUP(SUM(AI9) * 0.3, 0), ROUNDDOWN(SUM(AI9) * 0.3, 0)), SUM(AI9) * 0.3) -> 0 | BB9: =IF(INT(SUM(AJ9) * 0.3) <> B8, IF(SUM(AJ9) * 0.3 - INT(SUM(AJ9) * 0.3) >= 0.5, ROUNDUP(SUM(AJ9) * 0.3, 0), ROUNDDOWN(SUM(AJ9) * 0.3, 0)), SUM(AJ9) * 0.3) -> 0 | BC9: =IF(INT(SUM(AK9) * 0.3) <> C8, IF(SUM(AK9) * 0.3 - INT(SUM(AK9) * 0.3) >= 0.5, ROUNDUP(SUM(AK9) * 0.3, 0), ROUNDDOWN(SUM(AK9) * 0.3, 0)), SUM(AK9) * 0.3) -> 0 | BD9: =IF(INT(SUM(AL9) * 0.3) <> D8, IF(SUM(AL9) * 0.3 - INT(SUM(AL9) * 0.3) >= 0.5, ROUNDUP(SUM(AL9) * 0.3, 0), ROUNDDOWN(SUM(AL9) * 0.3, 0)), SUM(AL9) * 0.3) -> 0 | BE9: =IF(INT(SUM(AM9) * 0.3) <> E8, IF(SUM(AM9) * 0.3 - INT(SUM(AM9) * 0.3) >= 0.5, ROUNDUP(SUM(AM9) * 0.3, 0), ROUNDDOWN(SUM(AM9) * 0.3, 0)), SUM(AM9) * 0.3) -> 0 | BF9: =IF(INT(SUM(AN9) * 0.3) <> G8, IF(SUM(AN9) * 0.3 - INT(SUM(AN9) * 0.3) >= 0.5, ROUNDUP(SUM(AN9) * 0.3, 0), ROUNDDOWN(SUM(AN9) * 0.3, 0)), SUM(AN9) * 0.3) -> 0 | BG9: =IF(INT(SUM(AO9) * 0.5) <> A8, IF(SUM(AO9) * 0.5 - INT(SUM(AO9) * 0.5) >= 0.5, ROUNDUP(SUM(AO9) * 0.5, 0), ROUNDDOWN(SUM(AO9) * 0.5, 0)), SUM(AO9) * 0.5) -> 0 | BH9: =IF(INT(SUM(AP9) * 0.5) <> B8, IF(SUM(AP9) * 0.5 - INT(SUM(AP9) * 0.5) >= 0.5, ROUNDUP(SUM(AP9) * 0.5, 0), ROUNDDOWN(SUM(AP9) * 0.5, 0)), SUM(AP9) * 0.5) -> 0 | BI9: =IF(INT(SUM(AQ9) * 0.5) <> C8, IF(SUM(AQ9) * 0.5 - INT(SUM(AQ9) * 0.5) >= 0.5, ROUNDUP(SUM(AQ9) * 0.5, 0), ROUNDDOWN(SUM(AQ9) * 0.5, 0)), SUM(AQ9) * 0.5) -> 0 | BJ9: =IF(INT(SUM(AR9) * 0.5) <> D8, IF(SUM(AR9) * 0.5 - INT(SUM(AR9) * 0.5) >= 0.5, ROUNDUP(SUM(AR9) * 0.5, 0), ROUNDDOWN(SUM(AR9) * 0.5, 0)), SUM(AR9) * 0.5) -> 0 | BK9: =IF(INT(SUM(AS9) * 0.5) <> E8, IF(SUM(AS9) * 0.5 - INT(SUM(AS9) * 0.5) >= 0.5, ROUNDUP(SUM(AS9) * 0.5, 0), ROUNDDOWN(SUM(AS9) * 0.5, 0)), SUM(AS9) * 0.5) -> 0 | BL9: =IF(INT(SUM(AT9) * 0.5) <> G8, IF(SUM(AT9) * 0.5 - INT(SUM(AT9) * 0.5) >= 0.5, ROUNDUP(SUM(AT9) * 0.5, 0), ROUNDDOWN(SUM(AT9) * 0.5, 0)), SUM(AT9) * 0.5) -> 0 | BM9: =SUM(AU9,BA9,BG9) -> 0 | BN9: =SUM(AV9,BB9,BH9) -> 0 | BO9: =SUM(AW9,BC9,BI9) -> 0 | BP9: =SUM(AX9,BD9,BJ9) -> 0 | BQ9: =SUM(AY9,BE9,BK9) -> 0 | BR9: =SUM(BM9:BQ9) -> 0 | BS9: =SUM(BM9:BQ9)/500*100 -> 0 | BT9: =IF(BS9>=80,"A+",IF(BS9>=70,"A",IF(BS9>=60,"B+",IF(BS9>=50,"B",IF(BS9>=40,"C",IF(BS9>=30,"E","FAIL")))))) -> FAIL
B10: ='Unit 1'!A10 -> 0 | C10: ='Unit 1'!B10 -> 0 | D10: ='Unit 1'!$H$2 -> 3 | E10: ='Unit 1'!C10 -> 0 | F10: ='Unit 1'!D10 -> 0 | G10: ='Unit 1'!E10 -> 0 | H10: ='Unit 1'!F10 -> 0 | I10: ='Unit 1'!G10 -> 0 | J10: =SUM(E10:I10) -> 0 | K10: ='Unit 2'!B10 -> 0 | L10: ='Unit 2'!C10 -> 0 | M10: ='Unit 2'!D10 -> 0 | N10: ='Unit 2'!E10 -> 0 | O10: ='Unit 2'!F10 -> 0 | P10: =SUM(K10:O10) -> 0 | Q10: ='Unit 3'!B10 -> 0 | R10: ='Unit 3'!C10 -> 0 | S10: ='Unit 3'!D10 -> 0 | T10: ='Unit 3'!E10 -> 0 | U10: ='Unit 3'!F10 -> 0 | V10: =SUM(Q10:U10) -> 0 | W10: ='Unit 4'!B10 -> 0 | X10: ='Unit 4'!C10 -> 0 | Y10: ='Unit 4'!D10 -> 0 | Z10: ='Unit 4'!E10 -> 0 | AA10: ='Unit 4'!F10 -> 0 | AB10: =SUM(W10:AA10) -> 0 | AC10: =SUM(E10,K10,Q10,W10,) -> 0 | AD10: =SUM(F10,L10,R10,X10,) -> 0 | AE10: =SUM(G10,M10,S10,Y10,) -> 0 | AF10: =SUM(H10,N10,T10,Z10,) -> 0 | AG10: =SUM(I10,O10,U10,AA10,) -> 0 | AH10: =SUM(AC10:AG10) -> 0 | AI10: ='Half yearly'!B10 -> 0 | AJ10: ='Half yearly'!C10 -> 0 | AK10: ='Half yearly'!D10 -> 0 | AL10: ='Half yearly'!E10 -> 0 | AM10: ='Half yearly'!F10 -> 0 | AN10: =SUM(AI10:AM10) -> 0 | AO10: =Annual!B10 -> 0 | AP10: =Annual!C10 -> 0 | AQ10: =Annual!D10 -> 0 | AR10: =Annual!E10 -> 0 | AS10: =Annual!F10 -> 0 | AT10: =SUM(AO10:AS10) -> 0 | AU10: =IF(INT(SUM(E10, K10, Q10, W10) * 0.2) <> A9, IF(SUM(E10, K10, Q10, W10) * 0.2 - INT(SUM(E10, K10, Q10, W10) * 0.2) >= 0.5, ROUNDUP(SUM(E10, K10, Q10, W10) * 0.2, 0), ROUNDDOWN(SUM(E10, K10, Q10, W10) * 0.2, 0)), SUM(E10, K10, Q10, W10) * 0.2) -> 0 | AV10: =IF(INT(SUM(F10, L10, R10, X10) * 0.2) <> B9, IF(SUM(F10, L10, R10, X10) * 0.2 - INT(SUM(F10, L10, R10, X10) * 0.2) >= 0.5, ROUNDUP(SUM(F10, L10, R10, X10) * 0.2, 0), ROUNDDOWN(SUM(F10, L10, R10, X10) * 0.2, 0)), SUM(F10, L10, R10, X10) * 0.2) -> 0 | AW10: =IF(INT(SUM(G10, M10, S10, Y10) * 0.2) <> C9, IF(SUM(G10, M10, S10, Y10) * 0.2 - INT(SUM(G10, M10, S10, Y10) * 0.2) >= 0.5, ROUNDUP(SUM(G10, M10, S10, Y10) * 0.2, 0), ROUNDDOWN(SUM(G10, M10, S10, Y10) * 0.2, 0)), SUM(G10, M10, S10, Y10) * 0.2) -> 0 | AX10: =IF(INT(SUM(H10, N10, T10, Z10) * 0.2) <> D9, IF(SUM(H10, N10, T10, Z10) * 0.2 - INT(SUM(H10, N10, T10, Z10) * 0.2) >= 0.5, ROUNDUP(SUM(H10, N10, T10, Z10) * 0.2, 0), ROUNDDOWN(SUM(H10, N10, T10, Z10) * 0.2, 0)), SUM(H10, N10, T10, Z10) * 0.2) -> 0 | AY10: =IF(INT(SUM(I10, O10, U10, AA10) * 0.2) <> E9, IF(SUM(I10, O10, U10, AA10) * 0.2 - INT(SUM(I10, O10, U10, AA10) * 0.2) >= 0.5, ROUNDUP(SUM(I10, O10, U10, AA10) * 0.2, 0), ROUNDDOWN(SUM(I10, O10, U10, AA10) * 0.2, 0)), SUM(I10, O10, U10, AA10) * 0.2) -> 0 | AZ10: =IF(INT(SUM(J10, P10, V10, AB10) * 0.2) <> G9, IF(SUM(J10, P10, V10, AB10) * 0.2 - INT(SUM(J10, P10, V10, AB10) * 0.2) >= 0.5, ROUNDUP(SUM(J10, P10, V10, AB10) * 0.2, 0), ROUNDDOWN(SUM(J10, P10, V10, AB10) * 0.2, 0)), SUM(J10, P10, V10, AB10) * 0.2) -> 0 | BA10: =IF(INT(SUM(AI10) * 0.3) <> A9, IF(SUM(AI10) * 0.3 - INT(SUM(AI10) * 0.3) >= 0.5, ROUNDUP(SUM(AI10) * 0.3, 0), ROUNDDOWN(SUM(AI10) * 0.3, 0)), SUM(AI10) * 0.3) -> 0 | BB10: =IF(INT(SUM(AJ10) * 0.3) <> B9, IF(SUM(AJ10) * 0.3 - INT(SUM(AJ10) * 0.3) >= 0.5, ROUNDUP(SUM(AJ10) * 0.3, 0), ROUNDDOWN(SUM(AJ10) * 0.3, 0)), SUM(AJ10) * 0.3) -> 0 | BC10: =IF(INT(SUM(AK10) * 0.3) <> C9, IF(SUM(AK10) * 0.3 - INT(SUM(AK10) * 0.3) >= 0.5, ROUNDUP(SUM(AK10) * 0.3, 0), ROUNDDOWN(SUM(AK10) * 0.3, 0)), SUM(AK10) * 0.3) -> 0 | BD10: =IF(INT(SUM(AL10) * 0.3) <> D9, IF(SUM(AL10) * 0.3 - INT(SUM(AL10) * 0.3) >= 0.5, ROUNDUP(SUM(AL10) * 0.3, 0), ROUNDDOWN(SUM(AL10) * 0.3, 0)), SUM(AL10) * 0.3) -> 0 | BE10: =IF(INT(SUM(AM10) * 0.3) <> E9, IF(SUM(AM10) * 0.3 - INT(SUM(AM10) * 0.3) >= 0.5, ROUNDUP(SUM(AM10) * 0.3, 0), ROUNDDOWN(SUM(AM10) * 0.3, 0)), SUM(AM10) * 0.3) -> 0 | BF10: =IF(INT(SUM(AN10) * 0.3) <> G9, IF(SUM(AN10) * 0.3 - INT(SUM(AN10) * 0.3) >= 0.5, ROUNDUP(SUM(AN10) * 0.3, 0), ROUNDDOWN(SUM(AN10) * 0.3, 0)), SUM(AN10) * 0.3) -> 0 | BG10: =IF(INT(SUM(AO10) * 0.5) <> A9, IF(SUM(AO10) * 0.5 - INT(SUM(AO10) * 0.5) >= 0.5, ROUNDUP(SUM(AO10) * 0.5, 0), ROUNDDOWN(SUM(AO10) * 0.5, 0)), SUM(AO10) * 0.5) -> 0 | BH10: =IF(INT(SUM(AP10) * 0.5) <> B9, IF(SUM(AP10) * 0.5 - INT(SUM(AP10) * 0.5) >= 0.5, ROUNDUP(SUM(AP10) * 0.5, 0), ROUNDDOWN(SUM(AP10) * 0.5, 0)), SUM(AP10) * 0.5) -> 0 | BI10: =IF(INT(SUM(AQ10) * 0.5) <> C9, IF(SUM(AQ10) * 0.5 - INT(SUM(AQ10) * 0.5) >= 0.5, ROUNDUP(SUM(AQ10) * 0.5, 0), ROUNDDOWN(SUM(AQ10) * 0.5, 0)), SUM(AQ10) * 0.5) -> 0 | BJ10: =IF(INT(SUM(AR10) * 0.5) <> D9, IF(SUM(AR10) * 0.5 - INT(SUM(AR10) * 0.5) >= 0.5, ROUNDUP(SUM(AR10) * 0.5, 0), ROUNDDOWN(SUM(AR10) * 0.5, 0)), SUM(AR10) * 0.5) -> 0 | BK10: =IF(INT(SUM(AS10) * 0.5) <> E9, IF(SUM(AS10) * 0.5 - INT(SUM(AS10) * 0.5) >= 0.5, ROUNDUP(SUM(AS10) * 0.5, 0), ROUNDDOWN(SUM(AS10) * 0.5, 0)), SUM(AS10) * 0.5) -> 0 | BL10: =IF(INT(SUM(AT10) * 0.5) <> G9, IF(SUM(AT10) * 0.5 - INT(SUM(AT10) * 0.5) >= 0.5, ROUNDUP(SUM(AT10) * 0.5, 0), ROUNDDOWN(SUM(AT10) * 0.5, 0)), SUM(AT10) * 0.5) -> 0 | BM10: =SUM(AU10,BA10,BG10) -> 0 | BN10: =SUM(AV10,BB10,BH10) -> 0 | BO10: =SUM(AW10,BC10,BI10) -> 0 | BP10: =SUM(AX10,BD10,BJ10) -> 0 | BQ10: =SUM(AY10,BE10,BK10) -> 0 | BR10: =SUM(BM10:BQ10) -> 0 | BS10: =SUM(BM10:BQ10)/500*100 -> 0 | BT10: =IF(BS10>=80,"A+",IF(BS10>=70,"A",IF(BS10>=60,"B+",IF(BS10>=50,"B",IF(BS10>=40,"C",IF(BS10>=30,"E","FAIL")))))) -> FAIL
B11: ='Unit 1'!A11 -> 0 | C11: ='Unit 1'!B11 -> 0 | D11: ='Unit 1'!$H$2 -> 3 | E11: ='Unit 1'!C11 -> 0 | F11: ='Unit 1'!D11 -> 0 | G11: ='Unit 1'!E11 -> 0 | H11: ='Unit 1'!F11 -> 0 | I11: ='Unit 1'!G11 -> 0 | J11: =SUM(E11:I11) -> 0 | K11: ='Unit 2'!B11 -> 0 | L11: ='Unit 2'!C11 -> 0 | M11: ='Unit 2'!D11 -> 0 | N11: ='Unit 2'!E11 -> 0 | O11: ='Unit 2'!F11 -> 0 | P11: =SUM(K11:O11) -> 0 | Q11: ='Unit 3'!B11 -> 0 | R11: ='Unit 3'!C11 -> 0 | S11: ='Unit 3'!D11 -> 0 | T11: ='Unit 3'!E11 -> 0 | U11: ='Unit 3'!F11 -> 0 | V11: =SUM(Q11:U11) -> 0 | W11: ='Unit 4'!B11 -> 0 | X11: ='Unit 4'!C11 -> 0 | Y11: ='Unit 4'!D11 -> 0 | Z11: ='Unit 4'!E11 -> 0 | AA11: ='Unit 4'!F11 -> 0 | AB11: =SUM(W11:AA11) -> 0 | AC11: =SUM(E11,K11,Q11,W11,) -> 0 | AD11: =SUM(F11,L11,R11,X11,) -> 0 | AE11: =SUM(G11,M11,S11,Y11,) -> 0 | AF11: =SUM(H11,N11,T11,Z11,) -> 0 | AG11: =SUM(I11,O11,U11,AA11,) -> 0 | AH11: =SUM(AC11:AG11) -> 0 | AI11: ='Half yearly'!B11 -> 0 | AJ11: ='Half yearly'!C11 -> 0 | AK11: ='Half yearly'!D11 -> 0 | AL11: ='Half yearly'!E11 -> 0 | AM11: ='Half yearly'!F11 -> 0 | AN11: =SUM(AI11:AM11) -> 0 | AO11: =Annual!B11 -> 0 | AP11: =Annual!C11 -> 0 | AQ11: =Annual!D11 -> 0 | AR11: =Annual!E11 -> 0 | AS11: =Annual!F11 -> 0 | AT11: =SUM(AO11:AS11) -> 0 | AU11: =IF(INT(SUM(E11, K11, Q11, W11) * 0.2) <> A10, IF(SUM(E11, K11, Q11, W11) * 0.2 - INT(SUM(E11, K11, Q11, W11) * 0.2) >= 0.5, ROUNDUP(SUM(E11, K11, Q11, W11) * 0.2, 0), ROUNDDOWN(SUM(E11, K11, Q11, W11) * 0.2, 0)), SUM(E11, K11, Q11, W11) * 0.2) -> 0 | AV11: =IF(INT(SUM(F11, L11, R11, X11) * 0.2) <> B10, IF(SUM(F11, L11, R11, X11) * 0.2 - INT(SUM(F11, L11, R11, X11) * 0.2) >= 0.5, ROUNDUP(SUM(F11, L11, R11, X11) * 0.2, 0), ROUNDDOWN(SUM(F11, L11, R11, X11) * 0.2, 0)), SUM(F11, L11, R11, X11) * 0.2) -> 0 | AW11: =IF(INT(SUM(G11, M11, S11, Y11) * 0.2) <> C10, IF(SUM(G11, M11, S11, Y11) * 0.2 - INT(SUM(G11, M11, S11, Y11) * 0.2) >= 0.5, ROUNDUP(SUM(G11, M11, S11, Y11) * 0.2, 0), ROUNDDOWN(SUM(G11, M11, S11, Y11) * 0.2, 0)), SUM(G11, M11, S11, Y11) * 0.2) -> 0 | AX11: =IF(INT(SUM(H11, N11, T11, Z11) * 0.2) <> D10, IF(SUM(H11, N11, T11, Z11) * 0.2 - INT(SUM(H11, N11, T11, Z11) * 0.2) >= 0.5, ROUNDUP(SUM(H11, N11, T11, Z11) * 0.2, 0), ROUNDDOWN(SUM(H11, N11, T11, Z11) * 0.2, 0)), SUM(H11, N11, T11, Z11) * 0.2) -> 0 | AY11: =IF(INT(SUM(I11, O11, U11, AA11) * 0.2) <> E10, IF(SUM(I11, O11, U11, AA11) * 0.2 - INT(SUM(I11, O11, U11, AA11) * 0.2) >= 0.5, ROUNDUP(SUM(I11, O11, U11, AA11) * 0.2, 0), ROUNDDOWN(SUM(I11, O11, U11, AA11) * 0.2, 0)), SUM(I11, O11, U11, AA11) * 0.2) -> 0 | AZ11: =IF(INT(SUM(J11, P11, V11, AB11) * 0.2) <> G10, IF(SUM(J11, P11, V11, AB11) * 0.2 - INT(SUM(J11, P11, V11, AB11) * 0.2) >= 0.5, ROUNDUP(SUM(J11, P11, V11, AB11) * 0.2, 0), ROUNDDOWN(SUM(J11, P11, V11, AB11) * 0.2, 0)), SUM(J11, P11, V11, AB11) * 0.2) -> 0 | BA11: =IF(INT(SUM(AI11) * 0.3) <> A10, IF(SUM(AI11) * 0.3 - INT(SUM(AI11) * 0.3) >= 0.5, ROUNDUP(SUM(AI11) * 0.3, 0), ROUNDDOWN(SUM(AI11) * 0.3, 0)), SUM(AI11) * 0.3) -> 0 | BB11: =IF(INT(SUM(AJ11) * 0.3) <> B10, IF(SUM(AJ11) * 0.3 - INT(SUM(AJ11) * 0.3) >= 0.5, ROUNDUP(SUM(AJ11) * 0.3, 0), ROUNDDOWN(SUM(AJ11) * 0.3, 0)), SUM(AJ11) * 0.3) -> 0 | BC11: =IF(INT(SUM(AK11) * 0.3) <> C10, IF(SUM(AK11) * 0.3 - INT(SUM(AK11) * 0.3) >= 0.5, ROUNDUP(SUM(AK11) * 0.3, 0), ROUNDDOWN(SUM(AK11) * 0.3, 0)), SUM(AK11) * 0.3) -> 0 | BD11: =IF(INT(SUM(AL11) * 0.3) <> D10, IF(SUM(AL11) * 0.3 - INT(SUM(AL11) * 0.3) >= 0.5, ROUNDUP(SUM(AL11) * 0.3, 0), ROUNDDOWN(SUM(AL11) * 0.3, 0)), SUM(AL11) * 0.3) -> 0 | BE11: =IF(INT(SUM(AM11) * 0.3) <> E10, IF(SUM(AM11) * 0.3 - INT(SUM(AM11) * 0.3) >= 0.5, ROUNDUP(SUM(AM11) * 0.3, 0), ROUNDDOWN(SUM(AM11) * 0.3, 0)), SUM(AM11) * 0.3) -> 0 | BF11: =IF(INT(SUM(AN11) * 0.3) <> G10, IF(SUM(AN11) * 0.3 - INT(SUM(AN11) * 0.3) >= 0.5, ROUNDUP(SUM(AN11) * 0.3, 0), ROUNDDOWN(SUM(AN11) * 0.3, 0)), SUM(AN11) * 0.3) -> 0 | BG11: =IF(INT(SUM(AO11) * 0.5) <> A10, IF(SUM(AO11) * 0.5 - INT(SUM(AO11) * 0.5) >= 0.5, ROUNDUP(SUM(AO11) * 0.5, 0), ROUNDDOWN(SUM(AO11) * 0.5, 0)), SUM(AO11) * 0.5) -> 0 | BH11: =IF(INT(SUM(AP11) * 0.5) <> B10, IF(SUM(AP11) * 0.5 - INT(SUM(AP11) * 0.5) >= 0.5, ROUNDUP(SUM(AP11) * 0.5, 0), ROUNDDOWN(SUM(AP11) * 0.5, 0)), SUM(AP11) * 0.5) -> 0 | BI11: =IF(INT(SUM(AQ11) * 0.5) <> C10, IF(SUM(AQ11) * 0.5 - INT(SUM(AQ11) * 0.5) >= 0.5, ROUNDUP(SUM(AQ11) * 0.5, 0), ROUNDDOWN(SUM(AQ11) * 0.5, 0)), SUM(AQ11) * 0.5) -> 0 | BJ11: =IF(INT(SUM(AR11) * 0.5) <> D10, IF(SUM(AR11) * 0.5 - INT(SUM(AR11) * 0.5) >= 0.5, ROUNDUP(SUM(AR11) * 0.5, 0), ROUNDDOWN(SUM(AR11) * 0.5, 0)), SUM(AR11) * 0.5) -> 0 | BK11: =IF(INT(SUM(AS11) * 0.5) <> E10, IF(SUM(AS11) * 0.5 - INT(SUM(AS11) * 0.5) >= 0.5, ROUNDUP(SUM(AS11) * 0.5, 0), ROUNDDOWN(SUM(AS11) * 0.5, 0)), SUM(AS11) * 0.5) -> 0 | BL11: =IF(INT(SUM(AT11) * 0.5) <> G10, IF(SUM(AT11) * 0.5 - INT(SUM(AT11) * 0.5) >= 0.5, ROUNDUP(SUM(AT11) * 0.5, 0), ROUNDDOWN(SUM(AT11) * 0.5, 0)), SUM(AT11) * 0.5) -> 0 | BM11: =SUM(AU11,BA11,BG11) -> 0 | BN11: =SUM(AV11,BB11,BH11) -> 0 | BO11: =SUM(AW11,BC11,BI11) -> 0 | BP11: =SUM(AX11,BD11,BJ11) -> 0 | BQ11: =SUM(AY11,BE11,BK11) -> 0 | BR11: =SUM(BM11:BQ11) -> 0 | BS11: =SUM(BM11:BQ11)/500*100 -> 0 | BT11: =IF(BS11>=80,"A+",IF(BS11>=70,"A",IF(BS11>=60,"B+",IF(BS11>=50,"B",IF(BS11>=40,"C",IF(BS11>=30,"E","FAIL")))))) -> FAIL
B12: ='Unit 1'!A12 -> 0 | C12: ='Unit 1'!B12 -> 0 | D12: ='Unit 1'!$H$2 -> 3 | E12: ='Unit 1'!C12 -> 0 | F12: ='Unit 1'!D12 -> 0 | G12: ='Unit 1'!E12 -> 0 | H12: ='Unit 1'!F12 -> 0 | I12: ='Unit 1'!G12 -> 0 | J12: =SUM(E12:I12) -> 0 | K12: ='Unit 2'!B12 -> 0 | L12: ='Unit 2'!C12 -> 0 | M12: ='Unit 2'!D12 -> 0 | N12: ='Unit 2'!E12 -> 0 | O12: ='Unit 2'!F12 -> 0 | P12: =SUM(K12:O12) -> 0 | Q12: ='Unit 3'!B12 -> 0 | R12: ='Unit 3'!C12 -> 0 | S12: ='Unit 3'!D12 -> 0 | T12: ='Unit 3'!E12 -> 0 | U12: ='Unit 3'!F12 -> 0 | V12: =SUM(Q12:U12) -> 0 | W12: ='Unit 4'!B12 -> 0 | X12: ='Unit 4'!C12 -> 0 | Y12: ='Unit 4'!D12 -> 0 | Z12: ='Unit 4'!E12 -> 0 | AA12: ='Unit 4'!F12 -> 0 | AB12: =SUM(W12:AA12) -> 0 | AC12: =SUM(E12,K12,Q12,W12,) -> 0 | AD12: =SUM(F12,L12,R12,X12,) -> 0 | AE12: =SUM(G12,M12,S12,Y12,) -> 0 | AF12: =SUM(H12,N12,T12,Z12,) -> 0 | AG12: =SUM(I12,O12,U12,AA12,) -> 0 | AH12: =SUM(AC12:AG12) -> 0 | AI12: ='Half yearly'!B12 -> 0 | AJ12: ='Half yearly'!C12 -> 0 | AK12: ='Half yearly'!D12 -> 0 | AL12: ='Half yearly'!E12 -> 0 | AM12: ='Half yearly'!F12 -> 0 | AN12: =SUM(AI12:AM12) -> 0 | AO12: =Annual!B12 -> 0 | AP12: =Annual!C12 -> 0 | AQ12: =Annual!D12 -> 0 | AR12: =Annual!E12 -> 0 | AS12: =Annual!F12 -> 0 | AT12: =SUM(AO12:AS12) -> 0 | AU12: =IF(INT(SUM(E12, K12, Q12, W12) * 0.2) <> A11, IF(SUM(E12, K12, Q12, W12) * 0.2 - INT(SUM(E12, K12, Q12, W12) * 0.2) >= 0.5, ROUNDUP(SUM(E12, K12, Q12, W12) * 0.2, 0), ROUNDDOWN(SUM(E12, K12, Q12, W12) * 0.2, 0)), SUM(E12, K12, Q12, W12) * 0.2) -> 0 | AV12: =IF(INT(SUM(F12, L12, R12, X12) * 0.2) <> B11, IF(SUM(F12, L12, R12, X12) * 0.2 - INT(SUM(F12, L12, R12, X12) * 0.2) >= 0.5, ROUNDUP(SUM(F12, L12, R12, X12) * 0.2, 0), ROUNDDOWN(SUM(F12, L12, R12, X12) * 0.2, 0)), SUM(F12, L12, R12, X12) * 0.2) -> 0 | AW12: =IF(INT(SUM(G12, M12, S12, Y12) * 0.2) <> C11, IF(SUM(G12, M12, S12, Y12) * 0.2 - INT(SUM(G12, M12, S12, Y12) * 0.2) >= 0.5, ROUNDUP(SUM(G12, M12, S12, Y12) * 0.2, 0), ROUNDDOWN(SUM(G12, M12, S12, Y12) * 0.2, 0)), SUM(G12, M12, S12, Y12) * 0.2) -> 0 | AX12: =IF(INT(SUM(H12, N12, T12, Z12) * 0.2) <> D11, IF(SUM(H12, N12, T12, Z12) * 0.2 - INT(SUM(H12, N12, T12, Z12) * 0.2) >= 0.5, ROUNDUP(SUM(H12, N12, T12, Z12) * 0.2, 0), ROUNDDOWN(SUM(H12, N12, T12, Z12) * 0.2, 0)), SUM(H12, N12, T12, Z12) * 0.2) -> 0 | AY12: =IF(INT(SUM(I12, O12, U12, AA12) * 0.2) <> E11, IF(SUM(I12, O12, U12, AA12) * 0.2 - INT(SUM(I12, O12, U12, AA12) * 0.2) >= 0.5, ROUNDUP(SUM(I12, O12, U12, AA12) * 0.2, 0), ROUNDDOWN(SUM(I12, O12, U12, AA12) * 0.2, 0)), SUM(I12, O12, U12, AA12) * 0.2) -> 0 | AZ12: =IF(INT(SUM(J12, P12, V12, AB12) * 0.2) <> G11, IF(SUM(J12, P12, V12, AB12) * 0.2 - INT(SUM(J12, P12, V12, AB12) * 0.2) >= 0.5, ROUNDUP(SUM(J12, P12, V12, AB12) * 0.2, 0), ROUNDDOWN(SUM(J12, P12, V12, AB12) * 0.2, 0)), SUM(J12, P12, V12, AB12) * 0.2) -> 0 | BA12: =IF(INT(SUM(AI12) * 0.3) <> A11, IF(SUM(AI12) * 0.3 - INT(SUM(AI12) * 0.3) >= 0.5, ROUNDUP(SUM(AI12) * 0.3, 0), ROUNDDOWN(SUM(AI12) * 0.3, 0)), SUM(AI12) * 0.3) -> 0 | BB12: =IF(INT(SUM(AJ12) * 0.3) <> B11, IF(SUM(AJ12) * 0.3 - INT(SUM(AJ12) * 0.3) >= 0.5, ROUNDUP(SUM(AJ12) * 0.3, 0), ROUNDDOWN(SUM(AJ12) * 0.3, 0)), SUM(AJ12) * 0.3) -> 0 | BC12: =IF(INT(SUM(AK12) * 0.3) <> C11, IF(SUM(AK12) * 0.3 - INT(SUM(AK12) * 0.3) >= 0.5, ROUNDUP(SUM(AK12) * 0.3, 0), ROUNDDOWN(SUM(AK12) * 0.3, 0)), SUM(AK12) * 0.3) -> 0 | BD12: =IF(INT(SUM(AL12) * 0.3) <> D11, IF(SUM(AL12) * 0.3 - INT(SUM(AL12) * 0.3) >= 0.5, ROUNDUP(SUM(AL12) * 0.3, 0), ROUNDDOWN(SUM(AL12) * 0.3, 0)), SUM(AL12) * 0.3) -> 0 | BE12: =IF(INT(SUM(AM12) * 0.3) <> E11, IF(SUM(AM12) * 0.3 - INT(SUM(AM12) * 0.3) >= 0.5, ROUNDUP(SUM(AM12) * 0.3, 0), ROUNDDOWN(SUM(AM12) * 0.3, 0)), SUM(AM12) * 0.3) -> 0 | BF12: =IF(INT(SUM(AN12) * 0.3) <> G11, IF(SUM(AN12) * 0.3 - INT(SUM(AN12) * 0.3) >= 0.5, ROUNDUP(SUM(AN12) * 0.3, 0), ROUNDDOWN(SUM(AN12) * 0.3, 0)), SUM(AN12) * 0.3) -> 0 | BG12: =IF(INT(SUM(AO12) * 0.5) <> A11, IF(SUM(AO12) * 0.5 - INT(SUM(AO12) * 0.5) >= 0.5, ROUNDUP(SUM(AO12) * 0.5, 0), ROUNDDOWN(SUM(AO12) * 0.5, 0)), SUM(AO12) * 0.5) -> 0 | BH12: =IF(INT(SUM(AP12) * 0.5) <> B11, IF(SUM(AP12) * 0.5 - INT(SUM(AP12) * 0.5) >= 0.5, ROUNDUP(SUM(AP12) * 0.5, 0), ROUNDDOWN(SUM(AP12) * 0.5, 0)), SUM(AP12) * 0.5) -> 0 | BI12: =IF(INT(SUM(AQ12) * 0.5) <> C11, IF(SUM(AQ12) * 0.5 - INT(SUM(AQ12) * 0.5) >= 0.5, ROUNDUP(SUM(AQ12) * 0.5, 0), ROUNDDOWN(SUM(AQ12) * 0.5, 0)), SUM(AQ12) * 0.5) -> 0 | BJ12: =IF(INT(SUM(AR12) * 0.5) <> D11, IF(SUM(AR12) * 0.5 - INT(SUM(AR12) * 0.5) >= 0.5, ROUNDUP(SUM(AR12) * 0.5, 0), ROUNDDOWN(SUM(AR12) * 0.5, 0)), SUM(AR12) * 0.5) -> 0 | BK12: =IF(INT(SUM(AS12) * 0.5) <> E11, IF(SUM(AS12) * 0.5 - INT(SUM(AS12) * 0.5) >= 0.5, ROUNDUP(SUM(AS12) * 0.5, 0), ROUNDDOWN(SUM(AS12) * 0.5, 0)), SUM(AS12) * 0.5) -> 0 | BL12: =IF(INT(SUM(AT12) * 0.5) <> G11, IF(SUM(AT12) * 0.5 - INT(SUM(AT12) * 0.5) >= 0.5, ROUNDUP(SUM(AT12) * 0.5, 0), ROUNDDOWN(SUM(AT12) * 0.5, 0)), SUM(AT12) * 0.5) -> 0 | BM12: =SUM(AU12,BA12,BG12) -> 0 | BN12: =SUM(AV12,BB12,BH12) -> 0 | BO12: =SUM(AW12,BC12,BI12) -> 0 | BP12: =SUM(AX12,BD12,BJ12) -> 0 | BQ12: =SUM(AY12,BE12,BK12) -> 0 | BR12: =SUM(BM12:BQ12) -> 0 | BS12: =SUM(BM12:BQ12)/500*100 -> 0 | BT12: =IF(BS12>=80,"A+",IF(BS12>=70,"A",IF(BS12>=60,"B+",IF(BS12>=50,"B",IF(BS12>=40,"C",IF(BS12>=30,"E","FAIL")))))) -> FAIL
