Workbook

Sheet Unit 1
A1: Roll No | B1: Name | C1: English | D1: Bengali | E1: G Maths | F1: GK & Dr | G1: Class
G2: i

Sheet Unit 2
A1: Roll No | B1: English | C1: Bengali | D1: G Maths | E1: GK & Dr
A2: ='Unit 1'!A2 -> 0

Sheet Half yearly
A1: Roll No | B1: English | C1: Bengali | D1: G Maths | E1: GK & Dr
A2: ='Unit 1'!A2 -> 0

Sheet Unit 3
A1: Roll No | B1: English | C1: Bengali | D1: G Maths | E1: GK & Dr
A2: ='Unit 1'!A2 -> 0

Sheet Unit 4
A1: Roll No | B1: English | C1: Bengali | D1: G Maths | E1: GK & Dr
A2: ='Unit 1'!A2 -> 0

Sheet Annual
A1: Roll No | B1: English | C1: Bengali | D1: G Maths | E1: GK & Dr
A2: ='Unit 1'!A2 -> 0

Sheet Calculation
A1: New Roll | B1: Roll | C1: Name | D1: Class | E1: English unit 1 | F1: Bengali unit 1 | G1: G maths unit 1 | H1: S Science unit 1 | I1: Total Unit 1 | J1: English unit 2 | K1: Bengali unit 2 | L1: G maths unit 2 | M1: S Science unit 2 | N1: Total Unit 2 | O1: English unit 3 | P1: Bengali unit 3 | Q1: G maths unit 3 | R1: S Science unit 3 | S1: Total Unit 3 | T1: English unit 4 | U1: Bengali unit 4 | V1: G maths unit 4 | W1: S Science unit 4 | X1: Total Unit 4 | Y1: English Total | Z1: Bengali Total | AA1: G maths Total | AB1: S Science Total | AC1: Total Total | AD1: English Helf | AE1: Bengali Helf | AF1: G maths Helf | AG1: S Science Helf | AH1: Total Helf | AI1: English Annual | AJ1: Bengali Annual | AK1: G maths Annual | AL1: S Science Annual | AM1: Total Annual | AN1: English 20 % of Unit test | AO1: Bengali 20% of unit test | AP1: Gen Math 20% of unit test | AQ1: S Science 20% of unit test | AR1: Total of 20 % of unit test | AS1: English 30 % of halfyearly | AT1: Bengali 30% of halfyearly | AU1: Gen Math 30% of halfyearly | AV1: S Science 30% of halyearly | AW1: Total of 30 % of half | AX1: English 50 % of Annual | AY1: Bengali 50% of Annual | AZ1: Gen Math 50% of Annual | BA1: S Science 50% of Annual | BB1: Total of 50% of Annual Exam | BC1: English Grand total | BD1: Bengali Grand total | BE1: Gen Math grand total | BF1: S Science Grand total | BG1: Total of Grand Total | BH1: Percentage | BI1: Grade
B2: ='Unit 1'!A2 -> 0 | C2: ='Unit 1'!B2 -> 0 | D2: ='Unit 1'!$G$2 -> i | E2: ='Unit 1'!C2 -> 0 | F2: ='Unit 1'!D2 -> 0 | G2: ='Unit 1'!E2 -> 0 | H2: ='Unit 1'!F2 -> 0 | I2: =SUM(E2:H2) -> 0 | J2: ='Unit 2'!B2 -> 0 | K2: ='Unit 2'!C2 -> 0 | L2: ='Unit 2'!D2 -> 0 | M2: ='Unit 2'!E2 -> 0 | N2: =SUM(J2:M2) -> 0 | O2: ='Unit 3'!B2 -> 0 | P2: ='Unit 3'!C2 -> 0 | Q2: ='Unit 3'!D2 -> 0 | R2: ='Unit 3'!E2 -> 0 | S2: =SUM(O2:R2) -> 0 | T2: ='Unit 4'!B2 -> 0 | U2: ='Unit 4'!C2 -> 0 | V2: ='Unit 4'!D2 -> 0 | W2: ='Unit 4'!E2 -> 0 | X2: =SUM(T2:W2) -> 0 | Y2: =SUM(E2,J2,O2,T2,) -> 0 | Z2: =SUM(F2,K2,P2,U2,) -> 0 | AA2: =SUM(G2,L2,Q2,V2,) -> 0 | AB2: =SUM(H2,M2,R2,W2,) -> 0 | AC2: =SUM(Y2:AB2) -> 0 | AD2: ='Half yearly'!B2 -> 0 | AE2: ='Half yearly'!C2 -> 0 | AF2: ='Half yearly'!D2 -> 0 | AG2: ='Half yearly'!E2 -> 0 | AH2: =SUM(AD2:AG2) -> 0 | AI2: =Annual!B2 -> 0 | AJ2: =Annual!C2 -> 0 | AK2: =Annual!D2 -> 0 | AL2: =Annual!E2 -> 0 | AM2: =SUM(AI2:AL2) -> 0 | AN2: =IF(INT(SUM(E2, J2, O2, T2) * 0.2) <> A1, IF(SUM(E2, J2, O2, T2) * 0.2 - INT(SUM(E2, J2, O2, T2) * 0.2) >= 0.5, ROUNDUP(SUM(E2, J2, O2, T2) * 0.2, 0), ROUNDDOWN(SUM(E2, J2, O2, T2) * 0.2, 0)), SUM(E2, J2, O2, T2) * 0.2) -> 0 | AO2: =IF(INT(SUM(F2, K2, P2, U2) * 0.2) <> B1, IF(SUM(F2, K2, P2, U2) * 0.2 - INT(SUM(F2, K2, P2, U2) * 0.2) >= 0.5, ROUNDUP(SUM(F2, K2, P2, U2) * 0.2, 0), ROUNDDOWN(SUM(F2, K2, P2, U2) * 0.2, 0)), SUM(F2, K2, P2, U2) * 0.2) -> 0 | AP2: =IF(INT(SUM(G2, L2, Q2, V2) * 0.2) <> C1, IF(SUM(G2, L2, Q2, V2) * 0.2 - INT(SUM(G2, L2, Q2, V2) * 0.2) >= 0.5, ROUNDUP(SUM(G2, L2, Q2, V2) * 0.2, 0), ROUNDDOWN(SUM(G2, L2, Q2, V2) * 0.2, 0)), SUM(G2, L2, Q2, V2) * 0.2) -> 0 | AQ2: =IF(INT(SUM(H2, M2, R2, W2) * 0.2) <> E1, IF(SUM(H2, M2, R2, W2) * 0.2 - INT(SUM(H2, M2, R2, W2) * 0.2) >= 0.5, ROUNDUP(SUM(H2, M2, R2, W2) * 0.2, 0), ROUNDDOWN(SUM(H2, M2, R2, W2) * 0.2, 0)), SUM(H2, M2, R2, W2) * 0.2) -> 0 | AR2: =IF(INT(SUM(I2, N2, S2, X2) * 0.2) <> G1, IF(SUM(I2, N2, S2, X2) * 0.2 - INT(SUM(I2, N2, S2, X2) * 0.2) >= 0.5, ROUNDUP(SUM(I2, N2, S2, X2) * 0.2, 0), ROUNDDOWN(SUM(I2, N2, S2, X2) * 0.2, 0)), SUM(I2, N2, S2, X2) * 0.2) -> 0 | AS2: =IF(INT(SUM(AD2) * 0.3) <> A1, IF(SUM(AD2) * 0.3 - INT(SUM(AD2) * 0.3) >= 0.5, ROUNDUP(SUM(AD2) * 0.3, 0), ROUNDDOWN(SUM(AD2) * 0.3, 0)), SUM(AD2) * 0.3) -> 0 | AT2: =IF(INT(SUM(AE2) * 0.3) <> B1, IF(SUM(AE2) * 0.3 - INT(SUM(AE2) * 0.3) >= 0.5, ROUNDUP(SUM(AE2) * 0.3, 0), ROUNDDOWN(SUM(AE2) * 0.3, 0)), SUM(AE2) * 0.3) -> 0 | AU2: =IF(INT(SUM(AF2) * 0.3) <> C1, IF(SUM(AF2) * 0.3 - INT(SUM(AF2) * 0.3) >= 0.5, ROUNDUP(SUM(AF2) * 0.3, 0), ROUNDDOWN(SUM(AF2) * 0.3, 0)), SUM(AF2) * 0.3) -> 0 | AV2: =IF(INT(SUM(AG2) * 0.3) <> E1, IF(SUM(AG2) * 0.3 - INT(SUM(AG2) * 0.3) >= 0.5, ROUNDUP(SUM(AG2) * 0.3, 0), ROUNDDOWN(SUM(AG2) * 0.3, 0)), SUM(AG2) * 0.3) -> 0 | AW2: =IF(INT(SUM(AH2) * 0.3) <> G1, IF(SUM(AH2) * 0.3 - INT(SUM(AH2) * 0.3) >= 0.5, ROUNDUP(SUM(AH2) * 0.3, 0), ROUNDDOWN(SUM(AH2) * 0.3, 0)), SUM(AH2) * 0.3) -> 0 | AX2: =IF(INT(SUM(AI2) * 0.5) <> A1, IF(SUM(AI2) * 0.5 - INT(SUM(AI2) * 0.5) >= 0.5, ROUNDUP(SUM(AI2) * 0.5, 0), ROUNDDOWN(SUM(AI2) * 0.5, 0)), SUM(AI2) * 0.5) -> 0 | AY2: =IF(INT(SUM(AJ2) * 0.5) <> B1, IF(SUM(AJ2) * 0.5 - INT(SUM(AJ2) * 0.5) >= 0.5, ROUNDUP(SUM(AJ2) * 0.5, 0), ROUNDDOWN(SUM(AJ2) * 0.5, 0)), SUM(AJ2) * 0.5) -> 0 | AZ2: =IF(INT(SUM(AK2) * 0.5) <> C1, IF(SUM(AK2) * 0.5 - INT(SUM(AK2) * 0.5) >= 0.5, ROUNDUP(SUM(AK2) * 0.5, 0), ROUNDDOWN(SUM(AK2) * 0.5, 0)), SUM(AK2) * 0.5) -> 0 | BA2: =IF(INT(SUM(AL2) * 0.5) <> E1, IF(SUM(AL2) * 0.5 - INT(SUM(AL2) * 0.5) >= 0.5, ROUNDUP(SUM(AL2) * 0.5, 0), ROUNDDOWN(SUM(AL2) * 0.5, 0)), SUM(AL2) * 0.5) -> 0 | BB2: =IF(INT(SUM(AM2) * 0.5) <> G1, IF(SUM(AM2) * 0.5 - INT(SUM(AM2) * 0.5) >= 0.5, ROUNDUP(SUM(AM2) * 0.5, 0), ROUNDDOWN(SUM(AM2) * 0.5, 0)), SUM(AM2) * 0.5) -> 0 | BC2: =SUM(AN2,AS2,AX2) -> 0 | BD2: =SUM(AO2,AT2,AY2) -> 0 | BE2: =SUM(AP2,AU2,AZ2) -> 0 | BF2: =SUM(AQ2,AV2,BA2) -> 0 | BG2: =SUM(BC2:BF2) -> 0 | BH2: =SUM(BC2:BF2)/400*100 -> 0 | BI2: =IF(BH2>=80,"A+",IF(BH2>=70,"A",IF(BH2>=60,"B+",IF(BH2>=50,"B",IF(BH2>=40,"C",IF(BH2>=30,"E","FAIL")))))) -> FAIL
B3: ='Unit 1'!A3 -> 0 | C3: ='Unit 1'!B3 -> 0 | D3: ='Unit 1'!$G$2 -> i | E3: ='Unit 1'!C3 -> 0 | F3: ='Unit 1'!D3 -> 0 | G3: ='Unit 1'!E3 -> 0 | H3: ='Unit 1'!F3 -> 0 | I3: =SUM(E3:H3) -> 0 | J3: ='Unit 2'!B3 -> 0 | K3: ='Unit 2'!C3 -> 0 | L3: ='Unit 2'!D3 -> 0 | M3: ='Unit 2'!E3 -> 0 | N3: =SUM(J3:M3) -> 0 | O3: ='Unit 3'!B3 -> 0 | P3: ='Unit 3'!C3 -> 0 | Q3: ='Unit 3'!D3 -> 0 | R3: ='Unit 3'!E3 -> 0 | S3: =SUM(O3:R3) -> 0 | T3: ='Unit 4'!B3 -> 0 | U3: ='Unit 4'!C3 -> 0 | V3: ='Unit 4'!D3 -> 0 | W3: ='Unit 4'!E3 -> 0 | X3: =SUM(T3:W3) -> 0 | Y3: =SUM(E3,J3,O3,T3,) -> 0 | Z3: =SUM(F3,K3,P3,U3,) -> 0 | AA3: =SUM(G3,L3,Q3,V3,) -> 0 | AB3: =SUM(H3,M3,R3,W3,) -> 0 | AC3: =SUM(Y3:AB3) -> 0 | AD3: ='Half yearly'!B3 -> 0 | AE3: ='Half yearly'!C3 -> 0 | AF3: ='Half yearly'!D3 -> 0 | AG3: ='Half yearly'!E3 -> 0 | AH3: =SUM(AD3:AG3) -> 0 | AI3: =Annual!B3 -> 0 | AJ3: =Annual!C3 -> 0 | AK3: =Annual!D3 -> 0 | AL3: =Annual!E3 -> 0 | AM3: =SUM(AI3:AL3) -> 0 | AN3: =IF(INT(SUM(E3, J3, O3, T3) * 0.2) <> A2, IF(SUM(E3, J3, O3, T3) * 0.2 - INT(SUM(E3, J3, O3, T3) * 0.2) >= 0.5, ROUNDUP(SUM(E3, J3, O3, T3) * 0.2, 0), ROUNDDOWN(SUM(E3, J3, O3, T3) * 0.2, 0)), SUM(E3, J3, O3, T3) * 0.2) -> 0 | AO3: =IF(INT(SUM(F3, K3, P3, U3) * 0.2) <> B2, IF(SUM(F3, K3, P3, U3) * 0.2 - INT(SUM(F3, K3, P3, U3) * 0.2) >= 0.5, ROUNDUP(SUM(F3, K3, P3, U3) * 0.2, 0), ROUNDDOWN(SUM(F3, K3, P3, U3) * 0.2, 0)), SUM(F3, K3, P3, U3) * 0.2) -> 0 | AP3: =IF(INT(SUM(G3, L3, Q3, V3) * 0.2) <> C2, IF(SUM(G3, L3, Q3, V3) * 0.2 - INT(SUM(G3, L3, Q3, V3) * 0.2) >= 0.5, ROUNDUP(SUM(G3, L3, Q3, V3) * 0.2, 0), ROUNDDOWN(SUM(G3, L3, Q3, V3) * 0.2, 0)), SUM(G3, L3, Q3, V3) * 0.2) -> 0 | AQ3: =IF(INT(SUM(H3, M3, R3, W3) * 0.2) <> E2, IF(SUM(H3, M3, R3, W3) * 0.2 - INT(SUM(H3, M3, R3, W3) * 0.2) >= 0.5, ROUNDUP(SUM(H3, M3, R3, W3) * 0.2, 0), ROUNDDOWN(SUM(H3, M3, R3, W3) * 0.2, 0)), SUM(H3, M3, R3, W3) * 0.2) -> 0 | AR3: =IF(INT(SUM(I3, N3, S3, X3) * 0.2) <> G2, IF(SUM(I3, N3, S3, X3) * 0.2 - INT(SUM(I3, N3, S3, X3) * 0.2) >= 0.5, ROUNDUP(SUM(I3, N3, S3, X3) * 0.2, 0), ROUNDDOWN(SUM(I3, N3, S3, X3) * 0.2, 0)), SUM(I3, N3, S3, X3) * 0.2) -> 0 | AS3: =IF(INT(SUM(AD3) * 0.3) <> A2, IF(SUM(AD3) * 0.3 - INT(SUM(AD3) * 0.3) >= 0.5, ROUNDUP(SUM(AD3) * 0.3, 0), ROUNDDOWN(SUM(AD3) * 0.3, 0)), SUM(AD3) * 0.3) -> 0 | AT3: =IF(INT(SUM(AE3) * 0.3) <> B2, IF(SUM(AE3) * 0.3 - INT(SUM(AE3) * 0.3) >= 0.5, ROUNDUP(SUM(AE3) * 0.3, 0), ROUNDDOWN(SUM(AE3) * 0.3, 0)), SUM(AE3) * 0.3) -> 0 | AU3: =IF(INT(SUM(AF3) * 0.3) <> C2, IF(SUM(AF3) * 0.3 - INT(SUM(AF3) * 0.3) >= 0.5, ROUNDUP(SUM(AF3) * 0.3, 0), ROUNDDOWN(SUM(AF3) * 0.3, 0)), SUM(AF3) * 0.3) -> 0 | AV3: =IF(INT(SUM(AG3) * 0.3) <> E2, IF(SUM(AG3) * 0.3 - INT(SUM(AG3) * 0.3) >= 0.5, ROUNDUP(SUM(AG3) * 0.3, 0), ROUNDDOWN(SUM(AG3) * 0.3, 0)), SUM(AG3) * 0.3) -> 0 | AW3: =IF(INT(SUM(AH3) * 0.3) <> G2, IF(SUM(AH3) * 0.3 - INT(SUM(AH3) * 0.3) >= 0.5, ROUNDUP(SUM(AH3) * 0.3, 0), ROUNDDOWN(SUM(AH3) * 0.3, 0)), SUM(AH3) * 0.3) -> 0 | AX3: =IF(INT(SUM(AI3) * 0.5) <> A2, IF(SUM(AI3) * 0.5 - INT(SUM(AI3) * 0.5) >= 0.5, ROUNDUP(SUM(AI3) * 0.5, 0), ROUNDDOWN(SUM(AI3) * 0.5, 0)), SUM(AI3) * 0.5) -> 0 | AY3: =IF(INT(SUM(AJ3) * 0.5) <> B2, IF(SUM(AJ3) * 0.5 - INT(SUM(AJ3) * 0.5) >= 0.5, ROUNDUP(SUM(AJ3) * 0.5, 0), ROUNDDOWN(SUM(AJ3) * 0.5, 0)), SUM(AJ3) * 0.5) -> 0 | AZ3: =IF(INT(SUM(AK3) * 0.5) <> C2, IF(SUM(AK3) * 0.5 - INT(SUM(AK3) * 0.5) >= 0.5, ROUNDUP(SUM(AK3) * 0.5, 0), ROUNDDOWN(SUM(AK3) * 0.5, 0)), SUM(AK3) * 0.5) -> 0 | BA3: =IF(INT(SUM(AL3) * 0.5) <> E2, IF(SUM(AL3) * 0.5 - INT(SUM(AL3) * 0.5) >= 0.5, ROUNDUP(SUM(AL3) * 0.5, 0), ROUNDDOWN(SUM(AL3) * 0.5, 0)), SUM(AL3) * 0.5) -> 0 | BB3: =IF(INT(SUM(AM3) * 0.5) <> G2, IF(SUM(AM3) * 0.5 - INT(SUM(AM3) * 0.5) >= 0.5, ROUNDUP(SUM(AM3) * 0.5, 0), ROUNDDOWN(SUM(AM3) * 0.5, 0)), SUM(AM3) * 0.5) -> 0 | BC3: =SUM(AN3,AS3,AX3) -> 0 | BD3: =SUM(AO3,AT3,AY3) -> 0 | BE3: =SUM(AP3,AU3,AZ3) -> 0 | BF3: =SUM(AQ3,AV3,BA3) -> 0 | BG3: =SUM(BC3:BF3) -> 0 | BH3: =SUM(BC3:BF3)/500*100 -> 0 | BI3: =IF(BH3>=80,"A+",IF(BH3>=70,"A",IF(BH3>=60,"B+",IF(BH3>=50,"B",IF(BH3>=40,"C",IF(BH3>=30,"E","FAIL")))))) -> FAIL
B4: ='Unit 1'!A4 -> 0 | C4: ='Unit 1'!B4 -> 0 | D4: ='Unit 1'!$G$2 -> i | E4: ='Unit 1'!C4 -> 0 | F4: ='Unit 1'!D4 -> 0 | G4: ='Unit 1'!E4 -> 0 | H4: ='Unit 1'!F4 -> 0 | I4: =SUM(E4:H4) -> 0 | J4: ='Unit 2'!B4 -> 0 | K4: ='Unit 2'!C4 -> 0 | L4: ='Unit 2'!D4 -> 0 | M4: ='Unit 2'!E4 -> 0 | N4: =SUM(J4:M4) -> 0 | O4: ='Unit 3'!B4 -> 0 | P4: ='Unit 3'!C4 -> 0 | Q4: ='Unit 3'!D4 -> 0 | R4: ='Unit 3'!E4 -> 0 | S4: =SUM(O4:R4) -> 0 | T4: ='Unit 4'!B4 -> 0 | U4: ='Unit 4'!C4 -> 0 | V4: ='Unit 4'!D4 -> 0 | W4: ='Unit 4'!E4 -> 0 | X4: =SUM(T4:W4) -> 0 | Y4: =SUM(E4,J4,O4,T4,) -> 0 | Z4: =SUM(F4,K4,P4,U4,) -> 0 | AA4: =SUM(G4,L4,Q4,V4,) -> 0 | AB4: =SUM(H4,M4,R4,W4,) -> 0 | AC4: =SUM(Y4:AB4) -> 0 | AD4: ='Half yearly'!B4 -> 0 | AE4: ='Half yearly'!C4 -> 0 | AF4: ='Half yearly'!D4 -> 0 | AG4: ='Half yearly'!E4 -> 0 | AH4: =SUM(AD4:AG4) -> 0 | AI4: =Annual!B4 -> 0 | AJ4: =Annual!C4 -> 0 | AK4: =Annual!D4 -> 0 | AL4: =Annual!E4 -> 0 | AM4: =SUM(AI4:AL4) -> 0 | AN4: =IF(INT(SUM(E4, J4, O4, T4) * 0.2) <> A3, IF(SUM(E4, J4, O4, T4) * 0.2 - INT(SUM(E4, J4, O4, T4) * 0.2) >= 0.5, ROUNDUP(SUM(E4, J4, O4, T4) * 0.2, 0), ROUNDDOWN(SUM(E4, J4, O4, T4) * 0.2, 0)), SUM(E4, J4, O4, T4) * 0.2) -> 0 | AO4: =IF(INT(SUM(F4, K4, P4, U4) * 0.2) <> B3, IF(SUM(F4, K4, P4, U4) * 0.2 - INT(SUM(F4, K4, P4, U4) * 0.2) >= 0.5, ROUNDUP(SUM(F4, K4, P4, U4) * 0.2, 0), ROUNDDOWN(SUM(F4, K4, P4, U4) * 0.2, 0)), SUM(F4, K4, P4, U4) * 0.2) -> 0 | AP4: =IF(INT(SUM(G4, L4, Q4, V4) * 0.2) <> C3, IF(SUM(G4, L4, Q4, V4) * 0.2 - INT(SUM(G4, L4, Q4, V4) * 0.2) >= 0.5, ROUNDUP(SUM(G4, L4, Q4, V4) * 0.2, 0), ROUNDDOWN(SUM(G4, L4, Q4, V4) * 0.2, 0)), SUM(G4, L4, Q4, V4) * 0.2) -> 0 | AQ4: =IF(INT(SUM(H4, M4, R4, W4) * 0.2) <> E3, IF(SUM(H4, M4, R4, W4) * 0.2 - INT(SUM(H4, M4, R4, W4) * 0.2) >= 0.5, ROUNDUP(SUM(H4, M4, R4, W4) * 0.2, 0), ROUNDDOWN(SUM(H4, M4, R4, W4) * 0.2, 0)), SUM(H4, M4, R4, W4) * 0.2) -> 0 | AR4: =IF(INT(SUM(I4, N4, S4, X4) * 0.2) <> G3, IF(SUM(I4, N4, S4, X4) * 0.2 - INT(SUM(I4, N4, S4, X4) * 0.2) >= 0.5, ROUNDUP(SUM(I4, N4, S4, X4) * 0.2, 0), ROUNDDOWN(SUM(I4, N4, S4, X4) * 0.2, 0)), SUM(I4, N4, S4, X4) * 0.2) -> 0 | AS4: =IF(INT(SUM(AD4) * 0.3) <> A3, IF(SUM(AD4) * 0.3 - INT(SUM(AD4) * 0.3) >= 0.5, ROUNDUP(SUM(AD4) * 0.3, 0), ROUNDDOWN(SUM(AD4) * 0.3, 0)), SUM(AD4) * 0.3) -> 0 | AT4: =IF(INT(SUM(AE4) * 0.3) <> B3, IF(SUM(AE4) * 0.3 - INT(SUM(AE4) * 0.3) >= 0.5, ROUNDUP(SUM(AE4) * 0.3, 0), ROUNDDOWN(SUM(AE4) * 0.3, 0)), SUM(AE4) * 0.3) -> 0 | AU4: =IF(INT(SUM(AF4) * 0.3) <> C3, IF(SUM(AF4) * 0.3 - INT(SUM(AF4) * 0.3) >= 0.5, ROUNDUP(SUM(AF4) * 0.3, 0), ROUNDDOWN(SUM(AF4) * 0.3, 0)), SUM(AF4) * 0.3) -> 0 | AV4: =IF(INT(SUM(AG4) * 0.3) <> E3, IF(SUM(AG4) * 0.3 - INT(SUM(AG4) * 0.3) >= 0.5, ROUNDUP(SUM(AG4) * 0.3, 0), ROUNDDOWN(SUM(AG4) * 0.3, 0)), SUM(AG4) * 0.3) -> 0 | AW4: =IF(INT(SUM(AH4) * 0.3) <> G3, IF(SUM(AH4) * 0.3 - INT(SUM(AH4) * 0.3) >= 0.5, ROUNDUP(SUM(AH4) * 0.3, 0), ROUNDDOWN(SUM(AH4) * 0.3, 0)), SUM(AH4) * 0.3) -> 0 | AX4: =IF(INT(SUM(AI4) * 0.5) <> A3, IF(SUM(AI4) * 0.5 - INT(SUM(AI4) * 0.5) >= 0.5, ROUNDUP(SUM(AI4) * 0.5, 0), ROUNDDOWN(SUM(AI4) * 0.5, 0)), SUM(AI4) * 0.5) -> 0 | AY4: =IF(INT(SUM(AJ4) * 0.5) <> B3, IF(SUM(AJ4) * 0.5 - INT(SUM(AJ4) * 0.5) >= 0.5, ROUNDUP(SUM(AJ4) * 0.5, 0), ROUNDDOWN(SUM(AJ4) * 0.5, 0)), SUM(AJ4) * 0.5) -> 0 | AZ4: =IF(INT(SUM(AK4) * 0.5) <> C3, IF(SUM(AK4) * 0.5 - INT(SUM(AK4) * 0.5) >= 0.5, ROUNDUP(SUM(AK4) * 0.5, 0), ROUNDDOWN(SUM(AK4) * 0.5, 0)), SUM(AK4) * 0.5) -> 0 | BA4: =IF(INT(SUM(AL4) * 0.5) <> E3, IF(SUM(AL4) * 0.5 - INT(SUM(AL4) * 0.5) >= 0.5, ROUNDUP(SUM(AL4) * 0.5, 0), ROUNDDOWN(SUM(AL4) * 0.5, 0)), SUM(AL4) * 0.5) -> 0 | BB4: =IF(INT(SUM(AM4) * 0.5) <> G3, IF(SUM(AM4) * 0.5 - INT(SUM(AM4) * 0.5) >= 0.5, ROUNDUP(SUM(AM4) * 0.5, 0), ROUNDDOWN(SUM(AM4) * 0.5, 0)), SUM(AM4) * 0.5) -> 0 | BC4: =SUM(AN4,AS4,AX4) -> 0 | BD4: =SUM(AO4,AT4,AY4) -> 0 | BE4: =SUM(AP4,AU4,AZ4) -> 0 | BF4: =SUM(AQ4,AV4,BA4) -> 0 | BG4: =SUM(BC4:BF4) -> 0 | BH4: =SUM(BC4:BF4)/500*100 -> 0 | BI4: =IF(BH4>=80,"A+",IF(BH4>=70,"A",IF(BH4>=60,"B+",IF(BH4>=50,"B",IF(BH4>=40,"C",IF(BH4>=30,"E","FAIL")))))) -> FAIL
B5: ='Unit 1'!A5 -> 0 | C5: ='Unit 1'!B5 -> 0 | D5: ='Unit 1'!$G$2 -> i | E5: ='Unit 1'!C5 -> 0 | F5: ='Unit 1'!D5 -> 0 | G5: ='Unit 1'!E5 -> 0 | H5: ='Unit 1'!F5 -> 0 | I5: =SUM(E5:H5) -> 0 | J5: ='Unit 2'!B5 -> 0 | K5: ='Unit 2'!C5 -> 0 | L5: ='Unit 2'!D5 -> 0 | M5: ='Unit 2'!E5 -> 0 | N5: =SUM(J5:M5) -> 0 | O5: ='Unit 3'!B5 -> 0 | P5: ='Unit 3'!C5 -> 0 | Q5: ='Unit 3'!D5 -> 0 | R5: ='Unit 3'!E5 -> 0 | S5: =SUM(O5:R5) -> 0 | T5: ='Unit 4'!B5 -> 0 | U5: ='Unit 4'!C5 -> 0 | V5: ='Unit 4'!D5 -> 0 | W5: ='Unit 4'!E5 -> 0 | X5: =SUM(T5:W5) -> 0 | Y5: =SUM(E5,J5,O5,T5,) -> 0 | Z5: =SUM(F5,K5,P5,U5,) -> 0 | AA5: =SUM(G5,L5,Q5,V5,) -> 0 | AB5: =SUM(H5,M5,R5,W5,) -> 0 | AC5: =SUM(Y5:AB5) -> 0 | AD5: ='Half yearly'!B5 -> 0 | AE5: ='Half yearly'!C5 -> 0 | AF5: ='Half yearly'!D5 -> 0 | AG5: ='Half yearly'!E5 -> 0 | AH5: =SUM(AD5:AG5) -> 0 | AI5: =Annual!B5 -> 0 | AJ5: =Annual!C5 -> 0 | AK5: =Annual!D5 -> 0 | AL5: =Annual!E5 -> 0 | AM5: =SUM(AI5:AL5) -> 0 | AN5: =IF(INT(SUM(E5, J5, O5, T5) * 0.2) <> A4, IF(SUM(E5, J5, O5, T5) * 0.2 - INT(SUM(E5, J5, O5, T5) * 0.2) >= 0.5, ROUNDUP(SUM(E5, J5, O5, T5) * 0.2, 0), ROUNDDOWN(SUM(E5, J5, O5, T5) * 0.2, 0)), SUM(E5, J5, O5, T5) * 0.2) -> 0 | AO5: =IF(INT(SUM(F5, K5, P5, U5) * 0.2) <> B4, IF(SUM(F5, K5, P5, U5) * 0.2 - INT(SUM(F5, K5, P5, U5) * 0.2) >= 0.5, ROUNDUP(SUM(F5, K5, P5, U5) * 0.2, 0), ROUNDDOWN(SUM(F5, K5, P5, U5) * 0.2, 0)), SUM(F5, K5, P5, U5) * 0.2) -> 0 | AP5: =IF(INT(SUM(G5, L5, Q5, V5) * 0.2) <> C4, IF(SUM(G5, L5, Q5, V5) * 0.2 - INT(SUM(G5, L5, Q5, V5) * 0.2) >= 0.5, ROUNDUP(SUM(G5, L5, Q5, V5) * 0.2, 0), ROUNDDOWN(SUM(G5, L5, Q5, V5) * 0.2, 0)), SUM(G5, L5, Q5, V5) * 0.2) -> 0 | AQ5: =IF(INT(SUM(H5, M5, R5, W5) * 0.2) <> E4, IF(SUM(H5, M5, R5, W5) * 0.2 - INT(SUM(H5, M5, R5, W5) * 0.2) >= 0.5, ROUNDUP(SUM(H5, M5, R5, W5) * 0.2, 0), ROUNDDOWN(SUM(H5, M5, R5, W5) * 0.2, 0)), SUM(H5, M5, R5, W5) * 0.2) -> 0 | AR5: =IF(INT(SUM(I5, N5, S5, X5) * 0.2) <> G4, IF(SUM(I5, N5, S5, X5) * 0.2 - INT(SUM(I5, N5, S5, X5) * 0.2) >= 0.5, ROUNDUP(SUM(I5, N5, S5, X5) * 0.2, 0), ROUNDDOWN(SUM(I5, N5, S5, X5) * 0.2, 0)), SUM(I5, N5, S5, X5) * 0.2) -> 0 | AS5: =IF(INT(SUM(AD5) * 0.3) <> A4, IF(SUM(AD5) * 0.3 - INT(SUM(AD5) * 0.3) >= 0.5, ROUNDUP(SUM(AD5) * 0.3, 0), ROUNDDOWN(SUM(AD5) * 0.3, 0)), SUM(AD5) * 0.3) -> 0 | AT5: =IF(INT(SUM(AE5) * 0.3) <> B4, IF(SUM(AE5) * 0.3 - INT(SUM(AE5) * 0.3) >= 0.5, ROUNDUP(SUM(AE5) * 0.3, 0), ROUNDDOWN(SUM(AE5) * 0.3, 0)), SUM(AE5) * 0.3) -> 0 | AU5: =IF(INT(SUM(AF5) * 0.3) <> C4, IF(SUM(AF5) * 0.3 - INT(SUM(AF5) * 0.3) >= 0.5, ROUNDUP(SUM(AF5) * 0.3, 0), ROUNDDOWN(SUM(AF5) * 0.3, 0)), SUM(AF5) * 0.3) -> 0 | AV5: =IF(INT(SUM(AG5) * 0.3) <> E4, IF(SUM(AG5) * 0.3 - INT(SUM(AG5) * 0.3) >= 0.5, ROUNDUP(SUM(AG5) * 0.3, 0), ROUNDDOWN(SUM(AG5) * 0.3, 0)), SUM(AG5) * 0.3) -> 0 | AW5: =IF(INT(SUM(AH5) * 0.3) <> G4, IF(SUM(AH5) * 0.3 - INT(SUM(AH5) * 0.3) >= 0.5, ROUNDUP(SUM(AH5) * 0.3, 0), ROUNDDOWN(SUM(AH5) * 0.3, 0)), SUM(AH5) * 0.3) -> 0 | AX5: =IF(INT(SUM(AI5) * 0.5) <> A4, IF(SUM(AI5) * 0.5 - INT(SUM(AI5) * 0.5) >= 0.5, ROUNDUP(SUM(AI5) * 0.5, 0), ROUNDDOWN(SUM(AI5) * 0.5, 0)), SUM(AI5) * 0.5) -> 0 | AY5: =IF(INT(SUM(AJ5) * 0.5) <> B4, IF(SUM(AJ5) * 0.5 - INT(SUM(AJ5) * 0.5) >= 0.5, ROUNDUP(SUM(AJ5) * 0.5, 0), ROUNDDOWN(SUM(AJ5) * 0.5, 0)), SUM(AJ5) * 0.5) -> 0 | AZ5: =IF(INT(SUM(AK5) * 0.5) <> C4, IF(SUM(AK5) * 0.5 - INT(SUM(AK5) * 0.5) >= 0.5, ROUNDUP(SUM(AK5) * 0.5, 0), ROUNDDOWN(SUM(AK5) * 0.5, 0)), SUM(AK5) * 0.5) -> 0 | BA5: =IF(INT(SUM(AL5) * 0.5) <> E4, IF(SUM(AL5) * 0.5 - INT(SUM(AL5) * 0.5) >= 0.5, ROUNDUP(SUM(AL5) * 0.5, 0), ROUNDDOWN(SUM(AL5) * 0.5, 0)), SUM(AL5) * 0.5) -> 0 | BB5: =IF(INT(SUM(AM5) * 0.5) <> G4, IF(SUM(AM5) * 0.5 - INT(SUM(AM5) * 0.5) >= 0.5, ROUNDUP(SUM(AM5) * 0.5, 0), ROUNDDOWN(SUM(AM5) * 0.5, 0)), SUM(AM5) * 0.5) -> 0 | BC5: =SUM(AN5,AS5,AX5) -> 0 | BD5: =SUM(AO5,AT5,AY5) -> 0 | BE5: =SUM(AP5,AU5,AZ5) -> 0 | BF5: =SUM(AQ5,AV5,BA5) -> 0 | BG5: =SUM(BC5:BF5) -> 0 | BH5: =SUM(BC5:BF5)/500*100 -> 0 | BI5: =IF(BH5>=80,"A+",IF(BH5>=70,"A",IF(BH5>=60,"B+",IF(BH5>=50,"B",IF(BH5>=40,"C",IF(BH5>=30,"E","FAIL")))))) -> FAIL
B6: ='Unit 1'!A6 -> 0 | C6: ='Unit 1'!B6 -> 0 | D6: ='Unit 1'!$G$2 -> i | E6: ='Unit 1'!C6 -> 0 | F6: ='Unit 1'!D6 -> 0 | G6: ='Unit 1'!E6 -> 0 | H6: ='Unit 1'!F6 -> 0 | I6: =SUM(E6:H6) -> 0 | J6: ='Unit 2'!B6 -> 0 | K6: ='Unit 2'!C6 -> 0 | L6: ='Unit 2'!D6 -> 0 | M6: ='Unit 2'!E6 -> 0 | N6: =SUM(J6:M6) -> 0 | O6: ='Unit 3'!B6 -> 0 | P6: ='Unit 3'!C6 -> 0 | Q6: ='Unit 3'!D6 -> 0 | R6: ='Unit 3'!E6 -> 0 | S6: =SUM(O6:R6) -> 0 | T6: ='Unit 4'!B6 -> 0 | U6: ='Unit 4'!C6 -> 0 | V6: ='Unit 4'!D6 -> 0 | W6: ='Unit 4'!E6 -> 0 | X6: =SUM(T6:W6) -> 0 | Y6: =SUM(E6,J6,O6,T6,) -> 0 | Z6: =SUM(F6,K6,P6,U6,) -> 0 | AA6: =SUM(G6,L6,Q6,V6,) -> 0 | AB6: =SUM(H6,M6,R6,W6,) -> 0 | AC6: =SUM(Y6:AB6) -> 0 | AD6: ='Half yearly'!B6 -> 0 | AE6: ='Half yearly'!C6 -> 0 | AF6: ='Half yearly'!D6 -> 0 | AG6: ='Half yearly'!E6 -> 0 | AH6: =SUM(AD6:AG6) -> 0 | AI6: =Annual!B6 -> 0 | AJ6: =Annual!C6 -> 0 | AK6: =Annual!D6 -> 0 | AL6: =Annual!E6 -> 0 | AM6: =SUM(AI6:AL6) -> 0 | AN6: =IF(INT(SUM(E6, J6, O6, T6) * 0.2) <> A5, IF(SUM(E6, J6, O6, T6) * 0.2 - INT(SUM(E6, J6, O6, T6) * 0.2) >= 0.5, ROUNDUP(SUM(E6, J6, O6, T6) * 0.2, 0), ROUNDDOWN(SUM(E6, J6, O6, T6) * 0.2, 0)), SUM(E6, J6, O6, T6) * 0.2) -> 0 | AO6: =IF(INT(SUM(F6, K6, P6, U6) * 0.2) <> B5, IF(SUM(F6, K6, P6, U6) * 0.2 - INT(SUM(F6, K6, P6, U6) * 0.2) >= 0.5, ROUNDUP(SUM(F6, K6, P6, U6) * 0.2, 0), ROUNDDOWN(SUM(F6, K6, P6, U6) * 0.2, 0)), SUM(F6, K6, P6, U6) * 0.2) -> 0 | AP6: =IF(INT(SUM(G6, L6, Q6, V6) * 0.2) <> C5, IF(SUM(G6, L6, Q6, V6) * 0.2 - INT(SUM(G6, L6, Q6, V6) * 0.2) >= 0.5, ROUNDUP(SUM(G6, L6, Q6, V6) * 0.2, 0), ROUNDDOWN(SUM(G6, L6, Q6, V6) * 0.2, 0)), SUM(G6, L6, Q6, V6) * 0.2) -> 0 | AQ6: =IF(INT(SUM(H6, M6, R6, W6) * 0.2) <> E5, IF(SUM(H6, M6, R6, W6) * 0.2 - INT(SUM(H6, M6, R6, W6) * 0.2) >= 0.5, ROUNDUP(SUM(H6, M6, R6, W6) * 0.2, 0), ROUNDDOWN(SUM(H6, M6, R6, W6) * 0.2, 0)), SUM(H6, M6, R6, W6) * 0.2) -> 0 | AR6: =IF(INT(SUM(I6, N6, S6, X6) * 0.2) <> G5, IF(SUM(I6, N6, S6, X6) * 0.2 - INT(SUM(I6, N6, S6, X6) * 0.2) >= 0.5, ROUNDUP(SUM(I6, N6, S6, X6) * 0.2, 0), ROUNDDOWN(SUM(I6, N6, S6, X6) * 0.2, 0)), SUM(I6, N6, S6, X6) * 0.2) -> 0 | AS6: =IF(INT(SUM(AD6) * 0.3) <> A5, IF(SUM(AD6) * 0.3 - INT(SUM(AD6) * 0.3) >= 0.5, ROUNDUP(SUM(AD6) * 0.3, 0), ROUNDDOWN(SUM(AD6) * 0.3, 0)), SUM(AD6) * 0.3) -> 0 | AT6: =IF(INT(SUM(AE6) * 0.3) <> B5, IF(SUM(AE6) * 0.3 - INT(SUM(AE6) * 0.3) >= 0.5, ROUNDUP(SUM(AE6) * 0.3, 0), ROUNDDOWN(SUM(AE6) * 0.3, 0)), SUM(AE6) * 0.3) -> 0 | AU6: =IF(INT(SUM(AF6) * 0.3) <> C5, IF(SUM(AF6) * 0.3 - INT(SUM(AF6) * 0.3) >= 0.5, ROUNDUP(SUM(AF6) * 0.3, 0), ROUNDDOWN(SUM(AF6) * 0.3, 0)), SUM(AF6) * 0.3) -> 0 | AV6: =IF(INT(SUM(AG6) * 0.3) <> E5, IF(SUM(AG6) * 0.3 - INT(SUM(AG6) * 0.3) >= 0.5, ROUNDUP(SUM(AG6) * 0.3, 0), ROUNDDOWN(SUM(AG6) * 0.3, 0)), SUM(AG6) * 0.3) -> 0 | AW6: =IF(INT(SUM(AH6) * 0.3) <> G5, IF(SUM(AH6) * 0.3 - INT(SUM(AH6) * 0.3) >= 0.5, ROUNDUP(SUM(AH6) * 0.3, 0), ROUNDDOWN(SUM(AH6) * 0.3, 0)), SUM(AH6) * 0.3) -> 0 | AX6: =IF(INT(SUM(AI6) * 0.5) <> A5, IF(SUM(AI6) * 0.5 - INT(SUM(AI6) * 0.5) >= 0.5, ROUNDUP(SUM(AI6) * 0.5, 0), ROUNDDOWN(SUM(AI6) * 0.5, 0)), SUM(AI6) * 0.5) -> 0 | AY6: =IF(INT(SUM(AJ6) * 0.5) <> B5, IF(SUM(AJ6) * 0.5 - INT(SUM(AJ6) * 0.5) >= 0.5, ROUNDUP(SUM(AJ6) * 0.5, 0), ROUNDDOWN(SUM(AJ6) * 0.5, 0)), SUM(AJ6) * 0.5) -> 0 | AZ6: =IF(INT(SUM(AK6) * 0.5) <> C5, IF(SUM(AK6) * 0.5 - INT(SUM(AK6) * 0.5) >= 0.5, ROUNDUP(SUM(AK6) * 0.5, 0), ROUNDDOWN(SUM(AK6) * 0.5, 0)), SUM(AK6) * 0.5) -> 0 | BA6: =IF(INT(SUM(AL6) * 0.5) <> E5, IF(SUM(AL6) * 0.5 - INT(SUM(AL6) * 0.5) >= 0.5, ROUNDUP(SUM(AL6) * 0.5, 0), ROUNDDOWN(SUM(AL6) * 0.5, 0)), SUM(AL6) * 0.5) -> 0 | BB6: =IF(INT(SUM(AM6) * 0.5) <> G5, IF(SUM(AM6) * 0.5 - INT(SUM(AM6) * 0.5) >= 0.5, ROUNDUP(SUM(AM6) * 0.5, 0), ROUNDDOWN(SUM(AM6) * 0.5, 0)), SUM(AM6) * 0.5) -> 0 | BC6: =SUM(AN6,AS6,AX6) -> 0 | BD6: =SUM(AO6,AT6,AY6) -> 0 | BE6: =SUM(AP6,AU6,AZ6) -> 0 | BF6: =SUM(AQ6,AV6,BA6) -> 0 | BG6: =SUM(BC6:BF6) -> 0 | BH6: =SUM(BC6:BF6)/500*100 -> 0 | BI6: =IF(BH6>=80,"A+",IF(BH6>=70,"A",IF(BH6>=60,"B+",IF(BH6>=50,"B",IF(BH6>=40,"C",IF(BH6>=30,"E","FAIL")))))) -> FAIL
B7: ='Unit 1'!A7 -> 0 | C7: ='Unit 1'!B7 -> 0 | D7: ='Unit 1'!$G$2 -> i | E7: ='Unit 1'!C7 -> 0 | F7: ='Unit 1'!D7 -> 0 | G7: ='Unit 1'!E7 -> 0 | H7: ='Unit 1'!F7 -> 0 | I7: =SUM(E7:H7) -> 0 | J7: ='Unit 2'!B7 -> 0 | K7: ='Unit 2'!C7 -> 0 | L7: ='Unit 2'!D7 -> 0 | M7: ='Unit 2'!E7 -> 0 | N7: =SUM(J7:M7) -> 0 | O7: ='Unit 3'!B7 -> 0 | P7: ='Unit 3'!C7 -> 0 | Q7: ='Unit 3'!D7 -> 0 | R7: ='Unit 3'!E7 -> 0 | S7: =SUM(O7:R7) -> 0 | T7: ='Unit 4'!B7 -> 0 | U7: ='Unit 4'!C7 -> 0 | V7: ='Unit 4'!D7 -> 0 | W7: ='Unit 4'!E7 -> 0 | X7: =SUM(T7:W7) -> 0 | Y7: =SUM(E7,J7,O7,T7,) -> 0 | Z7: =SUM(F7,K7,P7,U7,) -> 0 | AA7: =SUM(G7,L7,Q7,V7,) -> 0 | AB7: =SUM(H7,M7,R7,W7,) -> 0 | AC7: =SUM(Y7:AB7) -> 0 | AD7: ='Half yearly'!B7 -> 0 | AE7: ='Half yearly'!C7 -> 0 | AF7: ='Half yearly'!D7 -> 0 | AG7: ='Half yearly'!E7 -> 0 | AH7: =SUM(AD7:AG7) -> 0 | AI7: =Annual!B7 -> 0 | AJ7: =Annual!C7 -> 0 | AK7: =Annual!D7 -> 0 | AL7: =Annual!E7 -> 0 | AM7: =SUM(AI7:AL7) -> 0 | AN7: =IF(INT(SUM(E7, J7, O7, T7) * 0.2) <> A6, IF(SUM(E7, J7, O7, T7) * 0.2 - INT(SUM(E7, J7, O7, T7) * 0.2) >= 0.5, ROUNDUP(SUM(E7, J7, O7, T7) * 0.2, 0), ROUNDDOWN(SUM(E7, J7, O7, T7) * 0.2, 0)), SUM(E7, J7, O7, T7) * 0.2) -> 0 | AO7: =IF(INT(SUM(F7, K7, P7, U7) * 0.2) <> B6, IF(SUM(F7, K7, P7, U7) * 0.2 - INT(SUM(F7, K7, P7, U7) * 0.2) >= 0.5, ROUNDUP(SUM(F7, K7, P7, U7) * 0.2, 0), ROUNDDOWN(SUM(F7, K7, P7, U7) * 0.2, 0)), SUM(F7, K7, P7, U7) * 0.2) -> 0 | AP7: =IF(INT(SUM(G7, L7, Q7, V7) * 0.2) <> C6, IF(SUM(G7, L7, Q7, V7) * 0.2 - INT(SUM(G7, L7, Q7, V7) * 0.2) >= 0.5, ROUNDUP(SUM(G7, L7, Q7, V7) * 0.2, 0), ROUNDDOWN(SUM(G7, L7, Q7, V7) * 0.2, 0)), SUM(G7, L7, Q7, V7) * 0.2) -> 0 | AQ7: =IF(INT(SUM(H7, M7, R7, W7) * 0.2) <> E6, IF(SUM(H7, M7, R7, W7) * 0.2 - INT(SUM(H7, M7, R7, W7) * 0.2) >= 0.5, ROUNDUP(SUM(H7, M7, R7, W7) * 0.2, 0), ROUNDDOWN(SUM(H7, M7, R7, W7) * 0.2, 0)), SUM(H7, M7, R7, W7) * 0.2) -> 0 | AR7: =IF(INT(SUM(I7, N7, S7, X7) * 0.2) <> G6, IF(SUM(I7, N7, S7, X7) * 0.2 - INT(SUM(I7, N7, S7, X7) * 0.2) >= 0.5, ROUNDUP(SUM(I7, N7, S7, X7) * 0.2, 0), ROUNDDOWN(SUM(I7, N7, S7, X7) * 0.2, 0)), SUM(I7, N7, S7, X7) * 0.2) -> 0 | AS7: =IF(INT(SUM(AD7) * 0.3) <> A6, IF(SUM(AD7) * 0.3 - INT(SUM(AD7) * 0.3) >= 0.5, ROUNDUP(SUM(AD7) * 0.3, 0), ROUNDDOWN(SUM(AD7) * 0.3, 0)), SUM(AD7) * 0.3) -> 0 | AT7: =IF(INT(SUM(AE7) * 0.3) <> B6, IF(SUM(AE7) * 0.3 - INT(SUM(AE7) * 0.3) >= 0.5, ROUNDUP(SUM(AE7) * 0.3, 0), ROUNDDOWN(SUM(AE7) * 0.3, 0)), SUM(AE7) * 0.3) -> 0 | AU7: =IF(INT(SUM(AF7) * 0.3) <> C6, IF(SUM(AF7) * 0.3 - INT(SUM(AF7) * 0.3) >= 0.5, ROUNDUP(SUM(AF7) * 0.3, 0), ROUNDDOWN(SUM(AF7) * 0.3, 0)), SUM(AF7) * 0.3) -> 0 | AV7: =IF(INT(SUM(AG7) * 0.3) <> E6, IF(SUM(AG7) * 0.3 - INT(SUM(AG7) * 0.3) >= 0.5, ROUNDUP(SUM(AG7) * 0.3, 0), ROUNDDOWN(SUM(AG7) * 0.3, 0)), SUM(AG7) * 0.3) -> 0 | AW7: =IF(INT(SUM(AH7) * 0.3) <> G6, IF(SUM(AH7) * 0.3 - INT(SUM(AH7) * 0.3) >= 0.5, ROUNDUP(SUM(AH7) * 0.3, 0), ROUNDDOWN(SUM(AH7) * 0.3, 0)), SUM(AH7) * 0.3) -> 0 | AX7: =IF(INT(SUM(AI7) * 0.5) <> A6, IF(SUM(AI7) * 0.5 - INT(SUM(AI7) * 0.5) >= 0.5, ROUNDUP(SUM(AI7) * 0.5, 0), ROUNDDOWN(SUM(AI7) * 0.5, 0)), SUM(AI7) * 0.5) -> 0 | AY7: =IF(INT(SUM(AJ7) * 0.5) <> B6, IF(SUM(AJ7) * 0.5 - INT(SUM(AJ7) * 0.5) >= 0.5, ROUNDUP(SUM(AJ7) * 0.5, 0), ROUNDDOWN(SUM(AJ7) * 0.5, 0)), SUM(AJ7) * 0.5) -> 0 | AZ7: =IF(INT(SUM(AK7) * 0.5) <> C6, IF(SUM(AK7) * 0.5 - INT(SUM(AK7) * 0.5) >= 0.5, ROUNDUP(SUM(AK7) * 0.5, 0), ROUNDDOWN(SUM(AK7) * 0.5, 0)), SUM(AK7) * 0.5) -> 0 | BA7: =IF(INT(SUM(AL7) * 0.5) <> E6, IF(SUM(AL7) * 0.5 - INT(SUM(AL7) * 0.5) >= 0.5, ROUNDUP(SUM(AL7) * 0.5, 0), ROUNDDOWN(SUM(AL7) * 0.5, 0)), SUM(AL7) * 0.5) -> 0 | BB7: =IF(INT(SUM(AM7) * 0.5) <> G6, IF(SUM(AM7) * 0.5 - INT(SUM(AM7) * 0.5) >= 0.5, ROUNDUP(SUM(AM7) * 0.5, 0), ROUNDDOWN(SUM(AM7) * 0.5, 0)), SUM(AM7) * 0.5) -> 0 | BC7: =SUM(AN7,AS7,AX7) -> 0 | BD7: =SUM(AO7,AT7,AY7) -> 0 | BE7: =SUM(AP7,AU7,AZ7) -> 0 | BF7: =SUM(AQ7,AV7,BA7) -> 0 | BG7: =SUM(BC7:BF7) -> 0 | BH7: =SUM(BC7:BF7)/500*100 -> 0 | BI7: =IF(BH7>=80,"A+",IF(BH7>=70,"A",IF(BH7>=60,"B+",IF(BH7>=50,"B",IF(BH7>=40,"C",IF(BH7>=30,"E","FAIL")))))) -> FAIL
B8: ='Unit 1'!A8 -> 0 | C8: ='Unit 1'!B8 -> 0 | D8: ='Unit 1'!$G$2 -> i | E8: ='Unit 1'!C8 -> 0 | F8: ='Unit 1'!D8 -> 0 | G8: ='Unit 1'!E8 -> 0 | H8: ='Unit 1'!F8 -> 0 | I8: =SUM(E8:H8) -> 0 | J8: ='Unit 2'!B8 -> 0 | K8: ='Unit 2'!C8 -> 0 | L8: ='Unit 2'!D8 -> 0 | M8: ='Unit 2'!E8 -> 0 | N8: =SUM(J8:M8) -> 0 | O8: ='Unit 3'!B8 -> 0 | P8: ='Unit 3'!C8 -> 0 | Q8: ='Unit 3'!D8 -> 0 | R8: ='Unit 3'!E8 -> 0 | S8: =SUM(O8:R8) -> 0 | T8: ='Unit 4'!B8 -> 0 | U8: ='Unit 4'!C8 -> 0 | V8: ='Unit 4'!D8 -> 0 | W8: ='Unit 4'!E8 -> 0 | X8: =SUM(T8:W8) -> 0 | Y8: =SUM(E8,J8,O8,T8,) -> 0 | Z8: =SUM(F8,K8,P8,U8,) -> 0 | AA8: =SUM(G8,L8,Q8,V8,) -> 0 | AB8: =SUM(H8,M8,R8,W8,) -> 0 | AC8: =SUM(Y8:AB8) -> 0 | AD8: ='Half yearly'!B8 -> 0 | AE8: ='Half yearly'!C8 -> 0 | AF8: ='Half yearly'!D8 -> 0 | AG8: ='Half yearly'!E8 -> 0 | AH8: =SUM(AD8:AG8) -> 0 | AI8: =Annual!B8 -> 0 | AJ8: =Annual!C8 -> 0 | AK8: =Annual!D8 -> 0 | AL8: =Annual!E8 -> 0 | AM8: =SUM(AI8:AL8) -> 0 | AN8: =IF(INT(SUM(E8, J8, O8, T8) * 0.2) <> A7, IF(SUM(E8, J8, O8, T8) * 0.2 - INT(SUM(E8, J8, O8, T8) * 0.2) >= 0.5, ROUNDUP(SUM(E8, J8, O8, T8) * 0.2, 0), ROUNDDOWN(SUM(E8, J8, O8, T8) * 0.2, 0)), SUM(E8, J8, O8, T8) * 0.2) -> 0 | AO8: =IF(INT(SUM(F8, K8, P8, U8) * 0.2) <> B7, IF(SUM(F8, K8, P8, U8) * 0.2 - INT(SUM(F8, K8, P8, U8) * 0.2) >= 0.5, ROUNDUP(SUM(F8, K8, P8, U8) * 0.2, 0), ROUNDDOWN(SUM(F8, K8, P8, U8) * 0.2, 0)), SUM(F8, K8, P8, U8) * 0.2) -> 0 | AP8: =IF(INT(SUM(G8, L8, Q8, V8) * 0.2) <> C7, IF(SUM(G8, L8, Q8, V8) * 0.2 - INT(SUM(G8, L8, Q8, V8) * 0.2) >= 0.5, ROUNDUP(SUM(G8, L8, Q8, V8) * 0.2, 0), ROUNDDOWN(SUM(G8, L8, Q8, V8) * 0.2, 0)), SUM(G8, L8, Q8, V8) * 0.2) -> 0 | AQ8: =IF(INT(SUM(H8, M8, R8, W8) * 0.2) <> E7, IF(SUM(H8, M8, R8, W8) * 0.2 - INT(SUM(H8, M8, R8, W8) * 0.2) >= 0.5, ROUNDUP(SUM(H8, M8, R8, W8) * 0.2, 0), ROUNDDOWN(SUM(H8, M8, R8, W8) * 0.2, 0)), SUM(H8, M8, R8, W8) * 0.2) -> 0 | AR8: =IF(INT(SUM(I8, N8, S8, X8) * 0.2) <> G7, IF(SUM(I8, N8, S8, X8) * 0.2 - INT(SUM(I8, N8, S8, X8) * 0.2) >= 0.5, ROUNDUP(SUM(I8, N8, S8, X8) * 0.2, 0), ROUNDDOWN(SUM(I8, N8, S8, X8) * 0.2, 0)), SUM(I8, N8, S8, X8) * 0.2) -> 0 | AS8: =IF(INT(SUM(AD8) * 0.3) <> A7, IF(SUM(AD8) * 0.3 - INT(SUM(AD8) * 0.3) >= 0.5, ROUNDUP(SUM(AD8) * 0.3, 0), ROUNDDOWN(SUM(AD8) * 0.3, 0)), SUM(AD8) * 0.3) -> 0 | AT8: =IF(INT(SUM(AE8) * 0.3) <> B7, IF(SUM(AE8) * 0.3 - INT(SUM(AE8) * 0.3) >= 0.5, ROUNDUP(SUM(AE8) * 0.3, 0), ROUNDDOWN(SUM(AE8) * 0.3, 0)), SUM(AE8) * 0.3) -> 0 | AU8: =IF(INT(SUM(AF8) * 0.3) <> C7, IF(SUM(AF8) * 0.3 - INT(SUM(AF8) * 0.3) >= 0.5, ROUNDUP(SUM(AF8) * 0.3, 0), ROUNDDOWN(SUM(AF8) * 0.3, 0)), SUM(AF8) * 0.3) -> 0 | AV8: =IF(INT(SUM(AG8) * 0.3) <> E7, IF(SUM(AG8) * 0.3 - INT(SUM(AG8) * 0.3) >= 0.5, ROUNDUP(SUM(AG8) * 0.3, 0), ROUNDDOWN(SUM(AG8) * 0.3, 0)), SUM(AG8) * 0.3) -> 0 | AW8: =IF(INT(SUM(AH8) * 0.3) <> G7, IF(SUM(AH8) * 0.3 - INT(SUM(AH8) * 0.3) >= 0.5, ROUNDUP(SUM(AH8) * 0.3, 0), ROUNDDOWN(SUM(AH8) * 0.3, 0)), SUM(AH8) * 0.3) -> 0 | AX8: =IF(INT(SUM(AI8) * 0.5) <> A7, IF(SUM(AI8) * 0.5 - INT(SUM(AI8) * 0.5) >= 0.5, ROUNDUP(SUM(AI8) * 0.5, 0), ROUNDDOWN(SUM(AI8) * 0.5, 0)), SUM(AI8) * 0.5) -> 0 | AY8: =IF(INT(SUM(AJ8) * 0.5) <> B7, IF(SUM(AJ8) * 0.5 - INT(SUM(AJ8) * 0.5) >= 0.5, ROUNDUP(SUM(AJ8) * 0.5, 0), ROUNDDOWN(SUM(AJ8) * 0.5, 0)), SUM(AJ8) * 0.5) -> 0 | AZ8: =IF(INT(SUM(AK8) * 0.5) <> C7, IF(SUM(AK8) * 0.5 - INT(SUM(AK8) * 0.5) >= 0.5, ROUNDUP(SUM(AK8) * 0.5, 0), ROUNDDOWN(SUM(AK8) * 0.5, 0)), SUM(AK8) * 0.5) -> 0 | BA8: =IF(INT(SUM(AL8) * 0.5) <> E7, IF(SUM(AL8) * 0.5 - INT(SUM(AL8) * 0.5) >= 0.5, ROUNDUP(SUM(AL8) * 0.5, 0), ROUNDDOWN(SUM(AL8) * 0.5, 0)), SUM(AL8) * 0.5) -> 0 | BB8: =IF(INT(SUM(AM8) * 0.5) <> G7, IF(SUM(AM8) * 0.5 - INT(SUM(AM8) * 0.5) >= 0.5, ROUNDUP(SUM(AM8) * 0.5, 0), ROUNDDOWN(SUM(AM8) * 0.5, 0)), SUM(AM8) * 0.5) -> 0 | BC8: =SUM(AN8,AS8,AX8) -> 0 | BD8: =SUM(AO8,AT8,AY8) -> 0 | BE8: =SUM(AP8,AU8,AZ8) -> 0 | BF8: =SUM(AQ8,AV8,BA8) -> 0 | BG8: =SUM(BC8:BF8) -> 0 | BH8: =SUM(BC8:BF8)/500*100 -> 0 | BI8: =IF(BH8>=80,"A+",IF(BH8>=70,"A",IF(BH8>=60,"B+",IF(BH8>=50,"B",IF(BH8>=40,"C",IF(BH8>=30,"E","FAIL")))))) -> FAIL
B9: ='Unit 1'!A9 -> 0 | C9: ='Unit 1'!B9 -> 0 | D9: ='Unit 1'!$G$2 -> i | E9: ='Unit 1'!C9 -> 0 | F9: ='Unit 1'!D9 -> 0 | G9: ='Unit 1'!E9 -> 0 | H9: ='Unit 1'!F9 -> 0 | I9: =SUM(E9:H9) -> 0 | J9: ='Unit 2'!B9 -> 0 | K9: ='Unit 2'!C9 -> 0 | L9: ='Unit 2'!D9 -> 0 | M9: ='Unit 2'!E9 -> 0 | N9: =SUM(J9:M9) -> 0 | O9: ='Unit 3'!B9 -> 0 | P9: ='Unit 3'!C9 -> 0 | Q9: ='Unit 3'!D9 -> 0 | R9: ='Unit 3'!E9 -> 0 | S9: =SUM(O9:R9) -> 0 | T9: ='Unit 4'!B9 -> 0 | U9: ='Unit 4'!C9 -> 0 | V9: ='Unit 4'!D9 -> 0 | W9: ='Unit 4'!E9 -> 0 | X9: =SUM(T9:W9) -> 0 | Y9: =SUM(E9,J9,O9,T9,) -> 0 | Z9: =SUM(F9,K9,P9,U9,) -> 0 | AA9: =SUM(G9,L9,Q9,V9,) -> 0 | AB9: =SUM(H9,M9,R9,W9,) -> 0 | AC9: =SUM(Y9:AB9) -> 0 | AD9: ='Half yearly'!B9 -> 0 | AE9: ='Half yearly'!C9 -> 0 | AF9: ='Half yearly'!D9 -> 0 | AG9: ='Half yearly'!E9 -> 0 | AH9: =SUM(AD9:AG9) -> 0 | AI9: =Annual!B9 -> 0 | AJ9: =Annual!C9 -> 0 | AK9: =Annual!D9 -> 0 | AL9: =Annual!E9 -> 0 | AM9: =SUM(AI9:AL9) -> 0 | AN9: =IF(INT(SUM(E9, J9, O9, T9) * 0.2) <> A8, IF(SUM(E9, J9, O9, T9) * 0.2 - INT(SUM(E9, J9, O9, T9) * 0.2) >= 0.5, ROUNDUP(SUM(E9, J9, O9, T9) * 0.2, 0), ROUNDDOWN(SUM(E9, J9, O9, T9) * 0.2, 0)), SUM(E9, J9, O9, T9) * 0.2) -> 0 | AO9: =IF(INT(SUM(F9, K9, P9, U9) * 0.2) <> B8, IF(SUM(F9, K9, P9, U9) * 0.2 - INT(SUM(F9, K9, P9, U9) * 0.2) >= 0.5, ROUNDUP(SUM(F9, K9, P9, U9) * 0.2, 0), ROUNDDOWN(SUM(F9, K9, P9, U9) * 0.2, 0)), SUM(F9, K9, P9, U9) * 0.2) -> 0 | AP9: =IF(INT(SUM(G9, L9, Q9, V9) * 0.2) <> C8, IF(SUM(G9, L9, Q9, V9) * 0.2 - INT(SUM(G9, L9, Q9, V9) * 0.2) >= 0.5, ROUNDUP(SUM(G9, L9, Q9, V9) * 0.2, 0), ROUNDDOWN(SUM(G9, L9, Q9, V9) * 0.2, 0)), SUM(G9, L9, Q9, V9) * 0.2) -> 0 | AQ9: =IF(INT(SUM(H9, M9, R9, W9) * 0.2) <> E8, IF(SUM(H9, M9, R9, W9) * 0.2 - INT(SUM(H9, M9, R9, W9) * 0.2) >= 0.5, ROUNDUP(SUM(H9, M9, R9, W9) * 0.2, 0), ROUNDDOWN(SUM(H9, M9, R9, W9) * 0.2, 0)), SUM(H9, M9, R9, W9) * 0.2) -> 0 | AR9: =IF(INT(SUM(I9, N9, S9, X9) * 0.2) <> G8, IF(SUM(I9, N9, S9, X9) * 0.2 - INT(SUM(I9, N9, S9, X9) * 0.2) >= 0.5, ROUNDUP(SUM(I9, N9, S9, X9) * 0.2, 0), ROUNDDOWN(SUM(I9, N9, S9, X9) * 0.2, 0)), SUM(I9, N9, S9, X9) * 0.2) -> 0 | AS9: =IF(INT(SUM(AD9) * 0.3) <> A8, IF(SUM(AD9) * 0.3 - INT(SUM(AD9) * 0.3) >= 0.5, ROUNDUP(SUM(AD9) * 0.3, 0), ROUNDDOWN(SUM(AD9) * 0.3, 0)), SUM(AD9) * 0.3) -> 0 | AT9: =IF(INT(SUM(AE9) * 0.3) <> B8, IF(SUM(AE9) * 0.3 - INT(SUM(AE9) * 0.3) >= 0.5, ROUNDUP(SUM(AE9) * 0.3, 0), ROUNDDOWN(SUM(AE9) * 0.3, 0)), SUM(AE9) * 0.3) -> 0 | AU9: =IF(INT(SUM(AF9) * 0.3) <> C8, IF(SUM(AF9) * 0.3 - INT(SUM(AF9) * 0.3) >= 0.5, ROUNDUP(SUM(AF9) * 0.3, 0), ROUNDDOWN(SUM(AF9) * 0.3, 0)), SUM(AF9) * 0.3) -> 0 | AV9: =IF(INT(SUM(AG9) * 0.3) <> E8, IF(SUM(AG9) * 0.3 - INT(SUM(AG9) * 0.3) >= 0.5, ROUNDUP(SUM(AG9) * 0.3, 0), ROUNDDOWN(SUM(AG9) * 0.3, 0)), SUM(AG9) * 0.3) -> 0 | AW9: =IF(INT(SUM(AH9) * 0.3) <> G8, IF(SUM(AH9) * 0.3 - INT(SUM(AH9) * 0.3) >= 0.5, ROUNDUP(SUM(AH9) * 0.3, 0), ROUNDDOWN(SUM(AH9) * 0.3, 0)), SUM(AH9) * 0.3) -> 0 | AX9: =IF(INT(SUM(AI9) * 0.5) <> A8, IF(SUM(AI9) * 0.5 - INT(SUM(AI9) * 0.5) >= 0.5, ROUNDUP(SUM(AI9) * 0.5, 0), ROUNDDOWN(SUM(AI9) * 0.5, 0)), SUM(AI9) * 0.5) -> 0 | AY9: =IF(INT(SUM(AJ9) * 0.5) <> B8, IF(SUM(AJ9) * 0.5 - INT(SUM(AJ9) * 0.5) >= 0.5, ROUNDUP(SUM(AJ9) * 0.5, 0), ROUNDDOWN(SUM(AJ9) * 0.5, 0)), SUM(AJ9) * 0.5) -> 0 | AZ9: =IF(INT(SUM(AK9) * 0.5) <> C8, IF(SUM(AK9) * 0.5 - INT(SUM(AK9) * 0.5) >= 0.5, ROUNDUP(SUM(AK9) * 0.5, 0), ROUNDDOWN(SUM(AK9) * 0.5, 0)), SUM(AK9) * 0.5) -> 0 | BA9: =IF(INT(SUM(AL9) * 0.5) <> E8, IF(SUM(AL9) * 0.5 - INT(SUM(AL9) * 0.5) >= 0.5, ROUNDUP(SUM(AL9) * 0.5, 0), ROUNDDOWN(SUM(AL9) * 0.5, 0)), SUM(AL9) * 0.5) -> 0 | BB9: =IF(INT(SUM(AM9) * 0.5) <> G8, IF(SUM(AM9) * 0.5 - INT(SUM(AM9) * 0.5) >= 0.5, ROUNDUP(SUM(AM9) * 0.5, 0), ROUNDDOWN(SUM(AM9) * 0.5, 0)), SUM(AM9) * 0.5) -> 0 | BC9: =SUM(AN9,AS9,AX9) -> 0 | BD9: =SUM(AO9,AT9,AY9) -> 0 | BE9: =SUM(AP9,AU9,AZ9) -> 0 | BF9: =SUM(AQ9,AV9,BA9) -> 0 | BG9: =SUM(BC9:BF9) -> 0 | BH9: =SUM(BC9:BF9)/500*100 -> 0 | BI9: =IF(BH9>=80,"A+",IF(BH9>=70,"A",IF(BH9>=60,"B+",IF(BH9>=50,"B",IF(BH9>=40,"C",IF(BH9>=30,"E","FAIL")))))) -> FAIL
B10: ='Unit 1'!A10 -> 0 | C10: ='Unit 1'!B10 -> 0 | D10: ='Unit 1'!$G$2 -> i | E10: ='Unit 1'!C10 -> 0 | F10: ='Unit 1'!D10 -> 0 | G10: ='Unit 1'!E10 -> 0 | H10: ='Unit 1'!F10 -> 0 | I10: =SUM(E10:H10) -> 0 | J10: ='Unit 2'!B10 -> 0 | K10: ='Unit 2'!C10 -> 0 | L10: ='Unit 2'!D10 -> 0 | M10: ='Unit 2'!E10 -> 0 | N10: =SUM(J10:M10) -> 0 | O10: ='Unit 3'!B10 -> 0 | P10: ='Unit 3'!C10 -> 0 | Q10: ='Unit 3'!D10 -> 0 | R10: ='Unit 3'!E10 -> 0 | S10: =SUM(O10:R10) -> 0 | T10: ='Unit 4'!B10 -> 0 | U10: ='Unit 4'!C10 -> 0 | V10: ='Unit 4'!D10 -> 0 | W10: ='Unit 4'!E10 -> 0 | X10: =SUM(T10:W10) -> 0 | Y10: =SUM(E10,J10,O10,T10,) -> 0 | Z10: =SUM(F10,K10,P10,U10,) -> 0 | AA10: =SUM(G10,L10,Q10,V10,) -> 0 | AB10: =SUM(H10,M10,R10,W10,) -> 0 | AC10: =SUM(Y10:AB10) -> 0 | AD10: ='Half yearly'!B10 -> 0 | AE10: ='Half yearly'!C10 -> 0 | AF10: ='Half yearly'!D10 -> 0 | AG10: ='Half yearly'!E10 -> 0 | AH10: =SUM(AD10:AG10) -> 0 | AI10: =Annual!B10 -> 0 | AJ10: =Annual!C10 -> 0 | AK10: =Annual!D10 -> 0 | AL10: =Annual!E10 -> 0 | AM10: =SUM(AI10:AL10) -> 0 | AN10: =IF(INT(SUM(E10, J10, O10, T10) * 0.2) <> A9, IF(SUM(E10, J10, O10, T10) * 0.2 - INT(SUM(E10, J10, O10, T10) * 0.2) >= 0.5, ROUNDUP(SUM(E10, J10, O10, T10) * 0.2, 0), ROUNDDOWN(SUM(E10, J10, O10, T10) * 0.2, 0)), SUM(E10, J10, O10, T10) * 0.2) -> 0 | AO10: =IF(INT(SUM(F10, K10, P10, U10) * 0.2) <> B9, IF(SUM(F10, K10, P10, U10) * 0.2 - INT(SUM(F10, K10, P10, U10) * 0.2) >= 0.5, ROUNDUP(SUM(F10, K10, P10, U10) * 0.2, 0), ROUNDDOWN(SUM(F10, K10, P10, U10) * 0.2, 0)), SUM(F10, K10, P10, U10) * 0.2) -> 0 | AP10: =IF(INT(SUM(G10, L10, Q10, V10) * 0.2) <> C9, IF(SUM(G10, L10, Q10, V10) * 0.2 - INT(SUM(G10, L10, Q10, V10) * 0.2) >= 0.5, ROUNDUP(SUM(G10, L10, Q10, V10) * 0.2, 0), ROUNDDOWN(SUM(G10, L10, Q10, V10) * 0.2, 0)), SUM(G10, L10, Q10, V10) * 0.2) -> 0 | AQ10: =IF(INT(SUM(H10, M10, R10, W10) * 0.2) <> E9, IF(SUM(H10, M10, R10, W10) * 0.2 - INT(SUM(H10, M10, R10, W10) * 0.2) >= 0.5, ROUNDUP(SUM(H10, M10, R10, W10) * 0.2, 0), ROUNDDOWN(SUM(H10, M10, R10, W10) * 0.2, 0)), SUM(H10, M10, R10, W10) * 0.2) -> 0 | AR10: =IF(INT(SUM(I10, N10, S10, X10) * 0.2) <> G9, IF(SUM(I10, N10, S10, X10) * 0.2 - INT(SUM(I10, N10, S10, X10) * 0.2) >= 0.5, ROUNDUP(SUM(I10, N10, S10, X10) * 0.2, 0), ROUNDDOWN(SUM(I10, N10, S10, X10) * 0.2, 0)), SUM(I10, N10, S10, X10) * 0.2) -> 0 | AS10: =IF(INT(SUM(AD10) * 0.3) <> A9, IF(SUM(AD10) * 0.3 - INT(SUM(AD10) * 0.3) >= 0.5, ROUNDUP(SUM(AD10) * 0.3, 0), ROUNDDOWN(SUM(AD10) * 0.3, 0)), SUM(AD10) * 0.3) -> 0 | AT10: =IF(INT(SUM(AE10) * 0.3) <> B9, IF(SUM(AE10) * 0.3 - INT(SUM(AE10) * 0.3) >= 0.5, ROUNDUP(SUM(AE10) * 0.3, 0), ROUNDDOWN(SUM(AE10) * 0.3, 0)), SUM(AE10) * 0.3) -> 0 | AU10: =IF(INT(SUM(AF10) * 0.3) <> C9, IF(SUM(AF10) * 0.3 - INT(SUM(AF10) * 0.3) >= 0.5, ROUNDUP(SUM(AF10) * 0.3, 0), ROUNDDOWN(SUM(AF10) * 0.3, 0)), SUM(AF10) * 0.3) -> 0 | AV10: =IF(INT(SUM(AG10) * 0.3) <> E9, IF(SUM(AG10) * 0.3 - INT(SUM(AG10) * 0.3) >= 0.5, ROUNDUP(SUM(AG10) * 0.3, 0), ROUNDDOWN(SUM(AG10) * 0.3, 0)), SUM(AG10) * 0.3) -> 0 | AW10: =IF(INT(SUM(AH10) * 0.3) <> G9, IF(SUM(AH10) * 0.3 - INT(SUM(AH10) * 0.3) >= 0.5, ROUNDUP(SUM(AH10) * 0.3, 0), ROUNDDOWN(SUM(AH10) * 0.3, 0)), SUM(AH10) * 0.3) -> 0 | AX10: =IF(INT(SUM(AI10) * 0.5) <> A9, IF(SUM(AI10) * 0.5 - INT(SUM(AI10) * 0.5) >= 0.5, ROUNDUP(SUM(AI10) * 0.5, 0), ROUNDDOWN(SUM(AI10) * 0.5, 0)), SUM(AI10) * 0.5) -> 0 | AY10: =IF(INT(SUM(AJ10) * 0.5) <> B9, IF(SUM(AJ10) * 0.5 - INT(SUM(AJ10) * 0.5) >= 0.5, ROUNDUP(SUM(AJ10) * 0.5, 0), ROUNDDOWN(SUM(AJ10) * 0.5, 0)), SUM(AJ10) * 0.5) -> 0 | AZ10: =IF(INT(SUM(AK10) * 0.5) <> C9, IF(SUM(AK10) * 0.5 - INT(SUM(AK10) * 0.5) >= 0.5, ROUNDUP(SUM(AK10) * 0.5, 0), ROUNDDOWN(SUM(AK10) * 0.5, 0)), SUM(AK10) * 0.5) -> 0 | BA10: =IF(INT(SUM(AL10) * 0.5) <> E9, IF(SUM(AL10) * 0.5 - INT(SUM(AL10) * 0.5) >= 0.5, ROUNDUP(SUM(AL10) * 0.5, 0), ROUNDDOWN(SUM(AL10) * 0.5, 0)), SUM(AL10) * 0.5) -> 0 | BB10: =IF(INT(SUM(AM10) * 0.5) <> G9, IF(SUM(AM10) * 0.5 - INT(SUM(AM10) * 0.5) >= 0.5, ROUNDUP(SUM(AM10) * 0.5, 0), ROUNDDOWN(SUM(AM10) * 0.5, 0)), SUM(AM10) * 0.5) -> 0 | BC10: =SUM(AN10,AS10,AX10) -> 0 | BD10: =SUM(AO10,AT10,AY10) -> 0 | BE10: =SUM(AP10,AU10,AZ10) -> 0 | BF10: =SUM(AQ10,AV10,BA10) -> 0 | BG10: =SUM(BC10:BF10) -> 0 | BH10: =SUM(BC10:BF10)/500*100 -> 0 | BI10: =IF(BH10>=80,"A+",IF(BH10>=70,"A",IF(BH10>=60,"B+",IF(BH10>=50,"B",IF(BH10>=40,"C",IF(BH10>=30,"E","FAIL")))))) -> FAIL
B11: ='Unit 1'!A11 -> 0 | C11: ='Unit 1'!B11 -> 0 | D11: ='Unit 1'!$G$2 -> i | E11: ='Unit 1'!C11 -> 0 | F11: ='Unit 1'!D11 -> 0 | G11: ='Unit 1'!E11 -> 0 | H11: ='Unit 1'!F11 -> 0 | I11: =SUM(E11:H11) -> 0 | J11: ='Unit 2'!B11 -> 0 | K11: ='Unit 2'!C11 -> 0 | L11: ='Unit 2'!D11 -> 0 | M11: ='Unit 2'!E11 -> 0 | N11: =SUM(J11:M11) -> 0 | O11: ='Unit 3'!B11 -> 0 | P11: ='Unit 3'!C11 -> 0 | Q11: ='Unit 3'!D11 -> 0 | R11: ='Unit 3'!E11 -> 0 | S11: =SUM(O11:R11) -> 0 | T11: ='Unit 4'!B11 -> 0 | U11: ='Unit 4'!C11 -> 0 | V11: ='Unit 4'!D11 -> 0 | W11: ='Unit 4'!E11 -> 0 | X11: =SUM(T11:W11) -> 0 | Y11: =SUM(E11,J11,O11,T11,) -> 0 | Z11: =SUM(F11,K11,P11,U11,) -> 0 | AA11: =SUM(G11,L11,Q11,V11,) -> 0 | AB11: =SUM(H11,M11,R11,W11,) -> 0 | AC11: =SUM(Y11:AB11) -> 0 | AD11: ='Half yearly'!B11 -> 0 | AE11: ='Half yearly'!C11 -> 0 | AF11: ='Half yearly'!D11 -> 0 | AG11: ='Half yearly'!E11 -> 0 | AH11: =SUM(AD11:AG11) -> 0 | AI11: =Annual!B11 -> 0 | AJ11: =Annual!C11 -> 0 | AK11: =Annual!D11 -> 0 | AL11: =Annual!E11 -> 0 | AM11: =SUM(AI11:AL11) -> 0 | AN11: =IF(INT(SUM(E11, J11, O11, T11) * 0.2) <> A10, IF(SUM(E11, J11, O11, T11) * 0.2 - INT(SUM(E11, J11, O11, T11) * 0.2) >= 0.5, ROUNDUP(SUM(E11, J11, O11, T11) * 0.2, 0), ROUNDDOWN(SUM(E11, J11, O11, T11) * 0.2, 0)), SUM(E11, J11, O11, T11) * 0.2) -> 0 | AO11: =IF(INT(SUM(F11, K11, P11, U11) * 0.2) <> B10, IF(SUM(F11, K11, P11, U11) * 0.2 - INT(SUM(F11, K11, P11, U11) * 0.2) >= 0.5, ROUNDUP(SUM(F11, K11, P11, U11) * 0.2, 0), ROUNDDOWN(SUM(F11, K11, P11, U11) * 0.2, 0)), SUM(F11, K11, P11, U11) * 0.2) -> 0 | AP11: =IF(INT(SUM(G11, L11, Q11, V11) * 0.2) <> C10, IF(SUM(G11, L11, Q11, V11) * 0.2 - INT(SUM(G11, L11, Q11, V11) * 0.2) >= 0.5, ROUNDUP(SUM(G11, L11, Q11, V11) * 0.2, 0), ROUNDDOWN(SUM(G11, L11, Q11, V11) * 0.2, 0)), SUM(G11, L11, Q11, V11) * 0.2) -> 0 | AQ11: =IF(INT(SUM(H11, M11, R11, W11) * 0.2) <> E10, IF(SUM(H11, M11, R11, W11) * 0.2 - INT(SUM(H11, M11, R11, W11) * 0.2) >= 0.5, ROUNDUP(SUM(H11, M11, R11, W11) * 0.2, 0), ROUNDDOWN(SUM(H11, M11, R11, W11) * 0.2, 0)), SUM(H11, M11, R11, W11) * 0.2) -> 0 | AR11: =IF(INT(SUM(I11, N11, S11, X11) * 0.2) <> G10, IF(SUM(I11, N11, S11, X11) * 0.2 - INT(SUM(I11, N11, S11, X11) * 0.2) >= 0.5, ROUNDUP(SUM(I11, N11, S11, X11) * 0.2, 0), ROUNDDOWN(SUM(I11, N11, S11, X11) * 0.2, 0)), SUM(I11, N11, S11, X11) * 0.2) -> 0 | AS11: =IF(INT(SUM(AD11) * 0.3) <> A10, IF(SUM(AD11) * 0.3 - INT(SUM(AD11) * 0.3) >= 0.5, ROUNDUP(SUM(AD11) * 0.3, 0), ROUNDDOWN(SUM(AD11) * 0.3, 0)), SUM(AD11) * 0.3) -> 0 | AT11: =IF(INT(SUM(AE11) * 0.3) <> B10, IF(SUM(AE11) * 0.3 - INT(SUM(AE11) * 0.3) >= 0.5, ROUNDUP(SUM(AE11) * 0.3, 0), ROUNDDOWN(SUM(AE11) * 0.3, 0)), SUM(AE11) * 0.3) -> 0 | AU11: =IF(INT(SUM(AF11) * 0.3) <> C10, IF(SUM(AF11) * 0.3 - INT(SUM(AF11) * 0.3) >= 0.5, ROUNDUP(SUM(AF11) * 0.3, 0), ROUNDDOWN(SUM(AF11) * 0.3, 0)), SUM(AF11) * 0.3) -> 0 | AV11: =IF(INT(SUM(AG11) * 0.3) <> E10, IF(SUM(AG11) * 0.3 - INT(SUM(AG11) * 0.3) >= 0.5, ROUNDUP(SUM(AG11) * 0.3, 0), ROUNDDOWN(SUM(AG11) * 0.3, 0)), SUM(AG11) * 0.3) -> 0 | AW11: =IF(INT(SUM(AH11) * 0.3) <> G10, IF(SUM(AH11) * 0.3 - INT(SUM(AH11) * 0.3) >= 0.5, ROUNDUP(SUM(AH11) * 0.3, 0), ROUNDDOWN(SUM(AH11) * 0.3, 0)), SUM(AH11) * 0.3) -> 0 | AX11: =IF(INT(SUM(AI11) * 0.5) <> A10, IF(SUM(AI11) * 0.5 - INT(SUM(AI11) * 0.5) >= 0.5, ROUNDUP(SUM(AI11) * 0.5, 0), ROUNDDOWN(SUM(AI11) * 0.5, 0)), SUM(AI11) * 0.5) -> 0 | AY11: =IF(INT(SUM(AJ11) * 0.5) <> B10, IF(SUM(AJ11) * 0.5 - INT(SUM(AJ11) * 0.5) >= 0.5, ROUNDUP(SUM(AJ11) * 0.5, 0), ROUNDDOWN(SUM(AJ11) * 0.5, 0)), SUM(AJ11) * 0.5) -> 0 | AZ11: =IF(INT(SUM(AK11) * 0.5) <> C10, IF(SUM(AK11) * 0.5 - INT(SUM(AK11) * 0.5) >= 0.5, ROUNDUP(SUM(AK11) * 0.5, 0), ROUNDDOWN(SUM(AK11) * 0.5, 0)), SUM(AK11) * 0.5) -> 0 | BA11: =IF(INT(SUM(AL11) * 0.5) <> E10, IF(SUM(AL11) * 0.5 - INT(SUM(AL11) * 0.5) >= 0.5, ROUNDUP(SUM(AL11) * 0.5, 0), ROUNDDOWN(SUM(AL11) * 0.5, 0)), SUM(AL11) * 0.5) -> 0 | BB11: =IF(INT(SUM(AM11) * 0.5) <> G10, IF(SUM(AM11) * 0.5 - INT(SUM(AM11) * 0.5) >= 0.5, ROUNDUP(SUM(AM11) * 0.5, 0), ROUNDDOWN(SUM(AM11) * 0.5, 0)), SUM(AM11) * 0.5) -> 0 | BC11: =SUM(AN11,AS11,AX11) -> 0 | BD11: =SUM(AO11,AT11,AY11) -> 0 | BE11: =SUM(AP11,AU11,AZ11) -> 0 | BF11: =SUM(AQ11,AV11,BA11) -> 0 | BG11: =SUM(BC11:BF11) -> 0 | BH11: =SUM(BC11:BF11)/500*100 -> 0 | BI11: =IF(BH11>=80,"A+",IF(BH11>=70,"A",IF(BH11>=60,"B+",IF(BH11>=50,"B",IF(BH11>=40,"C",IF(BH11>=30,"E","FAIL")))))) -> FAIL
B12: ='Unit 1'!A12 -> 0 | C12: ='Unit 1'!B12 -> 0 | D12: ='Unit 1'!$G$2 -> i | E12: ='Unit 1'!C12 -> 0 | F12: ='Unit 1'!D12 -> 0 | G12: ='Unit 1'!E12 -> 0 | H12: ='Unit 1'!F12 -> 0 | I12: =SUM(E12:H12) -> 0 | J12: ='Unit 2'!B12 -> 0 | K12: ='Unit 2'!C12 -> 0 | L12: ='Unit 2'!D12 -> 0 | M12: ='Unit 2'!E12 -> 0 | N12: =SUM(J12:M12) -> 0 | O12: ='Unit 3'!B12 -> 0 | P12: ='Unit 3'!C12 -> 0 | Q12: ='Unit 3'!D12 -> 0 | R12: ='Unit 3'!E12 -> 0 | S12: =SUM(O12:R12) -> 0 | T12: ='Unit 4'!B12 -> 0 | U12: ='Unit 4'!C12 -> 0 | V12: ='Unit 4'!D12 -> 0 | W12: ='Unit 4'!E12 -> 0 | X12: =SUM(T12:W12) -> 0 | Y12: =SUM(E12,J12,O12,T12,) -> 0 | Z12: =SUM(F12,K12,P12,U12,) -> 0 | AA12: =SUM(G12,L12,Q12,V12,) -> 0 | AB12: =SUM(H12,M12,R12,W12,) -> 0 | AC12: =SUM(Y12:AB12) -> 0 | AD12: ='Half yearly'!B12 -> 0 | AE12: ='Half yearly'!C12 -> 0 | AF12: ='Half yearly'!D12 -> 0 | AG12: ='Half yearly'!E12 -> 0 | AH12: =SUM(AD12:AG12) -> 0 | AI12: =Annual!B12 -> 0 | AJ12: =Annual!C12 -> 0 | AK12: =Annual!D12 -> 0 | AL12: =Annual!E12 -> 0 | AM12: =SUM(AI12:AL12) -> 0 | AN12: =IF(INT(SUM(E12, J12, O12, T12) * 0.2) <> A11, IF(SUM(E12, J12, O12, T12) * 0.2 - INT(SUM(E12, J12, O12, T12) * 0.2) >= 0.5, ROUNDUP(SUM(E12, J12, O12, T12) * 0.2, 0), ROUNDDOWN(SUM(E12, J12, O12, T12) * 0.2, 0)), SUM(E12, J12, O12, T12) * 0.2) -> 0 | AO12: =IF(INT(SUM(F12, K12, P12, U12) * 0.2) <> B11, IF(SUM(F12, K12, P12, U12) * 0.2 - INT(SUM(F12, K12, P12, U12) * 0.2) >= 0.5, ROUNDUP(SUM(F12, K12, P12, U12) * 0.2, 0), ROUNDDOWN(SUM(F12, K12, P12, U12) * 0.2, 0)), SUM(F12, K12, P12, U12) * 0.2) -> 0 | AP12: =IF(INT(SUM(G12, L12, Q12, V12) * 0.2) <> C11, IF(SUM(G12, L12, Q12, V12) * 0.2 - INT(SUM(G12, L12, Q12, V12) * 0.2) >= 0.5, ROUNDUP(SUM(G12, L12, Q12, V12) * 0.2, 0), ROUNDDOWN(SUM(G12, L12, Q12, V12) * 0.2, 0)), SUM(G12, L12, Q12, V12) * 0.2) -> 0 | AQ12: =IF(INT(SUM(H12, M12, R12, W12) * 0.2) <> E11, IF(SUM(H12, M12, R12, W12) * 0.2 - INT(SUM(H12, M12, R12, W12) * 0.2) >= 0.5, ROUNDUP(SUM(H12, M12, R12, W12) * 0.2, 0), ROUNDDOWN(SUM(H12, M12, R12, W12) * 0.2, 0)), SUM(H12, M12, R12, W12) * 0.2) -> 0 | AR12: =IF(INT(SUM(I12, N12, S12, X12) * 0.2) <> G11, IF(SUM(I12, N12, S12, X12) * 0.2 - INT(SUM(I12, N12, S12, X12) * 0.2) >= 0.5, ROUNDUP(SUM(I12, N12, S12, X12) * 0.2, 0), ROUNDDOWN(SUM(I12, N12, S12, X12) * 0.2, 0)), SUM(I12, N12, S12, X12) * 0.2) -> 0 | AS12: =IF(INT(SUM(AD12) * 0.3) <> A11, IF(SUM(AD12) * 0.3 - INT(SUM(AD12) * 0.3) >= 0.5, ROUNDUP(SUM(AD12) * 0.3, 0), ROUNDDOWN(SUM(AD12) * 0.3, 0)), SUM(AD12) * 0.3) -> 0 | AT12: =IF(INT(SUM(AE12) * 0.3) <> B11, IF(SUM(AE12) * 0.3 - INT(SUM(AE12) * 0.3) >= 0.5, ROUNDUP(SUM(AE12) * 0.3, 0), ROUNDDOWN(SUM(AE12) * 0.3, 0)), SUM(AE12) * 0.3) -> 0 | AU12: =IF(INT(SUM(AF12) * 0.3) <> C11, IF(SUM(AF12) * 0.3 - INT(SUM(AF12) * 0.3) >= 0.5, ROUNDUP(SUM(AF12) * 0.3, 0), ROUNDDOWN(SUM(AF12) * 0.3, 0)), SUM(AF12) * 0.3) -> 0 | AV12: =IF(INT(SUM(AG12) * 0.3) <> E11, IF(SUM(AG12) * 0.3 - INT(SUM(AG12) * 0.3) >= 0.5, ROUNDUP(SUM(AG12) * 0.3, 0), ROUNDDOWN(SUM(AG12) * 0.3, 0)), SUM(AG12) * 0.3) -> 0 | AW12: =IF(INT(SUM(AH12) * 0.3) <> G11, IF(SUM(AH12) * 0.3 - INT(SUM(AH12) * 0.3) >= 0.5, ROUNDUP(SUM(AH12) * 0.3, 0), ROUNDDOWN(SUM(AH12) * 0.3, 0)), SUM(AH12) * 0.3) -> 0 | AX12: =IF(INT(SUM(AI12) * 0.5) <> A11, IF(SUM(AI12) * 0.5 - INT(SUM(AI12) * 0.5) >= 0.5, ROUNDUP(SUM(AI12) * 0.5, 0), ROUNDDOWN(SUM(AI12) * 0.5, 0)), SUM(AI12) * 0.5) -> 0 | AY12: =IF(INT(SUM(AJ12) * 0.5) <> B11, IF(SUM(AJ12) * 0.5 - INT(SUM(AJ12) * 0.5) >= 0.5, ROUNDUP(SUM(AJ12) * 0.5, 0), ROUNDDOWN(SUM(AJ12) * 0.5, 0)), SUM(AJ12) * 0.5) -> 0 | AZ12: =IF(INT(SUM(AK12) * 0.5) <> C11, IF(SUM(AK12) * 0.5 - INT(SUM(AK12) * 0.5) >= 0.5, ROUNDUP(SUM(AK12) * 0.5, 0), ROUNDDOWN(SUM(AK12) * 0.5, 0)), SUM(AK12) * 0.5) -> 0 | BA12: =IF(INT(SUM(AL12) * 0.5) <> E11, IF(SUM(AL12) * 0.5 - INT(SUM(AL12) * 0.5) >= 0.5, ROUNDUP(SUM(AL12) * 0.5, 0), ROUNDDOWN(SUM(AL12) * 0.5, 0)), SUM(AL12) * 0.5) -> 0 | BB12: =IF(INT(SUM(AM12) * 0.5) <> G11, IF(SUM(AM12) * 0.5 - INT(SUM(AM12) * 0.5) >= 0.5, ROUNDUP(SUM(AM12) * 0.5, 0), ROUNDDOWN(SUM(AM12) * 0.5, 0)), SUM(AM12) * 0.5) -> 0 | BC12: =SUM(AN12,AS12,AX12) -> 0 | BD12: =SUM(AO12,AT12,AY12) -> 0 | BE12: =SUM(AP12,AU12,AZ12) -> 0 | BF12: =SUM(AQ12,AV12,BA12) -> 0 | BG12: =SUM(BC12:BF12) -> 0 | BH12: =SUM(BC12:BF12)/500*100 -> 0 | BI12: =IF(BH12>=80,"A+",IF(BH12>=70,"A",IF(BH12>=60,"B+",IF(BH12>=50,"B",IF(BH12>=40,"C",IF(BH12>=30,"E","FAIL")))))) -> FAIL
B13: ='Unit 1'!A13 -> 0 | C13: ='Unit 1'!B13 -> 0 | D13: ='Unit 1'!$G$2 -> i | E13: ='Unit 1'!C13 -> 0 | F13: ='Unit 1'!D13 -> 0 | G13: ='Unit 1'!E13 -> 0 | H13: ='Unit 1'!F13 -> 0 | I13: =SUM(E13:H13) -> 0 | J13: ='Unit 2'!B13 -> 0 | K13: ='Unit 2'!C13 -> 0 | L13: ='Unit 2'!D13 -> 0 | M13: ='Unit 2'!E13 -> 0 | N13: =SUM(J13:M13) -> 0 | O13: ='Unit 3'!B13 -> 0 | P13: ='Unit 3'!C13 -> 0 | Q13: ='Unit 3'!D13 -> 0 | R13: ='Unit 3'!E13 -> 0 | S13: =SUM(O13:R13) -> 0 | T13: ='Unit 4'!B13 -> 0 | U13: ='Unit 4'!C13 -> 0 | V13: ='Unit 4'!D13 -> 0 | W13: ='Unit 4'!E13 -> 0 | X13: =SUM(T13:W13) -> 0 | Y13: =SUM(E13,J13,O13,T13,) -> 0 | Z13: =SUM(F13,K13,P13,U13,) -> 0 | AA13: =SUM(G13,L13,Q13,V13,) -> 0 | AB13: =SUM(H13,M13,R13,W13,) -> 0 | AC13: =SUM(Y13:AB13) -> 0 | AD13: ='Half yearly'!B13 -> 0 | AE13: ='Half yearly'!C13 -> 0 | AF13: ='Half yearly'!D13 -> 0 | AG13: ='Half yearly'!E13 -> 0 | AH13: =SUM(AD13:AG13) -> 0 | AI13: =Annual!B13 -> 0 | AJ13: =Annual!C13 -> 0 | AK13: =Annual!D13 -> 0 | AL13: =Annual!E13 -> 0 | AM13: =SUM(AI13:AL13) -> 0 | AN13: =IF(INT(SUM(E13, J13, O13, T13) * 0.2) <> A12, IF(SUM(E13, J13, O13, T13) * 0.2 - INT(SUM(E13, J13, O13, T13) * 0.2) >= 0.5, ROUNDUP(SUM(E13, J13, O13, T13) * 0.2, 0), ROUNDDOWN(SUM(E13, J13, O13, T13) * 0.2, 0)), SUM(E13, J13, O13, T13) * 0.2) -> 0 | AO13: =IF(INT(SUM(F13, K13, P13, U13) * 0.2) <> B12, IF(SUM(F13, K13, P13, U13) * 0.2 - INT(SUM(F13, K13, P13, U13) * 0.2) >= 0.5, ROUNDUP(SUM(F13, K13, P13, U13) * 0.2, 0), ROUNDDOWN(SUM(F13, K13, P13, U13) * 0.2, 0)), SUM(F13, K13, P13, U13) * 0.2) -> 0 | AP13: =IF(INT(SUM(G13, L13, Q13, V13) * 0.2) <> C12, IF(SUM(G13, L13, Q13, V13) * 0.2 - INT(SUM(G13, L13, Q13, V13) * 0.2) >= 0.5, ROUNDUP(SUM(G13, L13, Q13, V13) * 0.2, 0), ROUNDDOWN(SUM(G13, L13, Q13, V13) * 0.2, 0)), SUM(G13, L13, Q13, V13) * 0.2) -> 0 | AQ13: =IF(INT(SUM(H13, M13, R13, W13) * 0.2) <> E12, IF(SUM(H13, M13, R13, W13) * 0.2 - INT(SUM(H13, M13, R13, W13) * 0.2) >= 0.5, ROUNDUP(SUM(H13, M13, R13, W13) * 0.2, 0), ROUNDDOWN(SUM(H13, M13, R13, W13) * 0.2, 0)), SUM(H13, M13, R13, W13) * 0.2) -> 0 | AR13: =IF(INT(SUM(I13, N13, S13, X13) * 0.2) <> G12, IF(SUM(I13, N13, S13, X13) * 0.2 - INT(SUM(I13, N13, S13, X13) * 0.2) >= 0.5, ROUNDUP(SUM(I13, N13, S13, X13) * 0.2, 0), ROUNDDOWN(SUM(I13, N13, S13, X13) * 0.2, 0)), SUM(I13, N13, S13, X13) * 0.2) -> 0 | AS13: =IF(INT(SUM(AD13) * 0.3) <> A12, IF(SUM(AD13) * 0.3 - INT(SUM(AD13) * 0.3) >= 0.5, ROUNDUP(SUM(AD13) * 0.3, 0), ROUNDDOWN(SUM(AD13) * 0.3, 0)), SUM(AD13) * 0.3) -> 0 | AT13: =IF(INT(SUM(AE13) * 0.3) <> B12, IF(SUM(AE13) * 0.3 - INT(SUM(AE13) * 0.3) >= 0.5, ROUNDUP(SUM(AE13) * 0.3, 0), ROUNDDOWN(SUM(AE13) * 0.3, 0)), SUM(AE13) * 0.3) -> 0 | AU13: =IF(INT(SUM(AF13) * 0.3) <> C12, IF(SUM(AF13) * 0.3 - INT(SUM(AF13) * 0.3) >= 0.5, ROUNDUP(SUM(AF13) * 0.3, 0), ROUNDDOWN(SUM(AF13) * 0.3, 0)), SUM(AF13) * 0.3) -> 0 | AV13: =IF(INT(SUM(AG13) * 0.3) <> E12, IF(SUM(AG13) * 0.3 - INT(SUM(AG13) * 0.3) >= 0.5, ROUNDUP(SUM(AG13) * 0.3, 0), ROUNDDOWN(SUM(AG13) * 0.3, 0)), SUM(AG13) * 0.3) -> 0 | AW13: =IF(INT(SUM(AH13) * 0.3) <> G12, IF(SUM(AH13) * 0.3 - INT(SUM(AH13) * 0.3) >= 0.5, ROUNDUP(SUM(AH13) * 0.3, 0), ROUNDDOWN(SUM(AH13) * 0.3, 0)), SUM(AH13) * 0.3) -> 0 | AX13: =IF(INT(SUM(AI13) * 0.5) <> A12, IF(SUM(AI13) * 0.5 - INT(SUM(AI13) * 0.5) >= 0.5, ROUNDUP(SUM(AI13) * 0.5, 0), ROUNDDOWN(SUM(AI13) * 0.5, 0)), SUM(AI13) * 0.5) -> 0 | AY13: =IF(INT(SUM(AJ13) * 0.5) <> B12, IF(SUM(AJ13) * 0.5 - INT(SUM(AJ13) * 0.5) >= 0.5, ROUNDUP(SUM(AJ13) * 0.5, 0), ROUNDDOWN(SUM(AJ13) * 0.5, 0)), SUM(AJ13) * 0.5) -> 0 | AZ13: =IF(INT(SUM(AK13) * 0.5) <> C12, IF(SUM(AK13) * 0.5 - INT(SUM(AK13) * 0.5) >= 0.5, ROUNDUP(SUM(AK13) * 0.5, 0), ROUNDDOWN(SUM(AK13) * 0.5, 0)), SUM(AK13) * 0.5) -> 0 | BA13: =IF(INT(SUM(AL13) * 0.5) <> E12, IF(SUM(AL13) * 0.5 - INT(SUM(AL13) * 0.5) >= 0.5, ROUNDUP(SUM(AL13) * 0.5, 0), ROUNDDOWN(SUM(AL13) * 0.5, 0)), SUM(AL13) * 0.5) -> 0 | BB13: =IF(INT(SUM(AM13) * 0.5) <> G12, IF(SUM(AM13) * 0.5 - INT(SUM(AM13) * 0.5) >= 0.5, ROUNDUP(SUM(AM13) * 0.5, 0), ROUNDDOWN(SUM(AM13) * 0.5, 0)), SUM(AM13) * 0.5) -> 0 | BC13: =SUM(AN13,AS13,AX13) -> 0 | BD13: =SUM(AO13,AT13,AY13) -> 0 | BE13: =SUM(AP13,AU13,AZ13) -> 0 | BF13: =SUM(AQ13,AV13,BA13) -> 0 | BG13: =SUM(BC13:BF13) -> 0 | BH13: =SUM(BC13:BF13)/500*100 -> 0 | BI13: =IF(BH13>=80,"A+",IF(BH13>=70,"A",IF(BH13>=60,"B+",IF(BH13>=50,"B",IF(BH13>=40,"C",IF(BH13>=30,"E","FAIL")))))) -> FAIL
B14: ='Unit 1'!A14 -> 0 | C14: ='Unit 1'!B14 -> 0 | D14: ='Unit 1'!$G$2 -> i | E14: ='Unit 1'!C14 -> 0 | F14: ='Unit 1'!D14 -> 0 | G14: ='Unit 1'!E14 -> 0 | H14: ='Unit 1'!F14 -> 0 | I14: =SUM(E14:H14) -> 0 | J14: ='Unit 2'!B14 -> 0 | K14: ='Unit 2'!C14 -> 0 | L14: ='Unit 2'!D14 -> 0 | M14: ='Unit 2'!E14 -> 0 | N14: =SUM(J14:M14) -> 0 | O14: ='Unit 3'!B14 -> 0 | P14: ='Unit 3'!C14 -> 0 | Q14: ='Unit 3'!D14 -> 0 | R14: ='Unit 3'!E14 -> 0 | S14: =SUM(O14:R14) -> 0 | T14: ='Unit 4'!B14 -> 0 | U14: ='Unit 4'!C14 -> 0 | V14: ='Unit 4'!D14 -> 0 | W14: ='Unit 4'!E14 -> 0 | X14: =SUM(T14:W14) -> 0 | Y14: =SUM(E14,J14,O14,T14,) -> 0 | Z14: =SUM(F14,K14,P14,U14,) -> 0 | AA14: =SUM(G14,L14,Q14,V14,) -> 0 | AB14: =SUM(H14,M14,R14,W14,) -> 0 | AC14: =SUM(Y14:AB14) -> 0 | AD14: ='Half yearly'!B14 -> 0 | AE14: ='Half yearly'!C14 -> 0 | AF14: ='Half yearly'!D14 -> 0 | AG14: ='Half yearly'!E14 -> 0 | AH14: =SUM(AD14:AG14) -> 0 | AI14: =Annual!B14 -> 0 | AJ14: =Annual!C14 -> 0 | AK14: =Annual!D14 -> 0 | AL14: =Annual!E14 -> 0 | AM14: =SUM(AI14:AL14) -> 0 | AN14: =IF(INT(SUM(E14, J14, O14, T14) * 0.2) <> A13, IF(SUM(E14, J14, O14, T14) * 0.2 - INT(SUM(E14, J14, O14, T14) * 0.2) >= 0.5, ROUNDUP(SUM(E14, J14, O14, T14) * 0.2, 0), ROUNDDOWN(SUM(E14, J14, O14, T14) * 0.2, 0)), SUM(E14, J14, O14, T14) * 0.2) -> 0 | AO14: =IF(INT(SUM(F14, K14, P14, U14) * 0.2) <> B13, IF(SUM(F14, K14, P14, U14) * 0.2 - INT(SUM(F14, K14, P14, U14) * 0.2) >= 0.5, ROUNDUP(SUM(F14, K14, P14, U14) * 0.2, 0), ROUNDDOWN(SUM(F14, K14, P14, U14) * 0.2, 0)), SUM(F14, K14, P14, U14) * 0.2) -> 0 | AP14: =IF(INT(SUM(G14, L14, Q14, V14) * 0.2) <> C13, IF(SUM(G14, L14, Q14, V14) * 0.2 - INT(SUM(G14, L14, Q14, V14) * 0.2) >= 0.5, ROUNDUP(SUM(G14, L14, Q14, V14) * 0.2, 0), ROUNDDOWN(SUM(G14, L14, Q14, V14) * 0.2, 0)), SUM(G14, L14, Q14, V14) * 0.2) -> 0 | AQ14: =IF(INT(SUM(H14, M14, R14, W14) * 0.2) <> E13, IF(SUM(H14, M14, R14, W14) * 0.2 - INT(SUM(H14, M14, R14, W14) * 0.2) >= 0.5, ROUNDUP(SUM(H14, M14, R14, W14) * 0.2, 0), ROUNDDOWN(SUM(H14, M14, R14, W14) * 0.2, 0)), SUM(H14, M14, R14, W14) * 0.2) -> 0 | AR14: =IF(INT(SUM(I14, N14, S14, X14) * 0.2) <> G13, IF(SUM(I14, N14, S14, X14) * 0.2 - INT(SUM(I14, N14, S14, X14) * 0.2) >= 0.5, ROUNDUP(SUM(I14, N14, S14, X14) * 0.2, 0), ROUNDDOWN(SUM(I14, N14, S14, X14) * 0.2, 0)), SUM(I14, N14, S14, X14) * 0.2) -> 0 | AS14: =IF(INT(SUM(AD14) * 0.3) <> A13, IF(SUM(AD14) * 0.3 - INT(SUM(AD14) * 0.3) >= 0.5, ROUNDUP(SUM(AD14) * 0.3, 0), ROUNDDOWN(SUM(AD14) * 0.3, 0)), SUM(AD14) * 0.3) -> 0 | AT14: =IF(INT(SUM(AE14) * 0.3) <> B13, IF(SUM(AE14) * 0.3 - INT(SUM(AE14) * 0.3) >= 0.5, ROUNDUP(SUM(AE14) * 0.3, 0), ROUNDDOWN(SUM(AE14) * 0.3, 0)), SUM(AE14) * 0.3) -> 0 | AU14: =IF(INT(SUM(AF14) * 0.3) <> C13, IF(SUM(AF14) * 0.3 - INT(SUM(AF14) * 0.3) >= 0.5, ROUNDUP(SUM(AF14) * 0.3, 0), ROUNDDOWN(SUM(AF14) * 0.3, 0)), SUM(AF14) * 0.3) -> 0 | AV14: =IF(INT(SUM(AG14) * 0.3) <> E13, IF(SUM(AG14) * 0.3 - INT(SUM(AG14) * 0.3) >= 0.5, ROUNDUP(SUM(AG14) * 0.3, 0), ROUNDDOWN(SUM(AG14) * 0.3, 0)), SUM(AG14) * 0.3) -> 0 | AW14: =IF(INT(SUM(AH14) * 0.3) <> G13, IF(SUM(AH14) * 0.3 - INT(SUM(AH14) * 0.3) >= 0.5, ROUNDUP(SUM(AH14) * 0.3, 0), ROUNDDOWN(SUM(AH14) * 0.3, 0)), SUM(AH14) * 0.3) -> 0 | AX14: =IF(INT(SUM(AI14) * 0.5) <> A13, IF(SUM(AI14) * 0.5 - INT(SUM(AI14) * 0.5) >= 0.5, ROUNDUP(SUM(AI14) * 0.5, 0), ROUNDDOWN(SUM(AI14) * 0.5, 0)), SUM(AI14) * 0.5) -> 0 | AY14: =IF(INT(SUM(AJ14) * 0.5) <> B13, IF(SUM(AJ14) * 0.5 - INT(SUM(AJ14) * 0.5) >= 0.5, ROUNDUP(SUM(AJ14) * 0.5, 0), ROUNDDOWN(SUM(AJ14) * 0.5, 0)), SUM(AJ14) * 0.5) -> 0 | AZ14: =IF(INT(SUM(AK14) * 0.5) <> C13, IF(SUM(AK14) * 0.5 - INT(SUM(AK14) * 0.5) >= 0.5, ROUNDUP(SUM(AK14) * 0.5, 0), ROUNDDOWN(SUM(AK14) * 0.5, 0)), SUM(AK14) * 0.5) -> 0 | BA14: =IF(INT(SUM(AL14) * 0.5) <> E13, IF(SUM(AL14) * 0.5 - INT(SUM(AL14) * 0.5) >= 0.5, ROUNDUP(SUM(AL14) * 0.5, 0), ROUNDDOWN(SUM(AL14) * 0.5, 0)), SUM(AL14) * 0.5) -> 0 | BB14: =IF(INT(SUM(AM14) * 0.5) <> G13, IF(SUM(AM14) * 0.5 - INT(SUM(AM14) * 0.5) >= 0.5, ROUNDUP(SUM(AM14) * 0.5, 0), ROUNDDOWN(SUM(AM14) * 0.5, 0)), SUM(AM14) * 0.5) -> 0 | BC14: =SUM(AN14,AS14,AX14) -> 0 | BD14: =SUM(AO14,AT14,AY14) -> 0 | BE14: =SUM(AP14,AU14,AZ14) -> 0 | BF14: =SUM(AQ14,AV14,BA14) -> 0 | BG14: =SUM(BC14:BF14) -> 0 | BH14: =SUM(BC14:BF14)/500*100 -> 0 | BI14: =IF(BH14>=80,"A+",IF(BH14>=70,"A",IF(BH14>=60,"B+",IF(BH14>=50,"B",IF(BH14>=40,"C",IF(BH14>=30,"E","FAIL")))))) -> FAIL
